Workbook
Name flag_pin_historical: #REF!
Name flag_pin_historical: #REF!
Name flag_pin_historical: #REF!
Name flag_pin_historical: Thresholds!$D$13
Name flag_pin_perc: #REF!
Name flag_pin_perc: #REF!
Name flag_pin_perc: #REF!
Name flag_pin_perc: Thresholds!$D$12
Name perc_1st_2nd: #REF!
Name perc_1st_2nd: #REF!
Name perc_1st_2nd: #REF!
Name perc_1st_2nd: Thresholds!$D$9
Name perc_1st_3rd: #REF!
Name perc_1st_3rd: #REF!
Name perc_1st_3rd: #REF!
Name perc_1st_3rd: Thresholds!$D$10
Name pin_perc: 'PiN Visuals'!$B$5:$F$16
Name sectors_sev_4: Thresholds!$D$29
Name sectors_sev_5: #REF!
Name sectors_sev_5: #REF!
Name sectors_sev_5: #REF!
Name sectors_sev_5: Thresholds!$D$28
Name zero_pin_thresh: #REF!
Name zero_pin_thresh: #REF!
Name zero_pin_thresh: #REF!
Name zero_pin_thresh: Thresholds!$D$8

Sheet Read Me
A1: JIAF 2 Tool 3: PiN & Severity estimation template
A3: Warnings for all sheets! | B3: Pre-set data checks have been coded into the template and they will be implemented as soon as sector data is inserted into the template. OCHA analysis teams are free to modify the template, including additional checks or removing any checks that are deemed not useful by the analysis team. At a minimum, the following columns will need to be updated by the teams: ID: A unique identifier, automatically generated and required to link certain formulas. Do not change or delete. Geographic and Population related columns: Do not delete columns for admin units and population group; please just hide any column if not needed. Sectoral Data: sectoral header names can be changed; sector columns can be removed or added in between the first and last collumn (but do not remove the first and the last sector columns); make sure the order of the sector names match the order of their percentage column and if new sector columns are added make sure to write the formula for the percentage calculation. More importantly, Do not delete the first and last column of the sectoral data section.
A5: Sheet | B5: Description
A6: Thresholds | B6: Thresholds - Flagging criteria & thresholds: OCHA analysis team to adjust if necessary the thresholds for pre-set data checks as per agreements with partners. - Sub-population group sectors: OCHA analysis team to list all sectors targeting sub-population groups (e.g. kids, women, IDPs) in their context.
A7: Overall PiN | B7: Preliminary PiN: Highest PiN among the Sector PINs is automatically taken as the preliminary PiN.
B8: Flags and Outlier Checks: Please note that the analysis team could decide to adjust the thresholds of these indicators, in the Threshold spreadshee or eliminate flags that they consider not relevant to their contexts
B9: Number of missing or zero PiN: OCHA analysis team to decide the threshold for accepted number of sectors at unit level not to provide a PiN value or have zero PiN.
B10: Highest PiN close to the total affected population: OCHA analysis team to decide the threshold of acceptable proportion of people in need to the affected population at unit level.
B11: Highest Sector targets only a subset of the affected population: OCHA analysis team to decide the sectors that target only a subset of the affected population.
B12: Difference b/w highest and 2nd highest: OCHA analysis team to decide whether certain outliers between highest sector with 2nd or 3rd highest require flagging for review and to enter 'Flagged' in the column.
B13: Difference b/w highest and 3rd highest: OCHA analysis team to decide whether certain outliers between highest sector with 2nd or 3rd highest require flagging for review and to enter 'Flagged' in the column.
B14: % Difference between this HNO's highest or 2nd highest sector PiN to same sector in the last HNO: OCHA analysis team to decide the threshold of change for this HNO's highest or 2nd higehst sector PiN and last HNO's PiN for the same sector.
A15: PiN Historical Trend | B15: This table can be used to compare current sector PiNs to the previous year's PiNs to identify increases or decreases. The current PIN will be automatically loaded from the Overal PIN spreadsheet, provided that the unique ID of the rows match. The Previous year's HNO data needs to be loaded in the Historical Trend spreadsheet. Formulas will automatically calculate the %change from previous to current year and highlights area where PiN is 50% higher or lower than the last HNO's PiN for further investigation. Countries can decide to change this 50% threshold according to their context.
A16: PiN Visulas | B16: Two visuals that can help better understand sectoral PiN affecting percentage of affected population and the percentage of change from one HNO to the last distribution.
A17: Intersectoral Severity | B17: # of sectors falling under severity phases: The number of sectors fallen under each severity phase can help better understand and see the relationship of the sectoral severities to the preliminary intersectoral severity. Preliminary Intersectoral Severity: preliminary intersectoral severity is automatically calculated according to the logical formula. Flags and Outlier Checks: Some sectors having severity phase 5 or 4: OCHA analysis team to decide number of sectors in phase 5 or 4 to be flagged and reviewed to confirm the concentration of high sectoral severities . Variation between preliminary severity and outcome indicators: preliminary intersectoral severity is higher or lower then outcome indicators (by 1 or more).
A18: Reference Table indicators | B18: Fill in reference table indicators data at unit level to automatically calculate the severity of the indicator which will be used to compare the intersectoral severity results with. If any indicators are added, removed or modified, please make sure that the formulas correctly reflect these changes.

Sheet Thresholds
C1: Please do not delete this sheet or tables in this sheet!
C3: Tables in this sheet are being used in formulas in other sheets!
B6: PiN Flagging criteria & thresholds | D6: Please assign the thresholds relevant for your country
A7: Flag Name | B7: Flag Description | C7: Recommended Threshold | D7: Country Threshold | E7: Explanation for proposing another threshold | F7: Purpose
B8: # Sectors with 0 PiN | C8: 2 | D8: 2 | F8: To flag potential data quality issue
A9: % Difference between 1st and 2nd highest PIN | B9: % difference threshold between 1st and 2nd highest PiN greater than 30% | C9: 0.3 | D9: 0.5 | E9: Many flags by default. Many divergences between sectors | F9: To identify areas to manual review
A10: % Difference between 1st and 3rd highest PIN | B10: % difference threshold between 1st and 3rd highest PiN greater than 50% | C10: 0.5 | D10: 0.8 | E10: there are big differences between the crisis/chocs (Food or Protection or diplacement). Differences may results in different population groups of interest or the difference between the sectors. | F10: To identify areas to manual review
A11: Highest sector PIN targets sub-population group(s) | B11: Whenever a sector dealing with a sub-population group is higher than any other sector - e.g., Education and Nutrition
A12: PiN greater than 90% of total affected population | B12: Flag where the 1st or the 2nd highest PiN is 90% of the affected population | C12: 0.9 | D12: 0.9
A13: Change from last year | B13: Flag where the change from last year of the 1st or 2nd highest PiN is significantly higher than the the average change from last year of all sectors | C13: 1 | D13: 1
A14: Manual Flag | B14: Any area can be flagged manually whenever there is a concern by any JIAF analysts about the PIN
B15: Outliers from the porpotion of highest PiN in the population nationwide
B16: % difference threshold between sectoral PiN change between this year and last year | C16: 2std | D16: 2std | F16: To identify areas to manual review
B18: PiN - Sub-population group sectors
B19: Sector | C19: Proportion of sector target population in overall population
A20: Decision Rule for determining PIN | B20: Education
A21: 1. accept highest PIN with no flags. 2. Accept highest PiN after reconciling any flags. 3. If no concensus on highest PIN, use 2nd highest PIN. 4. If no consensus on 2nd highest PIN elevate decision to HC level | B21: Nutrition
B26: Severity Flagging criteria & thresholds | D26: Please assign the thresholds relevant for your country
B27: Flagging criterion for PIN | C27: Recommended Threshold | D27: Country Threshold | E27: Explanation for proposing another threshold
B28: # of sectors in phase 5 | C28: 1 | D28: 1
B29: # of sectors in phase 4 with preliminary in phase 4 | C29: 5 | D29: 5
B33: Targeting thresholds
B34: Targeting criteria | C34: Recommended Threshold | D34: Country Threshold
B35: Areas in severity 3 | C35: 0.5 | D35: 0.5 | E35: 50% is the maximun threshold for Severity 3
B36: Areas in severity 4 & 5 | C36: 1 | D36: 1

Sheet Sheet1
B3: Column Labels
A4: Values | B4: 2 | C4: 3 | D4: 4 | E4: 5 | F4: Grand Total
A5: Sum of Final PiN | B5: 0 | C5: 4317003.2 | D5: 1667781 | E5: 429408.89 | F5: 6414193.1
A6: Count of ID | B6: 15 | C6: 106 | D6: 18 | E6: 2 | F6: 141

Sheet WS - 3.1 Overall PiN
AL1: =_xlfn.CONCAT(COUNTIF(tblPiNAnalysis[Number of missing / zero PiNs greater than threshold - Data quality],"Flagged"), "/", COUNTA(tblPiNAnalysis[Number of missing / zero PiNs greater than threshold - Data quality]), " (", ROUND((COUNTIF(tblPiNAnalysis[Number of missing / zero PiNs greater than threshold - Data quality],"Flagged")/(COUNTA(tblPiNAnalysis[Number of missing / zero PiNs greater than threshold - Data quality]) + COUNTBLANK(tblPiNAnalysis[Number of missing / zero PiNs greater than threshold - Data quality])))*100, 0), "%) flagged") -> 3/141 (1%) flagged | AM1: =_xlfn.CONCAT(COUNTIF(tblPiNAnalysis[Highest PiN greater than 90% of total affected population],"Flagged"), "/", COUNTA(tblPiNAnalysis[Admin 1]), " (", ROUND((COUNTIF(tblPiNAnalysis[Highest PiN greater than 90% of total affected population],"Flagged")/(COUNTA(tblPiNAnalysis[Highest PiN greater than 90% of total affected population]) + COUNTBLANK(tblPiNAnalysis[Highest PiN greater than 90% of total affected population])))*100, 0), "%) flagged") -> 13/141 (5%) flagged | AN1: =_xlfn.CONCAT(COUNTIF(tblPiNAnalysis[Highest sector targets sub-population group(s)],"Flagged"), "/", COUNTA(tblPiNAnalysis[Admin 1]), " (", ROUND((COUNTIF(tblPiNAnalysis[Highest sector targets sub-population group(s)],"Flagged")/(COUNTA(tblPiNAnalysis[Highest sector targets sub-population group(s)]) + COUNTBLANK(tblPiNAnalysis[Highest sector targets sub-population group(s)])))*100, 0), "%) flagged") -> 0/141 (0%) flagged | AT1: =_xlfn.CONCAT(COUNTIF(tblPiNAnalysis[% difference is over a specified threshold between Highest and 2nd Highest],"Flagged"), "/", COUNTA(tblPiNAnalysis[Admin 1]), " (", ROUND((COUNTIF(tblPiNAnalysis[% difference is over a specified threshold between Highest and 2nd Highest],"Flagged")/(COUNTA(tblPiNAnalysis[% difference is over a specified threshold between Highest and 2nd Highest]) + COUNTBLANK(tblPiNAnalysis[% difference is over a specified threshold between Highest and 2nd Highest])))*100, 0), "%) flagged") -> 48/141 (21%) flagged | AZ1: =_xlfn.CONCAT(COUNTIF(tblPiNAnalysis[% difference is over a specified threshold between Highest and 3rd Highest],"Flagged"), "/", COUNTA(tblPiNAnalysis[Admin 1]), " (", ROUND((COUNTIF(tblPiNAnalysis[% difference is over a specified threshold between Highest and 3rd Highest],"Flagged")/(COUNTA(tblPiNAnalysis[% difference is over a specified threshold between Highest and 3rd Highest]) + COUNTBLANK(tblPiNAnalysis[% difference is over a specified threshold between Highest and 3rd Highest])))*100, 0), "%) flagged") -> 78/141 (38%) flagged | BB1: =_xlfn.CONCAT(COUNTIF(tblPiNAnalysis[Change from last year for the highest sector(s) has significantly increased or decreased],"Flagged"), "/", COUNTA(tblPiNAnalysis[Admin 1]), " (", ROUND((COUNTIF(tblPiNAnalysis[Change from last year for the highest sector(s) has significantly increased or decreased],"Flagged")/(COUNTA(tblPiNAnalysis[Change from last year for the highest sector(s) has significantly increased or decreased]) + COUNTBLANK(tblPiNAnalysis[Change from last year for the highest sector(s) has significantly increased or decreased])))*100, 0), "%) flagged") -> 31/141 (12%) flagged | BD1: =_xlfn.CONCAT(COUNTIF(tblPiNAnalysis[Change from last year for the 2nd highest sector(s) has significantly increased or decreased],"Flagged"), "/", COUNTA(tblPiNAnalysis[Admin 1]), " (", ROUND((COUNTIF(tblPiNAnalysis[Change from last year for the 2nd highest sector(s) has significantly increased or decreased],"Flagged")/(COUNTA(tblPiNAnalysis[Change from last year for the 2nd highest sector(s) has significantly increased or decreased]) + COUNTBLANK(tblPiNAnalysis[Change from last year for the 2nd highest sector(s) has significantly increased or decreased])))*100, 0), "%) flagged") -> 19/141 (7%) flagged | BG1: =_xlfn.CONCAT(COUNTIF(tblPiNAnalysis[Manual Flag],"Flagged"), "/", COUNTA(tblPiNAnalysis[Admin 1]), " (", ROUND((COUNTIF(tblPiNAnalysis[Manual Flag],"Flagged")/(COUNTA(tblPiNAnalysis[Manual Flag]) + COUNTBLANK(tblPiNAnalysis[Manual Flag])))*100, 0), "%) flagged") -> 0/141 (0%) flagged | BI1: =_xlfn.CONCAT(COUNTIF(tblPiNAnalysis[Flagged],"Flagged"), "/", COUNTA(tblPiNAnalysis[Admin 1]), " (", ROUND((COUNTIF(tblPiNAnalysis[Flagged],"Flagged")/(COUNTA(tblPiNAnalysis[Flagged]) + COUNTBLANK(tblPiNAnalysis[Flagged])))*100, 0), "%) flagged") -> 104/141 (58%) flagged | BK1: =SUM(tblPiNAnalysis[Final PiN]) -> 6414193.1 | BN1: =SUM(tblPiNAnalysis[Preliminary TARGET 100% Sev 4&5 + 50% Sev 3]) -> 4255691.5
B2: Location | I2: Populaton | K2: Sectoral PiN (Number) | S2: Protection AoRs | W2: Sectoral % PiN (over total population) | AE2: Protection AoRs % | AI2: Highest Sector(s) | AO2: 2nd Highest Sector(s) | AR2: Difference between Highest and 2nd Highest PiN | AU2: 3rd Highest Sector(s) | AX2: Difference between Highest and 3rd Highest PiN | BA2: Historical PiN | BG2: Manual Flag | BI2: All Flags
A3: ID | B3: Admin 1 | C3: Admin 1 P-Code | D3: Admin 2 | E3: Admin 2 P-Code | F3: Admin 3 | G3: Admin 3 P-Code | H3: Pocket of need | I3: Population | J3: Population Group | K3: CCCM | L3: Education | M3: Nutrition | N3: Food Security | O3: Health | P3: Protection | Q3: Shelter | R3: WASH | S3: CP | T3: GBV | U3: Migrants | V3: _ | W3: CCCM% | X3: Education% | Y3: Nutrition% | Z3: Food Security% | AA3: Health% | AB3: Overarching Protection% | AC3: Shelter% | AD3: WASH% | AE3: Child Protection (CP)% | AF3: Gender-based Violence (GBV)% | AG3: Mine Action% | AH3: HLP% | AI3: Highest PiN | AJ3: Highest sector(s) | AK3: Highest sector(s') PiN % | AL3: Number of missing / zero PiNs greater than threshold - Data quality | AM3: Highest PiN greater than 90% of total affected population | AN3: Highest sector targets sub-population group(s) | AO3: 2nd Highest PiN | AP3: 2nd Highest sector(s) | AQ3: 2nd Highest sector PiN % | AR3: Difference of PiN between Highest and 2nd Highest | AS3: % Difference between Highest and 2nd Highest | AT3: % difference is over a specified threshold between Highest and 2nd Highest | AU3: 3rd Highest PiN | AV3: 3rd Highest sector(s) | AW3: 3rd Highest sector PiN % | AX3: Difference of PiN between Highest and 3rd Highest | AY3: % Difference between Highest and 3rd Highest | AZ3: % difference is over a specified threshold between Highest and 3rd Highest | BA3: Change from last year for the highest sector(s) | BB3: Change from last year for the highest sector(s) has significantly increased or decreased | BC3: Change from last year for the 2nd highest sector(s) | BD3: Change from last year for the 2nd highest sector(s) has significantly increased or decreased | BE3: Severity | BF3: Preliminary PiN | BG3: Manual Flag | BH3: Explanation for Manual Flag | BI3: # Flags | BJ3: Flagged | BK3: Final PiN | BL3: Evidence & Comments | BM3: PIN PRIORITIZED | BN3: Preliminary TARGET 100% Sev 4&5 + 50% Sev 3 | BO3: Preliminary TARGET 100% Sev 4&5 + 50% PIN in Sev 3 Intersect AND EXISTS Sect Sec >=4
A4: =IFERROR(_xlfn.CONCAT(IF(tblPiNAnalysis[[#This Row],[Population Group]]="", "",tblPiNAnalysis[[#This Row],[Population Group]] ), IF(tblPiNAnalysis[[#This Row],[Pocket of need]]<>"",tblPiNAnalysis[[#This Row],[Pocket of need]],), _xlfn.IFS(tblPiNAnalysis[[#This Row],[Admin 3 P-Code]]<>"", tblPiNAnalysis[[#This Row],[Admin 3 P-Code]], tblPiNAnalysis[[#This Row],[Admin 2 P-Code]]<>"", tblPiNAnalysis[[#This Row],[Admin 2 P-Code]], tblPiNAnalysis[[#This Row],[Admin 1 P-Code]]<>"", tblPiNAnalysis[[#This Row],[Admin 1 P-Code]])),"") -> Global_PopulationHT0111 | B4: Ouest | C4: HT01 | D4: Port-au-Prince | E4: HT0111 | I4: 926906 | J4: Global_Population | K4: 245716.5 | L4: 120467 | M4: 118634 | N4: 353355 | O4: 765508.09 | P4: 271807.02 | Q4: 215855 | R4: 231726.5 | W4: =IFERROR(IF(tblPiNAnalysis[[#This Row],[CCCM]]="", "", MROUND(tblPiNAnalysis[[#This Row],[CCCM]]/tblPiNAnalysis[[#This Row],[Population]], 0.05)), "") -> 0.25 | X4: =IFERROR(IF(tblPiNAnalysis[[#This Row],[Education]]="", "", MROUND(tblPiNAnalysis[[#This Row],[Education]]/tblPiNAnalysis[[#This Row],[Population]], 0.05)), "") -> 0.15 | Y4: =IFERROR(IF(tblPiNAnalysis[[#This Row],[Nutrition]]="", "", MROUND(tblPiNAnalysis[[#This Row],[Nutrition]]/tblPiNAnalysis[[#This Row],[Population]], 0.05)), "") -> 0.15 | Z4: =IFERROR(IF(tblPiNAnalysis[[#This Row],[Food Security]]="", "", MROUND(tblPiNAnalysis[[#This Row],[Food Security]]/tblPiNAnalysis[[#This Row],[Population]], 0.05)), "") -> 0.4 | AA4: =IFERROR(IF(tblPiNAnalysis[[#This Row],[Health]]="", "", MROUND(tblPiNAnalysis[[#This Row],[Health]]/tblPiNAnalysis[[#This Row],[Population]], 0.05)), "") -> 0.85 | AB4: =IFERROR(IF(tblPiNAnalysis[[#This Row],[Protection]]="", "", MROUND(tblPiNAnalysis[[#This Row],[Protection]]/tblPiNAnalysis[[#This Row],[Population]], 0.05)), "") -> 0.3 | AC4: =IFERROR(IF(tblPiNAnalysis[[#This Row],[Shelter]]="", "", MROUND(tblPiNAnalysis[[#This Row],[Shelter]]/tblPiNAnalysis[[#This Row],[Population]], 0.05)), "") -> 0.25 | AD4: =IFERROR(IF(tblPiNAnalysis[[#This Row],[WASH]]="", "", MROUND(tblPiNAnalysis[[#This Row],[WASH]]/tblPiNAnalysis[[#This Row],[Population]], 0.05)), "") -> 0.25 | AE4: =IFERROR(MROUND(tblPiNAnalysis[[#This Row],[CP]]/tblPiNAnalysis[[#This Row],[Population]], 0.05), "") -> 0 | AF4: =IFERROR(MROUND(tblPiNAnalysis[[#This Row],[GBV]]/tblPiNAnalysis[[#This Row],[Population]], 0.05), "") -> 0 | AG4: =IFERROR(MROUND(tblPiNAnalysis[[#This Row],[Migrants]]/tblPiNAnalysis[[#This Row],[Population]], 0.05), "") -> 0 | AH4: =IFERROR(MROUND(tblPiNAnalysis[[#This Row],[_]]/tblPiNAnalysis[[#This Row],[Population]], 0.05), "") -> 0 | AI4: =IFERROR(LARGE(tblPiNAnalysis[[#This Row],[CCCM]:[WASH]], 1), "") -> 765508.09 | AJ4: {=IF(tblPiNAnalysis[[#This Row],[Highest PiN]]="", "", _xlfn.TEXTJOIN(CHAR(10), TRUE, IF(tblPiNAnalysis[[#This Row],[Highest PiN]]=tblPiNAnalysis[[#This Row],[CCCM]:[WASH]], tblPiNAnalysis[[#Headers],[CCCM]:[WASH]], "")))} -> Health | AK4: =IF(tblPiNAnalysis[[#This Row],[Highest PiN]]="", "", tblPiNAnalysis[[#This Row],[Highest PiN]]/tblPiNAnalysis[[#This Row],[Population]]) -> 0.82587457 | AL4: =IF(SUM(tblPiNAnalysis[[#This Row],[CCCM]:[WASH]])=0, "",IF(COUNTIF(tblPiNAnalysis[[#This Row],[CCCM]:[WASH]],"=0")+COUNTIF(tblPiNAnalysis[[#This Row],[CCCM]:[WASH]],"")>=zero_pin_thresh, "Flagged", "")) | AM4: =IFERROR(IF(tblPiNAnalysis[[#This Row],[Highest PiN]]="", "", IF(tblPiNAnalysis[[#This Row],[Highest sector(s'') PiN %]]>=flag_pin_perc, "Flagged", "")), "") | AN4: {=IF(tblPiNAnalysis[[#This Row],[Highest PiN]]=0, "", IF(OR(COUNTIF(tblPiNAnalysis[[#This Row],[Highest sector(s)]],tblSubSectorPopulation[Sector])), "Flagged", ""))} | AO4: {=IFERROR(_xlfn.IFS(tblPiNAnalysis[[#This Row],[Highest PiN]]="", "", LARGE(tblPiNAnalysis[[#This Row],[CCCM]:[WASH]], 2) < tblPiNAnalysis[[#This Row],[Highest PiN]], LARGE(tblPiNAnalysis[[#This Row],[CCCM]:[WASH]], 2), LARGE(tblPiNAnalysis[[#This Row],[CCCM]:[WASH]], 3) < tblPiNAnalysis[[#This Row],[Highest PiN]], LARGE(tblPiNAnalysis[[#This Row],[CCCM]:[WASH]], 3), LARGE(tblPiNAnalysis[[#This Row],[CCCM]:[WASH]], 4) < tblPiNAnalysis[[#This Row],[Highest PiN]], LARGE(tblPiNAnalysis[[#This Row],[CCCM]:[WASH]], 4), LARGE(tblPiNAnalysis[[#This Row],[CCCM]:[WASH]], 5) < tblPiNAnalysis[[#This Row],[Highest PiN]], LARGE(tblPiNAnalysis[[#This Row],[CCCM]:[WASH]], 5), LARGE(tblPiNAnalysis[[#This Row],[CCCM]:[WASH]], 6) < tblPiNAnalysis[[#This Row],[Highest PiN]], LARGE(tblPiNAnalysis[[#This Row],[CCCM]:[WASH]], 6), LARGE(tblPiNAnalysis[[#This Row],[CCCM]:[WASH]], 7) <tblPiNAnalysis[[#This Row],[Highest PiN]], LARGE(tblPiNAnalysis[[#This Row],[CCCM]:[WASH]], 7), LARGE(tblPiNAnalysis[[#This Row],[CCCM]:[WASH]], 8) <= tblPiNAnalysis[[#This Row],[Highest PiN]], LARGE(tblPiNAnalysis[[#This Row],[CCCM]:[WASH]], 8)), "NA")} -> 353355 | AP4: {=IF(tblPiNAnalysis[[#This Row],[2nd Highest PiN]]="", "", _xlfn.TEXTJOIN(CHAR(10), TRUE, IF(tblPiNAnalysis[[#This Row],[2nd Highest PiN]]=tblPiNAnalysis[[#This Row],[CCCM]:[WASH]], tblPiNAnalysis[[#Headers],[CCCM]:[WASH]], "")))} -> Food Security | AQ4: =IFERROR(tblPiNAnalysis[[#This Row],[2nd Highest PiN]]/tblPiNAnalysis[[#This Row],[Population]], "") -> 0.38121989 | AR4: =IFERROR(tblPiNAnalysis[[#This Row],[Highest PiN]]-tblPiNAnalysis[[#This Row],[2nd Highest PiN]], "") -> 412153.09 | AS4: =IFERROR(((tblPiNAnalysis[[#This Row],[Highest PiN]]-tblPiNAnalysis[[#This Row],[2nd Highest PiN]])/tblPiNAnalysis[[#This Row],[2nd Highest PiN]]),"") -> 1.1663995 | AT4: {=_xlfn.IFS(tblPiNAnalysis[[#This Row],[% Difference between Highest and 2nd Highest]]="", "", SUM(IF(IF(tblPiNAnalysis[[#This Row],[Highest PiN]]=tblPiNAnalysis[[#This Row],[CCCM]:[WASH]], tblPiNAnalysis[[#Headers],[CCCM]:[WASH]], "")<>"", 1, 0))>1, "",tblPiNAnalysis[[#This Row],[% Difference between Highest and 2nd Highest]]>=perc_1st_2nd, "Flagged", TRUE(), "")} -> Flagged | AU4: {=IFERROR(_xlfn.IFS(tblPiNAnalysis[[#This Row],[2nd Highest PiN]]="", "", LARGE(tblPiNAnalysis[[#This Row],[CCCM]:[WASH]], 3) < tblPiNAnalysis[[#This Row],[2nd Highest PiN]], LARGE(tblPiNAnalysis[[#This Row],[CCCM]:[WASH]], 3), LARGE(tblPiNAnalysis[[#This Row],[CCCM]:[WASH]], 4) < tblPiNAnalysis[[#This Row],[2nd Highest PiN]], LARGE(tblPiNAnalysis[[#This Row],[CCCM]:[WASH]], 4), LARGE(tblPiNAnalysis[[#This Row],[CCCM]:[WASH]], 5) < tblPiNAnalysis[[#This Row],[2nd Highest PiN]], LARGE(tblPiNAnalysis[[#This Row],[CCCM]:[WASH]], 5), LARGE(tblPiNAnalysis[[#This Row],[CCCM]:[WASH]], 6) < tblPiNAnalysis[[#This Row],[2nd Highest PiN]], LARGE(tblPiNAnalysis[[#This Row],[CCCM]:[WASH]], 6), LARGE(tblPiNAnalysis[[#This Row],[CCCM]:[WASH]], 7) <tblPiNAnalysis[[#This Row],[2nd Highest PiN]], LARGE(tblPiNAnalysis[[#This Row],[CCCM]:[WASH]], 7), LARGE(tblPiNAnalysis[[#This Row],[CCCM]:[WASH]], 8) <= tblPiNAnalysis[[#This Row],[2nd Highest PiN]], LARGE(tblPiNAnalysis[[#This Row],[CCCM]:[WASH]], 8)), "NA")} -> 271807.02 | AV4: {=IF(tblPiNAnalysis[[#This Row],[3rd Highest PiN]]="", "", _xlfn.TEXTJOIN(CHAR(10), TRUE, IF(tblPiNAnalysis[[#This Row],[3rd Highest PiN]]=tblPiNAnalysis[[#This Row],[CCCM]:[WASH]], tblPiNAnalysis[[#Headers],[CCCM]:[WASH]], "")))} -> Protection | AW4: =IFERROR(tblPiNAnalysis[[#This Row],[3rd Highest PiN]]/tblPiNAnalysis[[#This Row],[Population]], "") -> 0.29324119 | AX4: =IFERROR(tblPiNAnalysis[[#This Row],[Highest PiN]]-tblPiNAnalysis[[#This Row],[3rd Highest PiN]],"") -> 493701.07 | AY4: =IFERROR(tblPiNAnalysis[[#This Row],[Difference of PiN between Highest and 3rd Highest]]/tblPiNAnalysis[[#This Row],[3rd Highest PiN]], "") -> 1.8163662 | AZ4: {=_xlfn.IFS(tblPiNAnalysis[[#This Row],[Difference of PiN between Highest and 3rd Highest]]="", "", SUM(IF(IF(tblPiNAnalysis[[#This Row],[Highest PiN]]=tblPiNAnalysis[[#This Row],[CCCM]:[WASH]], tblPiNAnalysis[[#Headers],[CCCM]:[WASH]], "")<>"", 1, 0))>1, "",tblPiNAnalysis[[#This Row],[% Difference between Highest and 3rd Highest]]>=perc_1st_3rd, "Flagged", 1=1, "")} -> Flagged | BA4: {=IFERROR(IF(tblPiNAnalysis[[#This Row],[ID]]="", "", INDEX(tblPiNHistorical[[CCCM]:[WASH]], MATCH(tblPiNAnalysis[[#This Row],[ID]],tblPiNHistorical[ID], 0),MATCH(_xlfn._xlws.FILTER(tblPiNAnalysis[[#Headers],[CCCM]:[WASH]], tblPiNAnalysis[[#This Row],[Highest PiN]]=tblPiNAnalysis[[#This Row],[CCCM]:[WASH]]), tblPiNHistorical[[#Headers],[CCCM]:[WASH]], 0))), "")} -> 1.1 | BB4: {=IFERROR(IF(SUM(IF(ABS(INDEX(tblPiNHistorical[[CCCM]:[WASH]], MATCH(tblPiNAnalysis[[#This Row],[ID]],tblPiNHistorical[ID], 0),MATCH(_xlfn._xlws.FILTER(tblPiNAnalysis[[#Headers],[CCCM]:[WASH]], tblPiNAnalysis[[#This Row],[Highest PiN]]=tblPiNAnalysis[[#This Row],[CCCM]:[WASH]]), tblPiNHistorical[[#Headers],[CCCM]:[WASH]], 0)))>=flag_pin_historical, 1, 0))>0, "Flagged", ""), "")} -> Flagged | BC4: {=IFERROR(IF(tblPiNAnalysis[[#This Row],[ID]]="", "", INDEX(tblPiNHistorical[[CCCM]:[WASH]], MATCH(tblPiNAnalysis[[#This Row],[ID]],tblPiNHistorical[ID], 0),MATCH(_xlfn._xlws.FILTER(tblPiNAnalysis[[#Headers],[CCCM]:[WASH]], tblPiNAnalysis[[#This Row],[2nd Highest PiN]]=tblPiNAnalysis[[#This Row],[CCCM]:[WASH]]), tblPiNHistorical[[#Headers],[CCCM]:[WASH]], 0))), "")} -> -0.2 | BD4: {=IFERROR(IF(SUM(IF(ABS(INDEX(tblPiNHistorical[[CCCM]:[WASH]], MATCH(tblPiNAnalysis[[#This Row],[ID]],tblPiNHistorical[ID], 0),MATCH(_xlfn._xlws.FILTER(tblPiNAnalysis[[#Headers],[CCCM]:[WASH]], tblPiNAnalysis[[#This Row],[2nd Highest PiN]]=tblPiNAnalysis[[#This Row],[CCCM]:[WASH]]), tblPiNHistorical[[#Headers],[CCCM]:[WASH]], 0)))>=flag_pin_historical, 1, 0))>0, "Flagged", ""), "")} | BE4: =INDEX(tblSeverityAnalysis[Final Severity], MATCH(tblPiNAnalysis[[#This Row],[ID]],tblSeverityAnalysis[ID], 0)) -> 5 | BF4: =IF(tblPiNAnalysis[[#This Row],[Severity]]>2,tblPiNAnalysis[[#This Row],[Highest PiN]],) -> 765508.09 | BI4: =COUNTIFS(tblPiNAnalysis[[#This Row],[Number of missing / zero PiNs greater than threshold - Data quality]:[Manual Flag]],"Flagged") -> 3 | BJ4: =IF(tblPiNAnalysis[[#This Row],['# Flags]]>0, "Flagged", "") -> Flagged | BK4: 353355 | BL4: 2nd highest PIN | BM4: =IF(OR(tblPiNAnalysis[[#This Row],[Severity]]=4,tblPiNAnalysis[[#This Row],[Severity]]=5),tblPiNAnalysis[[#This Row],[Final PiN]],0) -> 353355 | BN4: =IF(OR(tblPiNAnalysis[[#This Row],[Severity]]=4,tblPiNAnalysis[[#This Row],[Severity]]=5),100%, IF(tblPiNAnalysis[[#This Row],[Severity]]=3,50%,0%))*tblPiNAnalysis[[#This Row],[Final PiN]] -> 353355 | BO4: =IF(OR(tblPiNAnalysis[[#This Row],[Severity]]=4,tblPiNAnalysis[[#This Row],[Severity]]=5),100%, IF(AND(tblPiNAnalysis[[#This Row],[Severity]]=3,VLOOKUP(tblPiNAnalysis[[#This Row],[ID]],tblSeverityAnalysis[[ID]:[Highest Severity]],35,FALSE)>3),50%,0%))*tblPiNAnalysis[[#This Row],[Final PiN]] -> 353355
A5: =IFERROR(_xlfn.CONCAT(IF(tblPiNAnalysis[[#This Row],[Population Group]]="", "",tblPiNAnalysis[[#This Row],[Population Group]] ), IF(tblPiNAnalysis[[#This Row],[Pocket of need]]<>"",tblPiNAnalysis[[#This Row],[Pocket of need]],), _xlfn.IFS(tblPiNAnalysis[[#This Row],[Admin 3 P-Code]]<>"", tblPiNAnalysis[[#This Row],[Admin 3 P-Code]], tblPiNAnalysis[[#This Row],[Admin 2 P-Code]]<>"", tblPiNAnalysis[[#This Row],[Admin 2 P-Code]], tblPiNAnalysis[[#This Row],[Admin 1 P-Code]]<>"", tblPiNAnalysis[[#This Row],[Admin 1 P-Code]])),"") -> Global_PopulationHT0112 | B5: Ouest | C5: HT01 | D5: Delmas | E5: HT0112 | I5: 435779 | J5: Global_Population | K5: 115017 | L5: 43362 | M5: 54404 | N5: 85276 | O5: 108429.19 | P5: 136209.02 | Q5: 174122 | R5: 76678 | W5: =IFERROR(IF(tblPiNAnalysis[[#This Row],[CCCM]]="", "", MROUND(tblPiNAnalysis[[#This Row],[CCCM]]/tblPiNAnalysis[[#This Row],[Population]], 0.05)), "") -> 0.25 | X5: =IFERROR(IF(tblPiNAnalysis[[#This Row],[Education]]="", "", MROUND(tblPiNAnalysis[[#This Row],[Education]]/tblPiNAnalysis[[#This Row],[Population]], 0.05)), "") -> 0.1 | Y5: =IFERROR(IF(tblPiNAnalysis[[#This Row],[Nutrition]]="", "", MROUND(tblPiNAnalysis[[#This Row],[Nutrition]]/tblPiNAnalysis[[#This Row],[Population]], 0.05)), "") -> 0.1 | Z5: =IFERROR(IF(tblPiNAnalysis[[#This Row],[Food Security]]="", "", MROUND(tblPiNAnalysis[[#This Row],[Food Security]]/tblPiNAnalysis[[#This Row],[Population]], 0.05)), "") -> 0.2 | AA5: =IFERROR(IF(tblPiNAnalysis[[#This Row],[Health]]="", "", MROUND(tblPiNAnalysis[[#This Row],[Health]]/tblPiNAnalysis[[#This Row],[Population]], 0.05)), "") -> 0.25 | AB5: =IFERROR(IF(tblPiNAnalysis[[#This Row],[Protection]]="", "", MROUND(tblPiNAnalysis[[#This Row],[Protection]]/tblPiNAnalysis[[#This Row],[Population]], 0.05)), "") -> 0.3 | AC5: =IFERROR(IF(tblPiNAnalysis[[#This Row],[Shelter]]="", "", MROUND(tblPiNAnalysis[[#This Row],[Shelter]]/tblPiNAnalysis[[#This Row],[Population]], 0.05)), "") -> 0.4 | AD5: =IFERROR(IF(tblPiNAnalysis[[#This Row],[WASH]]="", "", MROUND(tblPiNAnalysis[[#This Row],[WASH]]/tblPiNAnalysis[[#This Row],[Population]], 0.05)), "") -> 0.2 | AE5: =IFERROR(MROUND(tblPiNAnalysis[[#This Row],[CP]]/tblPiNAnalysis[[#This Row],[Population]], 0.05), "") -> 0 | AF5: =IFERROR(MROUND(tblPiNAnalysis[[#This Row],[GBV]]/tblPiNAnalysis[[#This Row],[Population]], 0.05), "") -> 0 | AG5: =IFERROR(MROUND(tblPiNAnalysis[[#This Row],[Migrants]]/tblPiNAnalysis[[#This Row],[Population]], 0.05), "") -> 0 | AH5: =IFERROR(MROUND(tblPiNAnalysis[[#This Row],[_]]/tblPiNAnalysis[[#This Row],[Population]], 0.05), "") -> 0 | AI5: =IFERROR(LARGE(tblPiNAnalysis[[#This Row],[CCCM]:[WASH]], 1), "") -> 174122 | AJ5: {=IF(tblPiNAnalysis[[#This Row],[Highest PiN]]="", "", _xlfn.TEXTJOIN(CHAR(10), TRUE, IF(tblPiNAnalysis[[#This Row],[Highest PiN]]=tblPiNAnalysis[[#This Row],[CCCM]:[WASH]], tblPiNAnalysis[[#Headers],[CCCM]:[WASH]], "")))} -> Shelter | AK5: =IF(tblPiNAnalysis[[#This Row],[Highest PiN]]="", "", tblPiNAnalysis[[#This Row],[Highest PiN]]/tblPiNAnalysis[[#This Row],[Population]]) -> 0.39956492 | AL5: =IF(SUM(tblPiNAnalysis[[#This Row],[CCCM]:[WASH]])=0, "",IF(COUNTIF(tblPiNAnalysis[[#This Row],[CCCM]:[WASH]],"=0")+COUNTIF(tblPiNAnalysis[[#This Row],[CCCM]:[WASH]],"")>=zero_pin_thresh, "Flagged", "")) | AM5: =IFERROR(IF(tblPiNAnalysis[[#This Row],[Highest PiN]]="", "", IF(tblPiNAnalysis[[#This Row],[Highest sector(s'') PiN %]]>=flag_pin_perc, "Flagged", "")), "") | AN5: {=IF(tblPiNAnalysis[[#This Row],[Highest PiN]]=0, "", IF(OR(COUNTIF(tblPiNAnalysis[[#This Row],[Highest sector(s)]],tblSubSectorPopulation[Sector])), "Flagged", ""))} | AO5: {=IFERROR(_xlfn.IFS(tblPiNAnalysis[[#This Row],[Highest PiN]]="", "", LARGE(tblPiNAnalysis[[#This Row],[CCCM]:[WASH]], 2) < tblPiNAnalysis[[#This Row],[Highest PiN]], LARGE(tblPiNAnalysis[[#This Row],[CCCM]:[WASH]], 2), LARGE(tblPiNAnalysis[[#This Row],[CCCM]:[WASH]], 3) < tblPiNAnalysis[[#This Row],[Highest PiN]], LARGE(tblPiNAnalysis[[#This Row],[CCCM]:[WASH]], 3), LARGE(tblPiNAnalysis[[#This Row],[CCCM]:[WASH]], 4) < tblPiNAnalysis[[#This Row],[Highest PiN]], LARGE(tblPiNAnalysis[[#This Row],[CCCM]:[WASH]], 4), LARGE(tblPiNAnalysis[[#This Row],[CCCM]:[WASH]], 5) < tblPiNAnalysis[[#This Row],[Highest PiN]], LARGE(tblPiNAnalysis[[#This Row],[CCCM]:[WASH]], 5), LARGE(tblPiNAnalysis[[#This Row],[CCCM]:[WASH]], 6) < tblPiNAnalysis[[#This Row],[Highest PiN]], LARGE(tblPiNAnalysis[[#This Row],[CCCM]:[WASH]], 6), LARGE(tblPiNAnalysis[[#This Row],[CCCM]:[WASH]], 7) <tblPiNAnalysis[[#This Row],[Highest PiN]], LARGE(tblPiNAnalysis[[#This Row],[CCCM]:[WASH]], 7), LARGE(tblPiNAnalysis[[#This Row],[CCCM]:[WASH]], 8) <= tblPiNAnalysis[[#This Row],[Highest PiN]], LARGE(tblPiNAnalysis[[#This Row],[CCCM]:[WASH]], 8)), "NA")} -> 136209.02 | AP5: {=IF(tblPiNAnalysis[[#This Row],[2nd Highest PiN]]="", "", _xlfn.TEXTJOIN(CHAR(10), TRUE, IF(tblPiNAnalysis[[#This Row],[2nd Highest PiN]]=tblPiNAnalysis[[#This Row],[CCCM]:[WASH]], tblPiNAnalysis[[#Headers],[CCCM]:[WASH]], "")))} -> Protection | AQ5: =IFERROR(tblPiNAnalysis[[#This Row],[2nd Highest PiN]]/tblPiNAnalysis[[#This Row],[Population]], "") -> 0.31256443 | AR5: =IFERROR(tblPiNAnalysis[[#This Row],[Highest PiN]]-tblPiNAnalysis[[#This Row],[2nd Highest PiN]], "") -> 37912.984 | AS5: =IFERROR(((tblPiNAnalysis[[#This Row],[Highest PiN]]-tblPiNAnalysis[[#This Row],[2nd Highest PiN]])/tblPiNAnalysis[[#This Row],[2nd Highest PiN]]),"") -> 0.27834416 | AT5: {=_xlfn.IFS(tblPiNAnalysis[[#This Row],[% Difference between Highest and 2nd Highest]]="", "", SUM(IF(IF(tblPiNAnalysis[[#This Row],[Highest PiN]]=tblPiNAnalysis[[#This Row],[CCCM]:[WASH]], tblPiNAnalysis[[#Headers],[CCCM]:[WASH]], "")<>"", 1, 0))>1, "",tblPiNAnalysis[[#This Row],[% Difference between Highest and 2nd Highest]]>=perc_1st_2nd, "Flagged", TRUE(), "")} | AU5: {=IFERROR(_xlfn.IFS(tblPiNAnalysis[[#This Row],[2nd Highest PiN]]="", "", LARGE(tblPiNAnalysis[[#This Row],[CCCM]:[WASH]], 3) < tblPiNAnalysis[[#This Row],[2nd Highest PiN]], LARGE(tblPiNAnalysis[[#This Row],[CCCM]:[WASH]], 3), LARGE(tblPiNAnalysis[[#This Row],[CCCM]:[WASH]], 4) < tblPiNAnalysis[[#This Row],[2nd Highest PiN]], LARGE(tblPiNAnalysis[[#This Row],[CCCM]:[WASH]], 4), LARGE(tblPiNAnalysis[[#This Row],[CCCM]:[WASH]], 5) < tblPiNAnalysis[[#This Row],[2nd Highest PiN]], LARGE(tblPiNAnalysis[[#This Row],[CCCM]:[WASH]], 5), LARGE(tblPiNAnalysis[[#This Row],[CCCM]:[WASH]], 6) < tblPiNAnalysis[[#This Row],[2nd Highest PiN]], LARGE(tblPiNAnalysis[[#This Row],[CCCM]:[WASH]], 6), LARGE(tblPiNAnalysis[[#This Row],[CCCM]:[WASH]], 7) <tblPiNAnalysis[[#This Row],[2nd Highest PiN]], LARGE(tblPiNAnalysis[[#This Row],[CCCM]:[WASH]], 7), LARGE(tblPiNAnalysis[[#This Row],[CCCM]:[WASH]], 8) <= tblPiNAnalysis[[#This Row],[2nd Highest PiN]], LARGE(tblPiNAnalysis[[#This Row],[CCCM]:[WASH]], 8)), "NA")} -> 115017 | AV5: {=IF(tblPiNAnalysis[[#This Row],[3rd Highest PiN]]="", "", _xlfn.TEXTJOIN(CHAR(10), TRUE, IF(tblPiNAnalysis[[#This Row],[3rd Highest PiN]]=tblPiNAnalysis[[#This Row],[CCCM]:[WASH]], tblPiNAnalysis[[#Headers],[CCCM]:[WASH]], "")))} -> CCCM | AW5: =IFERROR(tblPiNAnalysis[[#This Row],[3rd Highest PiN]]/tblPiNAnalysis[[#This Row],[Population]], "") -> 0.26393424 | AX5: =IFERROR(tblPiNAnalysis[[#This Row],[Highest PiN]]-tblPiNAnalysis[[#This Row],[3rd Highest PiN]],"") -> 59105 | AY5: =IFERROR(tblPiNAnalysis[[#This Row],[Difference of PiN between Highest and 3rd Highest]]/tblPiNAnalysis[[#This Row],[3rd Highest PiN]], "") -> 0.51388056 | AZ5: {=_xlfn.IFS(tblPiNAnalysis[[#This Row],[Difference of PiN between Highest and 3rd Highest]]="", "", SUM(IF(IF(tblPiNAnalysis[[#This Row],[Highest PiN]]=tblPiNAnalysis[[#This Row],[CCCM]:[WASH]], tblPiNAnalysis[[#Headers],[CCCM]:[WASH]], "")<>"", 1, 0))>1, "",tblPiNAnalysis[[#This Row],[% Difference between Highest and 3rd Highest]]>=perc_1st_3rd, "Flagged", 1=1, "")} | BA5: {=IFERROR(IF(tblPiNAnalysis[[#This Row],[ID]]="", "", INDEX(tblPiNHistorical[[CCCM]:[WASH]], MATCH(tblPiNAnalysis[[#This Row],[ID]],tblPiNHistorical[ID], 0),MATCH(_xlfn._xlws.FILTER(tblPiNAnalysis[[#Headers],[CCCM]:[WASH]], tblPiNAnalysis[[#This Row],[Highest PiN]]=tblPiNAnalysis[[#This Row],[CCCM]:[WASH]]), tblPiNHistorical[[#Headers],[CCCM]:[WASH]], 0))), "")} -> 2.3 | BB5: {=IFERROR(IF(SUM(IF(ABS(INDEX(tblPiNHistorical[[CCCM]:[WASH]], MATCH(tblPiNAnalysis[[#This Row],[ID]],tblPiNHistorical[ID], 0),MATCH(_xlfn._xlws.FILTER(tblPiNAnalysis[[#Headers],[CCCM]:[WASH]], tblPiNAnalysis[[#This Row],[Highest PiN]]=tblPiNAnalysis[[#This Row],[CCCM]:[WASH]]), tblPiNHistorical[[#Headers],[CCCM]:[WASH]], 0)))>=flag_pin_historical, 1, 0))>0, "Flagged", ""), "")} -> Flagged | BC5: {=IFERROR(IF(tblPiNAnalysis[[#This Row],[ID]]="", "", INDEX(tblPiNHistorical[[CCCM]:[WASH]], MATCH(tblPiNAnalysis[[#This Row],[ID]],tblPiNHistorical[ID], 0),MATCH(_xlfn._xlws.FILTER(tblPiNAnalysis[[#Headers],[CCCM]:[WASH]], tblPiNAnalysis[[#This Row],[2nd Highest PiN]]=tblPiNAnalysis[[#This Row],[CCCM]:[WASH]]), tblPiNHistorical[[#Headers],[CCCM]:[WASH]], 0))), "")} | BD5: {=IFERROR(IF(SUM(IF(ABS(INDEX(tblPiNHistorical[[CCCM]:[WASH]], MATCH(tblPiNAnalysis[[#This Row],[ID]],tblPiNHistorical[ID], 0),MATCH(_xlfn._xlws.FILTER(tblPiNAnalysis[[#Headers],[CCCM]:[WASH]], tblPiNAnalysis[[#This Row],[2nd Highest PiN]]=tblPiNAnalysis[[#This Row],[CCCM]:[WASH]]), tblPiNHistorical[[#Headers],[CCCM]:[WASH]], 0)))>=flag_pin_historical, 1, 0))>0, "Flagged", ""), "")} | BE5: =INDEX(tblSeverityAnalysis[Final Severity], MATCH(tblPiNAnalysis[[#This Row],[ID]],tblSeverityAnalysis[ID], 0)) -> 4 | BF5: =IF(tblPiNAnalysis[[#This Row],[Severity]]>2,tblPiNAnalysis[[#This Row],[Highest PiN]],) -> 174122 | BI5: =COUNTIFS(tblPiNAnalysis[[#This Row],[Number of missing / zero PiNs greater than threshold - Data quality]:[Manual Flag]],"Flagged") -> 1 | BJ5: =IF(tblPiNAnalysis[[#This Row],['# Flags]]>0, "Flagged", "") -> Flagged | BK5: =tblPiNAnalysis[[#This Row],[Preliminary PiN]] -> 174122 | BM5: =IF(OR(tblPiNAnalysis[[#This Row],[Severity]]=4,tblPiNAnalysis[[#This Row],[Severity]]=5),tblPiNAnalysis[[#This Row],[Final PiN]],0) -> 174122 | BN5: =IF(OR(tblPiNAnalysis[[#This Row],[Severity]]=4,tblPiNAnalysis[[#This Row],[Severity]]=5),100%, IF(tblPiNAnalysis[[#This Row],[Severity]]=3,50%,0%))*tblPiNAnalysis[[#This Row],[Final PiN]] -> 174122 | BO5: =IF(OR(tblPiNAnalysis[[#This Row],[Severity]]=4,tblPiNAnalysis[[#This Row],[Severity]]=5),100%, IF(AND(tblPiNAnalysis[[#This Row],[Severity]]=3,VLOOKUP(tblPiNAnalysis[[#This Row],[ID]],tblSeverityAnalysis[[ID]:[Highest Severity]],35,FALSE)>3),50%,0%))*tblPiNAnalysis[[#This Row],[Final PiN]] -> 174122
A6: =IFERROR(_xlfn.CONCAT(IF(tblPiNAnalysis[[#This Row],[Population Group]]="", "",tblPiNAnalysis[[#This Row],[Population Group]] ), IF(tblPiNAnalysis[[#This Row],[Pocket of need]]<>"",tblPiNAnalysis[[#This Row],[Pocket of need]],), _xlfn.IFS(tblPiNAnalysis[[#This Row],[Admin 3 P-Code]]<>"", tblPiNAnalysis[[#This Row],[Admin 3 P-Code]], tblPiNAnalysis[[#This Row],[Admin 2 P-Code]]<>"", tblPiNAnalysis[[#This Row],[Admin 2 P-Code]], tblPiNAnalysis[[#This Row],[Admin 1 P-Code]]<>"", tblPiNAnalysis[[#This Row],[Admin 1 P-Code]])),"") -> Global_PopulationHT0113 | B6: Ouest | C6: HT01 | D6: Carrefour | E6: HT0113 | I6: 460506 | J6: Global_Population | K6: 14433 | L6: 73069 | M6: 54178 | N6: 115527 | O6: 317267.19 | P6: 19185.278 | Q6: 91474 | R6: 41445.54 | W6: =IFERROR(IF(tblPiNAnalysis[[#This Row],[CCCM]]="", "", MROUND(tblPiNAnalysis[[#This Row],[CCCM]]/tblPiNAnalysis[[#This Row],[Population]], 0.05)), "") -> 0.05 | X6: =IFERROR(IF(tblPiNAnalysis[[#This Row],[Education]]="", "", MROUND(tblPiNAnalysis[[#This Row],[Education]]/tblPiNAnalysis[[#This Row],[Population]], 0.05)), "") -> 0.15 | Y6: =IFERROR(IF(tblPiNAnalysis[[#This Row],[Nutrition]]="", "", MROUND(tblPiNAnalysis[[#This Row],[Nutrition]]/tblPiNAnalysis[[#This Row],[Population]], 0.05)), "") -> 0.1 | Z6: =IFERROR(IF(tblPiNAnalysis[[#This Row],[Food Security]]="", "", MROUND(tblPiNAnalysis[[#This Row],[Food Security]]/tblPiNAnalysis[[#This Row],[Population]], 0.05)), "") -> 0.25 | AA6: =IFERROR(IF(tblPiNAnalysis[[#This Row],[Health]]="", "", MROUND(tblPiNAnalysis[[#This Row],[Health]]/tblPiNAnalysis[[#This Row],[Population]], 0.05)), "") -> 0.7 | AB6: =IFERROR(IF(tblPiNAnalysis[[#This Row],[Protection]]="", "", MROUND(tblPiNAnalysis[[#This Row],[Protection]]/tblPiNAnalysis[[#This Row],[Population]], 0.05)), "") -> 0.05 | AC6: =IFERROR(IF(tblPiNAnalysis[[#This Row],[Shelter]]="", "", MROUND(tblPiNAnalysis[[#This Row],[Shelter]]/tblPiNAnalysis[[#This Row],[Population]], 0.05)), "") -> 0.2 | AD6: =IFERROR(IF(tblPiNAnalysis[[#This Row],[WASH]]="", "", MROUND(tblPiNAnalysis[[#This Row],[WASH]]/tblPiNAnalysis[[#This Row],[Population]], 0.05)), "") -> 0.1 | AE6: =IFERROR(MROUND(tblPiNAnalysis[[#This Row],[CP]]/tblPiNAnalysis[[#This Row],[Population]], 0.05), "") -> 0 | AF6: =IFERROR(MROUND(tblPiNAnalysis[[#This Row],[GBV]]/tblPiNAnalysis[[#This Row],[Population]], 0.05), "") -> 0 | AG6: =IFERROR(MROUND(tblPiNAnalysis[[#This Row],[Migrants]]/tblPiNAnalysis[[#This Row],[Population]], 0.05), "") -> 0 | AH6: =IFERROR(MROUND(tblPiNAnalysis[[#This Row],[_]]/tblPiNAnalysis[[#This Row],[Population]], 0.05), "") -> 0 | AI6: =IFERROR(LARGE(tblPiNAnalysis[[#This Row],[CCCM]:[WASH]], 1), "") -> 317267.19 | AJ6: {=IF(tblPiNAnalysis[[#This Row],[Highest PiN]]="", "", _xlfn.TEXTJOIN(CHAR(10), TRUE, IF(tblPiNAnalysis[[#This Row],[Highest PiN]]=tblPiNAnalysis[[#This Row],[CCCM]:[WASH]], tblPiNAnalysis[[#Headers],[CCCM]:[WASH]], "")))} -> Health | AK6: =IF(tblPiNAnalysis[[#This Row],[Highest PiN]]="", "", tblPiNAnalysis[[#This Row],[Highest PiN]]/tblPiNAnalysis[[#This Row],[Population]]) -> 0.68895343 | AL6: =IF(SUM(tblPiNAnalysis[[#This Row],[CCCM]:[WASH]])=0, "",IF(COUNTIF(tblPiNAnalysis[[#This Row],[CCCM]:[WASH]],"=0")+COUNTIF(tblPiNAnalysis[[#This Row],[CCCM]:[WASH]],"")>=zero_pin_thresh, "Flagged", "")) | AM6: =IFERROR(IF(tblPiNAnalysis[[#This Row],[Highest PiN]]="", "", IF(tblPiNAnalysis[[#This Row],[Highest sector(s'') PiN %]]>=flag_pin_perc, "Flagged", "")), "") | AN6: {=IF(tblPiNAnalysis[[#This Row],[Highest PiN]]=0, "", IF(OR(COUNTIF(tblPiNAnalysis[[#This Row],[Highest sector(s)]],tblSubSectorPopulation[Sector])), "Flagged", ""))} | AO6: {=IFERROR(_xlfn.IFS(tblPiNAnalysis[[#This Row],[Highest PiN]]="", "", LARGE(tblPiNAnalysis[[#This Row],[CCCM]:[WASH]], 2) < tblPiNAnalysis[[#This Row],[Highest PiN]], LARGE(tblPiNAnalysis[[#This Row],[CCCM]:[WASH]], 2), LARGE(tblPiNAnalysis[[#This Row],[CCCM]:[WASH]], 3) < tblPiNAnalysis[[#This Row],[Highest PiN]], LARGE(tblPiNAnalysis[[#This Row],[CCCM]:[WASH]], 3), LARGE(tblPiNAnalysis[[#This Row],[CCCM]:[WASH]], 4) < tblPiNAnalysis[[#This Row],[Highest PiN]], LARGE(tblPiNAnalysis[[#This Row],[CCCM]:[WASH]], 4), LARGE(tblPiNAnalysis[[#This Row],[CCCM]:[WASH]], 5) < tblPiNAnalysis[[#This Row],[Highest PiN]], LARGE(tblPiNAnalysis[[#This Row],[CCCM]:[WASH]], 5), LARGE(tblPiNAnalysis[[#This Row],[CCCM]:[WASH]], 6) < tblPiNAnalysis[[#This Row],[Highest PiN]], LARGE(tblPiNAnalysis[[#This Row],[CCCM]:[WASH]], 6), LARGE(tblPiNAnalysis[[#This Row],[CCCM]:[WASH]], 7) <tblPiNAnalysis[[#This Row],[Highest PiN]], LARGE(tblPiNAnalysis[[#This Row],[CCCM]:[WASH]], 7), LARGE(tblPiNAnalysis[[#This Row],[CCCM]:[WASH]], 8) <= tblPiNAnalysis[[#This Row],[Highest PiN]], LARGE(tblPiNAnalysis[[#This Row],[CCCM]:[WASH]], 8)), "NA")} -> 115527 | AP6: {=IF(tblPiNAnalysis[[#This Row],[2nd Highest PiN]]="", "", _xlfn.TEXTJOIN(CHAR(10), TRUE, IF(tblPiNAnalysis[[#This Row],[2nd Highest PiN]]=tblPiNAnalysis[[#This Row],[CCCM]:[WASH]], tblPiNAnalysis[[#Headers],[CCCM]:[WASH]], "")))} -> Food Security | AQ6: =IFERROR(tblPiNAnalysis[[#This Row],[2nd Highest PiN]]/tblPiNAnalysis[[#This Row],[Population]], "") -> 0.2508697 | AR6: =IFERROR(tblPiNAnalysis[[#This Row],[Highest PiN]]-tblPiNAnalysis[[#This Row],[2nd Highest PiN]], "") -> 201740.19 | AS6: =IFERROR(((tblPiNAnalysis[[#This Row],[Highest PiN]]-tblPiNAnalysis[[#This Row],[2nd Highest PiN]])/tblPiNAnalysis[[#This Row],[2nd Highest PiN]]),"") -> 1.7462601 | AT6: {=_xlfn.IFS(tblPiNAnalysis[[#This Row],[% Difference between Highest and 2nd Highest]]="", "", SUM(IF(IF(tblPiNAnalysis[[#This Row],[Highest PiN]]=tblPiNAnalysis[[#This Row],[CCCM]:[WASH]], tblPiNAnalysis[[#Headers],[CCCM]:[WASH]], "")<>"", 1, 0))>1, "",tblPiNAnalysis[[#This Row],[% Difference between Highest and 2nd Highest]]>=perc_1st_2nd, "Flagged", TRUE(), "")} -> Flagged | AU6: {=IFERROR(_xlfn.IFS(tblPiNAnalysis[[#This Row],[2nd Highest PiN]]="", "", LARGE(tblPiNAnalysis[[#This Row],[CCCM]:[WASH]], 3) < tblPiNAnalysis[[#This Row],[2nd Highest PiN]], LARGE(tblPiNAnalysis[[#This Row],[CCCM]:[WASH]], 3), LARGE(tblPiNAnalysis[[#This Row],[CCCM]:[WASH]], 4) < tblPiNAnalysis[[#This Row],[2nd Highest PiN]], LARGE(tblPiNAnalysis[[#This Row],[CCCM]:[WASH]], 4), LARGE(tblPiNAnalysis[[#This Row],[CCCM]:[WASH]], 5) < tblPiNAnalysis[[#This Row],[2nd Highest PiN]], LARGE(tblPiNAnalysis[[#This Row],[CCCM]:[WASH]], 5), LARGE(tblPiNAnalysis[[#This Row],[CCCM]:[WASH]], 6) < tblPiNAnalysis[[#This Row],[2nd Highest PiN]], LARGE(tblPiNAnalysis[[#This Row],[CCCM]:[WASH]], 6), LARGE(tblPiNAnalysis[[#This Row],[CCCM]:[WASH]], 7) <tblPiNAnalysis[[#This Row],[2nd Highest PiN]], LARGE(tblPiNAnalysis[[#This Row],[CCCM]:[WASH]], 7), LARGE(tblPiNAnalysis[[#This Row],[CCCM]:[WASH]], 8) <= tblPiNAnalysis[[#This Row],[2nd Highest PiN]], LARGE(tblPiNAnalysis[[#This Row],[CCCM]:[WASH]], 8)), "NA")} -> 91474 | AV6: {=IF(tblPiNAnalysis[[#This Row],[3rd Highest PiN]]="", "", _xlfn.TEXTJOIN(CHAR(10), TRUE, IF(tblPiNAnalysis[[#This Row],[3rd Highest PiN]]=tblPiNAnalysis[[#This Row],[CCCM]:[WASH]], tblPiNAnalysis[[#Headers],[CCCM]:[WASH]], "")))} -> Shelter | AW6: =IFERROR(tblPiNAnalysis[[#This Row],[3rd Highest PiN]]/tblPiNAnalysis[[#This Row],[Population]], "") -> 0.19863802 | AX6: =IFERROR(tblPiNAnalysis[[#This Row],[Highest PiN]]-tblPiNAnalysis[[#This Row],[3rd Highest PiN]],"") -> 225793.19 | AY6: =IFERROR(tblPiNAnalysis[[#This Row],[Difference of PiN between Highest and 3rd Highest]]/tblPiNAnalysis[[#This Row],[3rd Highest PiN]], "") -> 2.4683865 | AZ6: {=_xlfn.IFS(tblPiNAnalysis[[#This Row],[Difference of PiN between Highest and 3rd Highest]]="", "", SUM(IF(IF(tblPiNAnalysis[[#This Row],[Highest PiN]]=tblPiNAnalysis[[#This Row],[CCCM]:[WASH]], tblPiNAnalysis[[#Headers],[CCCM]:[WASH]], "")<>"", 1, 0))>1, "",tblPiNAnalysis[[#This Row],[% Difference between Highest and 3rd Highest]]>=perc_1st_3rd, "Flagged", 1=1, "")} -> Flagged | BA6: {=IFERROR(IF(tblPiNAnalysis[[#This Row],[ID]]="", "", INDEX(tblPiNHistorical[[CCCM]:[WASH]], MATCH(tblPiNAnalysis[[#This Row],[ID]],tblPiNHistorical[ID], 0),MATCH(_xlfn._xlws.FILTER(tblPiNAnalysis[[#Headers],[CCCM]:[WASH]], tblPiNAnalysis[[#This Row],[Highest PiN]]=tblPiNAnalysis[[#This Row],[CCCM]:[WASH]]), tblPiNHistorical[[#Headers],[CCCM]:[WASH]], 0))), "")} -> 4.2 | BB6: {=IFERROR(IF(SUM(IF(ABS(INDEX(tblPiNHistorical[[CCCM]:[WASH]], MATCH(tblPiNAnalysis[[#This Row],[ID]],tblPiNHistorical[ID], 0),MATCH(_xlfn._xlws.FILTER(tblPiNAnalysis[[#Headers],[CCCM]:[WASH]], tblPiNAnalysis[[#This Row],[Highest PiN]]=tblPiNAnalysis[[#This Row],[CCCM]:[WASH]]), tblPiNHistorical[[#Headers],[CCCM]:[WASH]], 0)))>=flag_pin_historical, 1, 0))>0, "Flagged", ""), "")} -> Flagged | BC6: {=IFERROR(IF(tblPiNAnalysis[[#This Row],[ID]]="", "", INDEX(tblPiNHistorical[[CCCM]:[WASH]], MATCH(tblPiNAnalysis[[#This Row],[ID]],tblPiNHistorical[ID], 0),MATCH(_xlfn._xlws.FILTER(tblPiNAnalysis[[#Headers],[CCCM]:[WASH]], tblPiNAnalysis[[#This Row],[2nd Highest PiN]]=tblPiNAnalysis[[#This Row],[CCCM]:[WASH]]), tblPiNHistorical[[#Headers],[CCCM]:[WASH]], 0))), "")} -> 0 | BD6: {=IFERROR(IF(SUM(IF(ABS(INDEX(tblPiNHistorical[[CCCM]:[WASH]], MATCH(tblPiNAnalysis[[#This Row],[ID]],tblPiNHistorical[ID], 0),MATCH(_xlfn._xlws.FILTER(tblPiNAnalysis[[#Headers],[CCCM]:[WASH]], tblPiNAnalysis[[#This Row],[2nd Highest PiN]]=tblPiNAnalysis[[#This Row],[CCCM]:[WASH]]), tblPiNHistorical[[#Headers],[CCCM]:[WASH]], 0)))>=flag_pin_historical, 1, 0))>0, "Flagged", ""), "")} | BE6: =INDEX(tblSeverityAnalysis[Final Severity], MATCH(tblPiNAnalysis[[#This Row],[ID]],tblSeverityAnalysis[ID], 0)) -> 4 | BF6: =IF(tblPiNAnalysis[[#This Row],[Severity]]>2,tblPiNAnalysis[[#This Row],[Highest PiN]],) -> 317267.19 | BI6: =COUNTIFS(tblPiNAnalysis[[#This Row],[Number of missing / zero PiNs greater than threshold - Data quality]:[Manual Flag]],"Flagged") -> 3 | BJ6: =IF(tblPiNAnalysis[[#This Row],['# Flags]]>0, "Flagged", "") -> Flagged | BK6: 115527 | BL6: 2nd highest PIN | BM6: =IF(OR(tblPiNAnalysis[[#This Row],[Severity]]=4,tblPiNAnalysis[[#This Row],[Severity]]=5),tblPiNAnalysis[[#This Row],[Final PiN]],0) -> 115527 | BN6: =IF(OR(tblPiNAnalysis[[#This Row],[Severity]]=4,tblPiNAnalysis[[#This Row],[Severity]]=5),100%, IF(tblPiNAnalysis[[#This Row],[Severity]]=3,50%,0%))*tblPiNAnalysis[[#This Row],[Final PiN]] -> 115527 | BO6: =IF(OR(tblPiNAnalysis[[#This Row],[Severity]]=4,tblPiNAnalysis[[#This Row],[Severity]]=5),100%, IF(AND(tblPiNAnalysis[[#This Row],[Severity]]=3,VLOOKUP(tblPiNAnalysis[[#This Row],[ID]],tblSeverityAnalysis[[ID]:[Highest Severity]],35,FALSE)>3),50%,0%))*tblPiNAnalysis[[#This Row],[Final PiN]] -> 115527
A7: =IFERROR(_xlfn.CONCAT(IF(tblPiNAnalysis[[#This Row],[Population Group]]="", "",tblPiNAnalysis[[#This Row],[Population Group]] ), IF(tblPiNAnalysis[[#This Row],[Pocket of need]]<>"",tblPiNAnalysis[[#This Row],[Pocket of need]],), _xlfn.IFS(tblPiNAnalysis[[#This Row],[Admin 3 P-Code]]<>"", tblPiNAnalysis[[#This Row],[Admin 3 P-Code]], tblPiNAnalysis[[#This Row],[Admin 2 P-Code]]<>"", tblPiNAnalysis[[#This Row],[Admin 2 P-Code]], tblPiNAnalysis[[#This Row],[Admin 1 P-Code]]<>"", tblPiNAnalysis[[#This Row],[Admin 1 P-Code]])),"") -> Global_PopulationHT0114 | B7: Ouest | C7: HT01 | D7: Petion-Ville | E7: HT0114 | I7: 394895 | J7: Global_Population | K7: 30757.5 | L7: 24780 | M7: 38803 | N7: 97113 | O7: 103609.9 | P7: 42634.5 | Q7: 116694 | R7: 60092.717 | W7: =IFERROR(IF(tblPiNAnalysis[[#This Row],[CCCM]]="", "", MROUND(tblPiNAnalysis[[#This Row],[CCCM]]/tblPiNAnalysis[[#This Row],[Population]], 0.05)), "") -> 0.1 | X7: =IFERROR(IF(tblPiNAnalysis[[#This Row],[Education]]="", "", MROUND(tblPiNAnalysis[[#This Row],[Education]]/tblPiNAnalysis[[#This Row],[Population]], 0.05)), "") -> 0.05 | Y7: =IFERROR(IF(tblPiNAnalysis[[#This Row],[Nutrition]]="", "", MROUND(tblPiNAnalysis[[#This Row],[Nutrition]]/tblPiNAnalysis[[#This Row],[Population]], 0.05)), "") -> 0.1 | Z7: =IFERROR(IF(tblPiNAnalysis[[#This Row],[Food Security]]="", "", MROUND(tblPiNAnalysis[[#This Row],[Food Security]]/tblPiNAnalysis[[#This Row],[Population]], 0.05)), "") -> 0.25 | AA7: =IFERROR(IF(tblPiNAnalysis[[#This Row],[Health]]="", "", MROUND(tblPiNAnalysis[[#This Row],[Health]]/tblPiNAnalysis[[#This Row],[Population]], 0.05)), "") -> 0.25 | AB7: =IFERROR(IF(tblPiNAnalysis[[#This Row],[Protection]]="", "", MROUND(tblPiNAnalysis[[#This Row],[Protection]]/tblPiNAnalysis[[#This Row],[Population]], 0.05)), "") -> 0.1 | AC7: =IFERROR(IF(tblPiNAnalysis[[#This Row],[Shelter]]="", "", MROUND(tblPiNAnalysis[[#This Row],[Shelter]]/tblPiNAnalysis[[#This Row],[Population]], 0.05)), "") -> 0.3 | AD7: =IFERROR(IF(tblPiNAnalysis[[#This Row],[WASH]]="", "", MROUND(tblPiNAnalysis[[#This Row],[WASH]]/tblPiNAnalysis[[#This Row],[Population]], 0.05)), "") -> 0.15 | AE7: =IFERROR(MROUND(tblPiNAnalysis[[#This Row],[CP]]/tblPiNAnalysis[[#This Row],[Population]], 0.05), "") -> 0 | AF7: =IFERROR(MROUND(tblPiNAnalysis[[#This Row],[GBV]]/tblPiNAnalysis[[#This Row],[Population]], 0.05), "") -> 0 | AG7: =IFERROR(MROUND(tblPiNAnalysis[[#This Row],[Migrants]]/tblPiNAnalysis[[#This Row],[Population]], 0.05), "") -> 0 | AH7: =IFERROR(MROUND(tblPiNAnalysis[[#This Row],[_]]/tblPiNAnalysis[[#This Row],[Population]], 0.05), "") -> 0 | AI7: =IFERROR(LARGE(tblPiNAnalysis[[#This Row],[CCCM]:[WASH]], 1), "") -> 116694 | AJ7: {=IF(tblPiNAnalysis[[#This Row],[Highest PiN]]="", "", _xlfn.TEXTJOIN(CHAR(10), TRUE, IF(tblPiNAnalysis[[#This Row],[Highest PiN]]=tblPiNAnalysis[[#This Row],[CCCM]:[WASH]], tblPiNAnalysis[[#Headers],[CCCM]:[WASH]], "")))} -> Shelter | AK7: =IF(tblPiNAnalysis[[#This Row],[Highest PiN]]="", "", tblPiNAnalysis[[#This Row],[Highest PiN]]/tblPiNAnalysis[[#This Row],[Population]]) -> 0.2955064 | AL7: =IF(SUM(tblPiNAnalysis[[#This Row],[CCCM]:[WASH]])=0, "",IF(COUNTIF(tblPiNAnalysis[[#This Row],[CCCM]:[WASH]],"=0")+COUNTIF(tblPiNAnalysis[[#This Row],[CCCM]:[WASH]],"")>=zero_pin_thresh, "Flagged", "")) | AM7: =IFERROR(IF(tblPiNAnalysis[[#This Row],[Highest PiN]]="", "", IF(tblPiNAnalysis[[#This Row],[Highest sector(s'') PiN %]]>=flag_pin_perc, "Flagged", "")), "") | AN7: {=IF(tblPiNAnalysis[[#This Row],[Highest PiN]]=0, "", IF(OR(COUNTIF(tblPiNAnalysis[[#This Row],[Highest sector(s)]],tblSubSectorPopulation[Sector])), "Flagged", ""))} | AO7: {=IFERROR(_xlfn.IFS(tblPiNAnalysis[[#This Row],[Highest PiN]]="", "", LARGE(tblPiNAnalysis[[#This Row],[CCCM]:[WASH]], 2) < tblPiNAnalysis[[#This Row],[Highest PiN]], LARGE(tblPiNAnalysis[[#This Row],[CCCM]:[WASH]], 2), LARGE(tblPiNAnalysis[[#This Row],[CCCM]:[WASH]], 3) < tblPiNAnalysis[[#This Row],[Highest PiN]], LARGE(tblPiNAnalysis[[#This Row],[CCCM]:[WASH]], 3), LARGE(tblPiNAnalysis[[#This Row],[CCCM]:[WASH]], 4) < tblPiNAnalysis[[#This Row],[Highest PiN]], LARGE(tblPiNAnalysis[[#This Row],[CCCM]:[WASH]], 4), LARGE(tblPiNAnalysis[[#This Row],[CCCM]:[WASH]], 5) < tblPiNAnalysis[[#This Row],[Highest PiN]], LARGE(tblPiNAnalysis[[#This Row],[CCCM]:[WASH]], 5), LARGE(tblPiNAnalysis[[#This Row],[CCCM]:[WASH]], 6) < tblPiNAnalysis[[#This Row],[Highest PiN]], LARGE(tblPiNAnalysis[[#This Row],[CCCM]:[WASH]], 6), LARGE(tblPiNAnalysis[[#This Row],[CCCM]:[WASH]], 7) <tblPiNAnalysis[[#This Row],[Highest PiN]], LARGE(tblPiNAnalysis[[#This Row],[CCCM]:[WASH]], 7), LARGE(tblPiNAnalysis[[#This Row],[CCCM]:[WASH]], 8) <= tblPiNAnalysis[[#This Row],[Highest PiN]], LARGE(tblPiNAnalysis[[#This Row],[CCCM]:[WASH]], 8)), "NA")} -> 103609.9 | AP7: {=IF(tblPiNAnalysis[[#This Row],[2nd Highest PiN]]="", "", _xlfn.TEXTJOIN(CHAR(10), TRUE, IF(tblPiNAnalysis[[#This Row],[2nd Highest PiN]]=tblPiNAnalysis[[#This Row],[CCCM]:[WASH]], tblPiNAnalysis[[#Headers],[CCCM]:[WASH]], "")))} -> Health | AQ7: =IFERROR(tblPiNAnalysis[[#This Row],[2nd Highest PiN]]/tblPiNAnalysis[[#This Row],[Population]], "") -> 0.26237329 | AR7: =IFERROR(tblPiNAnalysis[[#This Row],[Highest PiN]]-tblPiNAnalysis[[#This Row],[2nd Highest PiN]], "") -> 13084.099 | AS7: =IFERROR(((tblPiNAnalysis[[#This Row],[Highest PiN]]-tblPiNAnalysis[[#This Row],[2nd Highest PiN]])/tblPiNAnalysis[[#This Row],[2nd Highest PiN]]),"") -> 0.12628232 | AT7: {=_xlfn.IFS(tblPiNAnalysis[[#This Row],[% Difference between Highest and 2nd Highest]]="", "", SUM(IF(IF(tblPiNAnalysis[[#This Row],[Highest PiN]]=tblPiNAnalysis[[#This Row],[CCCM]:[WASH]], tblPiNAnalysis[[#Headers],[CCCM]:[WASH]], "")<>"", 1, 0))>1, "",tblPiNAnalysis[[#This Row],[% Difference between Highest and 2nd Highest]]>=perc_1st_2nd, "Flagged", TRUE(), "")} | AU7: {=IFERROR(_xlfn.IFS(tblPiNAnalysis[[#This Row],[2nd Highest PiN]]="", "", LARGE(tblPiNAnalysis[[#This Row],[CCCM]:[WASH]], 3) < tblPiNAnalysis[[#This Row],[2nd Highest PiN]], LARGE(tblPiNAnalysis[[#This Row],[CCCM]:[WASH]], 3), LARGE(tblPiNAnalysis[[#This Row],[CCCM]:[WASH]], 4) < tblPiNAnalysis[[#This Row],[2nd Highest PiN]], LARGE(tblPiNAnalysis[[#This Row],[CCCM]:[WASH]], 4), LARGE(tblPiNAnalysis[[#This Row],[CCCM]:[WASH]], 5) < tblPiNAnalysis[[#This Row],[2nd Highest PiN]], LARGE(tblPiNAnalysis[[#This Row],[CCCM]:[WASH]], 5), LARGE(tblPiNAnalysis[[#This Row],[CCCM]:[WASH]], 6) < tblPiNAnalysis[[#This Row],[2nd Highest PiN]], LARGE(tblPiNAnalysis[[#This Row],[CCCM]:[WASH]], 6), LARGE(tblPiNAnalysis[[#This Row],[CCCM]:[WASH]], 7) <tblPiNAnalysis[[#This Row],[2nd Highest PiN]], LARGE(tblPiNAnalysis[[#This Row],[CCCM]:[WASH]], 7), LARGE(tblPiNAnalysis[[#This Row],[CCCM]:[WASH]], 8) <= tblPiNAnalysis[[#This Row],[2nd Highest PiN]], LARGE(tblPiNAnalysis[[#This Row],[CCCM]:[WASH]], 8)), "NA")} -> 97113 | AV7: {=IF(tblPiNAnalysis[[#This Row],[3rd Highest PiN]]="", "", _xlfn.TEXTJOIN(CHAR(10), TRUE, IF(tblPiNAnalysis[[#This Row],[3rd Highest PiN]]=tblPiNAnalysis[[#This Row],[CCCM]:[WASH]], tblPiNAnalysis[[#Headers],[CCCM]:[WASH]], "")))} -> Food Security | AW7: =IFERROR(tblPiNAnalysis[[#This Row],[3rd Highest PiN]]/tblPiNAnalysis[[#This Row],[Population]], "") -> 0.24592107 | AX7: =IFERROR(tblPiNAnalysis[[#This Row],[Highest PiN]]-tblPiNAnalysis[[#This Row],[3rd Highest PiN]],"") -> 19581 | AY7: =IFERROR(tblPiNAnalysis[[#This Row],[Difference of PiN between Highest and 3rd Highest]]/tblPiNAnalysis[[#This Row],[3rd Highest PiN]], "") -> 0.20163109 | AZ7: {=_xlfn.IFS(tblPiNAnalysis[[#This Row],[Difference of PiN between Highest and 3rd Highest]]="", "", SUM(IF(IF(tblPiNAnalysis[[#This Row],[Highest PiN]]=tblPiNAnalysis[[#This Row],[CCCM]:[WASH]], tblPiNAnalysis[[#Headers],[CCCM]:[WASH]], "")<>"", 1, 0))>1, "",tblPiNAnalysis[[#This Row],[% Difference between Highest and 3rd Highest]]>=perc_1st_3rd, "Flagged", 1=1, "")} | BA7: {=IFERROR(IF(tblPiNAnalysis[[#This Row],[ID]]="", "", INDEX(tblPiNHistorical[[CCCM]:[WASH]], MATCH(tblPiNAnalysis[[#This Row],[ID]],tblPiNHistorical[ID], 0),MATCH(_xlfn._xlws.FILTER(tblPiNAnalysis[[#Headers],[CCCM]:[WASH]], tblPiNAnalysis[[#This Row],[Highest PiN]]=tblPiNAnalysis[[#This Row],[CCCM]:[WASH]]), tblPiNHistorical[[#Headers],[CCCM]:[WASH]], 0))), "")} -> 0.3 | BB7: {=IFERROR(IF(SUM(IF(ABS(INDEX(tblPiNHistorical[[CCCM]:[WASH]], MATCH(tblPiNAnalysis[[#This Row],[ID]],tblPiNHistorical[ID], 0),MATCH(_xlfn._xlws.FILTER(tblPiNAnalysis[[#Headers],[CCCM]:[WASH]], tblPiNAnalysis[[#This Row],[Highest PiN]]=tblPiNAnalysis[[#This Row],[CCCM]:[WASH]]), tblPiNHistorical[[#Headers],[CCCM]:[WASH]], 0)))>=flag_pin_historical, 1, 0))>0, "Flagged", ""), "")} | BC7: {=IFERROR(IF(tblPiNAnalysis[[#This Row],[ID]]="", "", INDEX(tblPiNHistorical[[CCCM]:[WASH]], MATCH(tblPiNAnalysis[[#This Row],[ID]],tblPiNHistorical[ID], 0),MATCH(_xlfn._xlws.FILTER(tblPiNAnalysis[[#Headers],[CCCM]:[WASH]], tblPiNAnalysis[[#This Row],[2nd Highest PiN]]=tblPiNAnalysis[[#This Row],[CCCM]:[WASH]]), tblPiNHistorical[[#Headers],[CCCM]:[WASH]], 0))), "")} -> 0.6 | BD7: {=IFERROR(IF(SUM(IF(ABS(INDEX(tblPiNHistorical[[CCCM]:[WASH]], MATCH(tblPiNAnalysis[[#This Row],[ID]],tblPiNHistorical[ID], 0),MATCH(_xlfn._xlws.FILTER(tblPiNAnalysis[[#Headers],[CCCM]:[WASH]], tblPiNAnalysis[[#This Row],[2nd Highest PiN]]=tblPiNAnalysis[[#This Row],[CCCM]:[WASH]]), tblPiNHistorical[[#Headers],[CCCM]:[WASH]], 0)))>=flag_pin_historical, 1, 0))>0, "Flagged", ""), "")} | BE7: =INDEX(tblSeverityAnalysis[Final Severity], MATCH(tblPiNAnalysis[[#This Row],[ID]],tblSeverityAnalysis[ID], 0)) -> 4 | BF7: =IF(tblPiNAnalysis[[#This Row],[Severity]]>2,tblPiNAnalysis[[#This Row],[Highest PiN]],) -> 116694 | BI7: =COUNTIFS(tblPiNAnalysis[[#This Row],[Number of missing / zero PiNs greater than threshold - Data quality]:[Manual Flag]],"Flagged") -> 0 | BJ7: =IF(tblPiNAnalysis[[#This Row],['# Flags]]>0, "Flagged", "") | BK7: =tblPiNAnalysis[[#This Row],[Preliminary PiN]] -> 116694 | BM7: =IF(OR(tblPiNAnalysis[[#This Row],[Severity]]=4,tblPiNAnalysis[[#This Row],[Severity]]=5),tblPiNAnalysis[[#This Row],[Final PiN]],0) -> 116694 | BN7: =IF(OR(tblPiNAnalysis[[#This Row],[Severity]]=4,tblPiNAnalysis[[#This Row],[Severity]]=5),100%, IF(tblPiNAnalysis[[#This Row],[Severity]]=3,50%,0%))*tblPiNAnalysis[[#This Row],[Final PiN]] -> 116694 | BO7: =IF(OR(tblPiNAnalysis[[#This Row],[Severity]]=4,tblPiNAnalysis[[#This Row],[Severity]]=5),100%, IF(AND(tblPiNAnalysis[[#This Row],[Severity]]=3,VLOOKUP(tblPiNAnalysis[[#This Row],[ID]],tblSeverityAnalysis[[ID]:[Highest Severity]],35,FALSE)>3),50%,0%))*tblPiNAnalysis[[#This Row],[Final PiN]] -> 116694
