Workbook
Name flag_pin_historical: Umbrales!$D$13
Name flag_pin_perc: Umbrales!$D$12
Name perc_1st_2nd: Umbrales!$D$9
Name perc_1st_3rd: Umbrales!$D$10
Name pin_perc: #REF!
Name sectors_sev_4: Umbrales!$D$27
Name sectors_sev_5: Umbrales!$D$26
Name zero_pin_thresh: Umbrales!$D$8

Sheet Leer
A1: Herramienta JIAF 2 3: Plantilla de estimación de la PiN y de la Severidad
A3: Warnings for all sheets! | B3: Pre-set data checks have been coded into the template and they will be implemented as soon as sector data is inserted into the template. OCHA analysis teams are free to modify the template, including additional checks or removing any checks that are deemed not useful by the analysis team. At a minimum, the following columns will need to be updated by the teams: ID: A unique identifier, automatically generated and required to link certain formulas. Do not change or delete. Geographic and Population related columns: Do not delete columns for admin units and population group; please just hide any column if not needed. Sectoral Data: sectoral header names can be changed; sector columns can be removed or added in between the first and last collumn (but do not remove the first and the last sector columns); make sure the order of the sector names match the order of their percentage column and if new sector columns are added make sure to write the formula for the percentage calculation. More importantly, Do not delete the first and last column of the sectoral data section.
A5: Sheet | B5: Description
A6: Thresholds | B6: Thresholds - Flagging criteria & thresholds: OCHA analysis team to adjust if necessary the thresholds for pre-set data checks as per agreements with partners. - Sub-population group sectors: OCHA analysis team to list all sectors targeting sub-population groups (e.g. kids, women, IDPs) in their context.
A7: Overall PiN | B7: Preliminary PiN: Highest PiN among the Sector PINs is automatically taken as the preliminary PiN.
B8: Flags and Outlier Checks: Please note that the analysis team could decide to adjust the thresholds of these indicators, in the Threshold spreadshee or eliminate flags that they consider not relevant to their contexts
B9: Number of missing or zero PiN: OCHA analysis team to decide the threshold for accepted number of sectors at unit level not to provide a PiN value or have zero PiN.
B10: Highest PiN close to the total affected population: OCHA analysis team to decide the threshold of acceptable proportion of people in need to the affected population at unit level.
B11: Highest Sector targets only a subset of the affected population: OCHA analysis team to decide the sectors that target only a subset of the affected population.
B12: Difference b/w highest and 2nd highest: OCHA analysis team to decide whether certain outliers between highest sector with 2nd or 3rd highest require flagging for review and to enter 'Flagged' in the column.
B13: Difference b/w highest and 3rd highest: OCHA analysis team to decide whether certain outliers between highest sector with 2nd or 3rd highest require flagging for review and to enter 'Flagged' in the column.
B14: % Difference between this HNO's highest or 2nd highest sector PiN to same sector in the last HNO: OCHA analysis team to decide the threshold of change for this HNO's highest or 2nd higehst sector PiN and last HNO's PiN for the same sector.
A15: PiN Historical Trend | B15: This table can be used to compare current sector PiNs to the previous year's PiNs to identify increases or decreases. The current PIN will be automatically loaded from the Overal PIN spreadsheet, provided that the unique ID of the rows match. The Previous year's HNO data needs to be loaded in the Historical Trend spreadsheet. Formulas will automatically calculate the %change from previous to current year and highlights area where PiN is 50% higher or lower than the last HNO's PiN for further investigation. Countries can decide to change this 50% threshold according to their context.
A16: PiN Visulas | B16: Two visuals that can help better understand sectoral PiN affecting percentage of affected population and the percentage of change from one HNO to the last distribution.
A17: Intersectoral Severity | B17: # of sectors falling under severity phases: The number of sectors fallen under each severity phase can help better understand and see the relationship of the sectoral severities to the preliminary intersectoral severity. Preliminary Intersectoral Severity: preliminary intersectoral severity is automatically calculated according to the logical formula. Flags and Outlier Checks: Some sectors having severity phase 5 or 4: OCHA analysis team to decide number of sectors in phase 5 or 4 to be flagged and reviewed to confirm the concentration of high sectoral severities . Variation between preliminary severity and outcome indicators: preliminary intersectoral severity is higher or lower then outcome indicators (by 1 or more).
A18: Reference Table indicators | B18: Fill in reference table indicators data at unit level to automatically calculate the severity of the indicator which will be used to compare the intersectoral severity results with. If any indicators are added, removed or modified, please make sure that the formulas correctly reflect these changes.

Sheet Umbrales
C1: ¡No elimine esta ficha ni las tablas que contiene!
C3: ¡Las tablas de esta hoja se están utilizando en fórmulas de otras hojas!
B6: PiN Criterios de señalización y umbrales | D6: Please assign the thresholds relevant for your country
A7: Nombre del marcador | B7: Descripción del marcador | C7: Umbral recomendado | D7: Umbral País | E7: Explicación de la propuesta de otro umbral | F7: Propósito
B8: Número de sectores con 0 PiN | C8: 2 | D8: 2
A9: % Diferencia entre el 1º y el 2º número más alto de PiN | B9: Umbral de diferencia porcentual entre el 1º y el 2º PiN más alto, superior al 30 % | C9: 0.3 | D9: 0.3
A10: % Diferencia entre el 1° y el 3° número más alto de PiN | B10: % umbral de diferencia entre el 1° y el 3° PiN más alto, superior al 50 % | C10: 0.5 | D10: 0.5
A11: El número de PiN del sector más alto se dirige a subgrupos de población | B11: Siempre que un clúster relacionado con un subgrupo de población sea superior a cualquier otro clúster - por ejemplo, Educación y Nutrición
A12: PiN superior al 90 % de la población total afectada | B12: Marcar dónde el 1º o el 2º PiN más alto es el 90 % de la población afectada | C12: 0.9 | D12: 0.9
A13: Variación respecto al año pasado | B13: Marcar cuando la variación con respecto al año anterior del primer o segundo PiN más alto es significativamente superior a la variación media con respecto al año anterior de todos los grupos | C13: 1 | D13: 1
A14: Marcador manual | B14: Cualquier área puede ser marcada manualmente siempre que haya una preocupación por parte de cualquier analista de la JIAF sobre las PiN
B16: PiN, Sectores de grupos de subpoblación
B17: Sector | C17: Proportion of sector target population in overall population
A18: Decision Rule for determining PIN | B18: Education
A19: 1. acepte PiN más alto sin marcadores. 2. Acepte PiN más alto después de conciliar cualquier marcador. 3. Si no hay consenso sobre el número de PiN más alto, utilice el segundo PiN más alto. 4. Si no hay consenso sobre el segundo PiN más alto, elevar la decisión al nivel de la coordinación de asuntos humanitarios (HC, por sus siglas en inglés)
B24: Severity Flagging criteria & thresholds | D24: Please assign the thresholds relevant for your country
B25: Criterio de marcado para PiN | C25: Umbral recomendado | D25: Umbral País | E25: Explicación de la propuesta de otro umbral
B26: Nº de sectores en fase 5 | C26: 2 | D26: 2
B27: Nº de sectores en fase 4 o inferior con preliminares en fase 5 | C27: 5 | D27: 5
B31: Población meta y priorizada
B32: Criterios para población meta | C32: Umbral recomendado | D32: Umbral País
B33: Porcentage para areas en Severidad 3 | C33: 0.5 | D33: 0.5
B34: Porcentage para areas en Severidad 4 y 5 | C34: 1 | D34: 1

Sheet Tendencia histórica de PiN
I1: =SUM(tblPiNHistorical[SAMV25]) -> 4384836 | J1: =SUM(tblPiNHistorical[NUT25]) -> 1172289 | K1: =SUM(tblPiNHistorical[SAL25]) -> 7088469 | L1: =SUM(tblPiNHistorical[EDU25]) -> 2757468.1 | M1: =SUM(tblPiNHistorical[PRO25]) -> 5500000 | N1: =SUM(tblPiNHistorical[ASH25]) -> 3616104 | O1: =SUM(tblPiNHistorical[SAMV26]) -> 5099878.7 | P1: =SUM(tblPiNHistorical[NUT26]) -> 1282418.4 | Q1: =SUM(tblPiNHistorical[SAL26]) -> 10537415 | R1: =SUM(tblPiNHistorical[EDU26]) -> 3254789.7 | S1: =SUM(tblPiNHistorical[PRO26]) -> 5969598.4 | T1: =SUM(tblPiNHistorical[ASH26]) -> 5179743.4
B2: Ubicación | G2: Población | I2: PiN de los grupos del año anterior | O2: PiN de las agrupaciones actuales | U2: Diferencias absolutas de PiN | AA2: % Diferencias PiN
A3: ID | B3: Admin 1 | C3: Admin 1 Código P | D3: Admin 2 | E3: Admin 2 Código P | F3: Foco de necesidades | G3: Población | H3: Grupo de población | I3: SAMV25 | J3: NUT25 | K3: SAL25 | L3: EDU25 | M3: PRO25 | N3: ASH25 | O3: SAMV26 | P3: NUT26 | Q3: SAL26 | R3: EDU26 | S3: PRO26 | T3: ASH26 | U3: Diferencia PiN para SAM | V3: Diferencia PiN para NUT | W3: Diferencia PiN para SAL | X3: Diferencia PiN para EDU | Y3: Diferencia PiN para PRO | Z3: Diferencia PiN para ASH | AA3: SAMV | AB3: NUT | AC3: SAL | AD3: EDU | AE3: PRO | AF3: ASH
A4: =IFERROR(_xlfn.CONCAT(IF(tblPiNHistorical[[#This Row],[Grupo de población]]="", "",tblPiNHistorical[[#This Row],[Grupo de población]] ), IF(tblPiNHistorical[[#This Row],[Foco de necesidades]]<>"",tblPiNHistorical[[#This Row],[Foco de necesidades]],), _xlfn.IFS(tblPiNHistorical[[#This Row],[Admin 2 Código P]]<>"", tblPiNHistorical[[#This Row],[Admin 2 Código P]], tblPiNHistorical[[#This Row],[Admin 1 Código P]]<>"", tblPiNHistorical[[#This Row],[Admin 1 Código P]])),"") -> VenezolanosVE0101 | B4: Distrito Capital | C4: VE01 | D4: Libertador | E4: VE0101 | G4: 1943901 | H4: Venezolanos | I4: 328568 | J4: 71637 | K4: 506111.22 | L4: 80105.145 | M4: 519174.25 | N4: 388780 | O4: =tblPiNAnalysis[[#This Row],[SAMV]] -> 407399 | P4: =tblPiNAnalysis[[#This Row],[NUT]] -> 72481.959 | Q4: =tblPiNAnalysis[[#This Row],[SAL]] -> 725544.08 | R4: =tblPiNAnalysis[[#This Row],[EDU]] -> 246169.73 | S4: =tblPiNAnalysis[[#This Row],[PRO]] -> 475623.18 | T4: =tblPiNAnalysis[[#This Row],[ASH]] -> 268351.92 | U4: =IF(OR(tblPiNHistorical[[#This Row],[SAMV25]]="", tblPiNHistorical[[#This Row],[SAMV25]]=0, tblPiNHistorical[[#This Row],[SAMV26]]="", tblPiNHistorical[[#This Row],[SAMV26]]=0), "", tblPiNHistorical[[#This Row],[SAMV26]]-tblPiNHistorical[[#This Row],[SAMV25]]) -> 78831 | V4: =IF(OR(tblPiNHistorical[[#This Row],[NUT25]]="", tblPiNHistorical[[#This Row],[NUT25]]=0, tblPiNHistorical[[#This Row],[NUT26]]="", tblPiNHistorical[[#This Row],[NUT26]]=0), "", tblPiNHistorical[[#This Row],[NUT26]]-tblPiNHistorical[[#This Row],[NUT25]]) -> 844.95942 | W4: =IF(OR(tblPiNHistorical[[#This Row],[SAL25]]="", tblPiNHistorical[[#This Row],[SAL25]]=0, tblPiNHistorical[[#This Row],[SAL26]]="", tblPiNHistorical[[#This Row],[SAL26]]=0), "", tblPiNHistorical[[#This Row],[SAL26]]-tblPiNHistorical[[#This Row],[SAL25]]) -> 219432.86 | X4: =IF(OR(tblPiNHistorical[[#This Row],[EDU25]]="", tblPiNHistorical[[#This Row],[EDU25]]=0, tblPiNHistorical[[#This Row],[EDU26]]="", tblPiNHistorical[[#This Row],[EDU26]]=0), "", tblPiNHistorical[[#This Row],[EDU26]]-tblPiNHistorical[[#This Row],[EDU25]]) -> 166064.59 | Y4: =IF(OR(tblPiNHistorical[[#This Row],[PRO25]]="", tblPiNHistorical[[#This Row],[PRO25]]=0, tblPiNHistorical[[#This Row],[PRO26]]="", tblPiNHistorical[[#This Row],[PRO26]]=0), "", tblPiNHistorical[[#This Row],[PRO26]]-tblPiNHistorical[[#This Row],[PRO25]]) -> -43551.073 | Z4: =IF(OR(tblPiNHistorical[[#This Row],[ASH25]]="", tblPiNHistorical[[#This Row],[ASH25]]=0, tblPiNHistorical[[#This Row],[ASH26]]="", tblPiNHistorical[[#This Row],[ASH26]]=0), "", tblPiNHistorical[[#This Row],[ASH26]]-tblPiNHistorical[[#This Row],[ASH25]]) -> -120428.08 | AA4: =IF(AND(tblPiNHistorical[[#This Row],[SAMV25]]=0,tblPiNHistorical[[#This Row],[SAMV26]]>0),"New26 "&tblPiNHistorical[[#This Row],[SAMV26]], IF(AND(tblPiNHistorical[[#This Row],[SAMV25]]>0,tblPiNHistorical[[#This Row],[SAMV26]]=0),"NoPIN26 "&tblPiNHistorical[[#This Row],[SAMV25]], IFERROR(ROUND((tblPiNHistorical[[#This Row],[SAMV26]]-tblPiNHistorical[[#This Row],[SAMV25]])/tblPiNHistorical[[#This Row],[SAMV25]], 1), "") )) -> 0.2 | AB4: =IF(AND(tblPiNHistorical[[#This Row],[NUT25]]=0,tblPiNHistorical[[#This Row],[NUT26]]>0),"New26 "&tblPiNHistorical[[#This Row],[NUT26]], IF(AND(tblPiNHistorical[[#This Row],[NUT25]]>0,tblPiNHistorical[[#This Row],[NUT26]]=0),"NoPIN26 "&tblPiNHistorical[[#This Row],[NUT25]], IFERROR(ROUND((tblPiNHistorical[[#This Row],[NUT26]]-tblPiNHistorical[[#This Row],[NUT25]])/tblPiNHistorical[[#This Row],[NUT25]], 1), "") )) -> 0 | AC4: =IF(AND(tblPiNHistorical[[#This Row],[SAL25]]=0,tblPiNHistorical[[#This Row],[SAL26]]>0),"New26 "&tblPiNHistorical[[#This Row],[SAL26]], IF(AND(tblPiNHistorical[[#This Row],[SAL25]]>0,tblPiNHistorical[[#This Row],[SAL26]]=0),"NoPIN26 "&tblPiNHistorical[[#This Row],[SAL25]], IFERROR(ROUND((tblPiNHistorical[[#This Row],[SAL26]]-tblPiNHistorical[[#This Row],[SAL25]])/tblPiNHistorical[[#This Row],[SAL25]], 1), "") )) -> 0.4 | AD4: =IF(AND(tblPiNHistorical[[#This Row],[EDU25]]=0,tblPiNHistorical[[#This Row],[EDU26]]>0),"New26 "&tblPiNHistorical[[#This Row],[EDU26]], IF(AND(tblPiNHistorical[[#This Row],[EDU25]]>0,tblPiNHistorical[[#This Row],[EDU26]]=0),"NoPIN26 "&tblPiNHistorical[[#This Row],[EDU25]], IFERROR(ROUND((tblPiNHistorical[[#This Row],[EDU26]]-tblPiNHistorical[[#This Row],[EDU25]])/tblPiNHistorical[[#This Row],[EDU25]], 1), "") )) -> 2.1 | AE4: =IF(AND(tblPiNHistorical[[#This Row],[PRO25]]=0,tblPiNHistorical[[#This Row],[PRO26]]>0),"New26 "&tblPiNHistorical[[#This Row],[PRO26]], IF(AND(tblPiNHistorical[[#This Row],[PRO25]]>0,tblPiNHistorical[[#This Row],[PRO26]]=0),"NoPIN26 "&tblPiNHistorical[[#This Row],[PRO25]], IFERROR(ROUND((tblPiNHistorical[[#This Row],[PRO26]]-tblPiNHistorical[[#This Row],[PRO25]])/tblPiNHistorical[[#This Row],[PRO25]], 1), "") )) -> -0.1 | AF4: =IF(AND(tblPiNHistorical[[#This Row],[ASH25]]=0,tblPiNHistorical[[#This Row],[ASH26]]>0),"New26 "&tblPiNHistorical[[#This Row],[ASH26]], IF(AND(tblPiNHistorical[[#This Row],[ASH25]]>0,tblPiNHistorical[[#This Row],[ASH26]]=0),"NoPIN26 "&tblPiNHistorical[[#This Row],[ASH25]], IFERROR(ROUND((tblPiNHistorical[[#This Row],[ASH26]]-tblPiNHistorical[[#This Row],[ASH25]])/tblPiNHistorical[[#This Row],[ASH25]], 1), "") )) -> -0.3
A5: =IFERROR(_xlfn.CONCAT(IF(tblPiNHistorical[[#This Row],[Grupo de población]]="", "",tblPiNHistorical[[#This Row],[Grupo de población]] ), IF(tblPiNHistorical[[#This Row],[Foco de necesidades]]<>"",tblPiNHistorical[[#This Row],[Foco de necesidades]],), _xlfn.IFS(tblPiNHistorical[[#This Row],[Admin 2 Código P]]<>"", tblPiNHistorical[[#This Row],[Admin 2 Código P]], tblPiNHistorical[[#This Row],[Admin 1 Código P]]<>"", tblPiNHistorical[[#This Row],[Admin 1 Código P]])),"") -> VenezolanosVE0201 | B5: Amazonas | C5: VE02 | D5: Autónomo Alto Orinoco | E5: VE0201 | G5: 12687 | H5: Venezolanos | I5: 2537 | J5: 966 | K5: 3303.3057 | L5: 3996.6147 | M5: 1990.6302 | N5: 6344 | O5: =tblPiNAnalysis[[#This Row],[SAMV]] -> 236854 | P5: =tblPiNAnalysis[[#This Row],[NUT]] -> 74440.982 | Q5: =tblPiNAnalysis[[#This Row],[SAL]] -> 544725.64 | R5: =tblPiNAnalysis[[#This Row],[EDU]] -> 276989.54 | S5: =tblPiNAnalysis[[#This Row],[PRO]] -> 355702.25 | T5: =tblPiNAnalysis[[#This Row],[ASH]] -> 201473.87 | U5: =IF(OR(tblPiNHistorical[[#This Row],[SAMV25]]="", tblPiNHistorical[[#This Row],[SAMV25]]=0, tblPiNHistorical[[#This Row],[SAMV26]]="", tblPiNHistorical[[#This Row],[SAMV26]]=0), "", tblPiNHistorical[[#This Row],[SAMV26]]-tblPiNHistorical[[#This Row],[SAMV25]]) -> 234317 | V5: =IF(OR(tblPiNHistorical[[#This Row],[NUT25]]="", tblPiNHistorical[[#This Row],[NUT25]]=0, tblPiNHistorical[[#This Row],[NUT26]]="", tblPiNHistorical[[#This Row],[NUT26]]=0), "", tblPiNHistorical[[#This Row],[NUT26]]-tblPiNHistorical[[#This Row],[NUT25]]) -> 73474.982 | W5: =IF(OR(tblPiNHistorical[[#This Row],[SAL25]]="", tblPiNHistorical[[#This Row],[SAL25]]=0, tblPiNHistorical[[#This Row],[SAL26]]="", tblPiNHistorical[[#This Row],[SAL26]]=0), "", tblPiNHistorical[[#This Row],[SAL26]]-tblPiNHistorical[[#This Row],[SAL25]]) -> 541422.33 | X5: =IF(OR(tblPiNHistorical[[#This Row],[EDU25]]="", tblPiNHistorical[[#This Row],[EDU25]]=0, tblPiNHistorical[[#This Row],[EDU26]]="", tblPiNHistorical[[#This Row],[EDU26]]=0), "", tblPiNHistorical[[#This Row],[EDU26]]-tblPiNHistorical[[#This Row],[EDU25]]) -> 272992.93 | Y5: =IF(OR(tblPiNHistorical[[#This Row],[PRO25]]="", tblPiNHistorical[[#This Row],[PRO25]]=0, tblPiNHistorical[[#This Row],[PRO26]]="", tblPiNHistorical[[#This Row],[PRO26]]=0), "", tblPiNHistorical[[#This Row],[PRO26]]-tblPiNHistorical[[#This Row],[PRO25]]) -> 353711.62 | Z5: =IF(OR(tblPiNHistorical[[#This Row],[ASH25]]="", tblPiNHistorical[[#This Row],[ASH25]]=0, tblPiNHistorical[[#This Row],[ASH26]]="", tblPiNHistorical[[#This Row],[ASH26]]=0), "", tblPiNHistorical[[#This Row],[ASH26]]-tblPiNHistorical[[#This Row],[ASH25]]) -> 195129.87 | AA5: =IF(AND(tblPiNHistorical[[#This Row],[SAMV25]]=0,tblPiNHistorical[[#This Row],[SAMV26]]>0),"New26 "&tblPiNHistorical[[#This Row],[SAMV26]], IF(AND(tblPiNHistorical[[#This Row],[SAMV25]]>0,tblPiNHistorical[[#This Row],[SAMV26]]=0),"NoPIN26 "&tblPiNHistorical[[#This Row],[SAMV25]], IFERROR(ROUND((tblPiNHistorical[[#This Row],[SAMV26]]-tblPiNHistorical[[#This Row],[SAMV25]])/tblPiNHistorical[[#This Row],[SAMV25]], 1), "") )) -> 92.4 | AB5: =IF(AND(tblPiNHistorical[[#This Row],[NUT25]]=0,tblPiNHistorical[[#This Row],[NUT26]]>0),"New26 "&tblPiNHistorical[[#This Row],[NUT26]], IF(AND(tblPiNHistorical[[#This Row],[NUT25]]>0,tblPiNHistorical[[#This Row],[NUT26]]=0),"NoPIN26 "&tblPiNHistorical[[#This Row],[NUT25]], IFERROR(ROUND((tblPiNHistorical[[#This Row],[NUT26]]-tblPiNHistorical[[#This Row],[NUT25]])/tblPiNHistorical[[#This Row],[NUT25]], 1), "") )) -> 76.1 | AC5: =IF(AND(tblPiNHistorical[[#This Row],[SAL25]]=0,tblPiNHistorical[[#This Row],[SAL26]]>0),"New26 "&tblPiNHistorical[[#This Row],[SAL26]], IF(AND(tblPiNHistorical[[#This Row],[SAL25]]>0,tblPiNHistorical[[#This Row],[SAL26]]=0),"NoPIN26 "&tblPiNHistorical[[#This Row],[SAL25]], IFERROR(ROUND((tblPiNHistorical[[#This Row],[SAL26]]-tblPiNHistorical[[#This Row],[SAL25]])/tblPiNHistorical[[#This Row],[SAL25]], 1), "") )) -> 163.9 | AD5: =IF(AND(tblPiNHistorical[[#This Row],[EDU25]]=0,tblPiNHistorical[[#This Row],[EDU26]]>0),"New26 "&tblPiNHistorical[[#This Row],[EDU26]], IF(AND(tblPiNHistorical[[#This Row],[EDU25]]>0,tblPiNHistorical[[#This Row],[EDU26]]=0),"NoPIN26 "&tblPiNHistorical[[#This Row],[EDU25]], IFERROR(ROUND((tblPiNHistorical[[#This Row],[EDU26]]-tblPiNHistorical[[#This Row],[EDU25]])/tblPiNHistorical[[#This Row],[EDU25]], 1), "") )) -> 68.3 | AE5: =IF(AND(tblPiNHistorical[[#This Row],[PRO25]]=0,tblPiNHistorical[[#This Row],[PRO26]]>0),"New26 "&tblPiNHistorical[[#This Row],[PRO26]], IF(AND(tblPiNHistorical[[#This Row],[PRO25]]>0,tblPiNHistorical[[#This Row],[PRO26]]=0),"NoPIN26 "&tblPiNHistorical[[#This Row],[PRO25]], IFERROR(ROUND((tblPiNHistorical[[#This Row],[PRO26]]-tblPiNHistorical[[#This Row],[PRO25]])/tblPiNHistorical[[#This Row],[PRO25]], 1), "") )) -> 177.7 | AF5: =IF(AND(tblPiNHistorical[[#This Row],[ASH25]]=0,tblPiNHistorical[[#This Row],[ASH26]]>0),"New26 "&tblPiNHistorical[[#This Row],[ASH26]], IF(AND(tblPiNHistorical[[#This Row],[ASH25]]>0,tblPiNHistorical[[#This Row],[ASH26]]=0),"NoPIN26 "&tblPiNHistorical[[#This Row],[ASH25]], IFERROR(ROUND((tblPiNHistorical[[#This Row],[ASH26]]-tblPiNHistorical[[#This Row],[ASH25]])/tblPiNHistorical[[#This Row],[ASH25]], 1), "") )) -> 30.8
A6: =IFERROR(_xlfn.CONCAT(IF(tblPiNHistorical[[#This Row],[Grupo de población]]="", "",tblPiNHistorical[[#This Row],[Grupo de población]] ), IF(tblPiNHistorical[[#This Row],[Foco de necesidades]]<>"",tblPiNHistorical[[#This Row],[Foco de necesidades]],), _xlfn.IFS(tblPiNHistorical[[#This Row],[Admin 2 Código P]]<>"", tblPiNHistorical[[#This Row],[Admin 2 Código P]], tblPiNHistorical[[#This Row],[Admin 1 Código P]]<>"", tblPiNHistorical[[#This Row],[Admin 1 Código P]])),"") -> VenezolanosVE0202 | B6: Amazonas | C6: VE02 | D6: Autónomo Atabapo | E6: VE0202 | G6: 9169 | H6: Venezolanos | I6: 1834 | J6: 591 | K6: 2386.8217 | L6: 1247.0257 | M6: 1990.6302 | N6: 4585 | O6: =tblPiNAnalysis[[#This Row],[SAMV]] -> 112537 | P6: =tblPiNAnalysis[[#This Row],[NUT]] -> 42739.616 | Q6: =tblPiNAnalysis[[#This Row],[SAL]] -> 309735.35 | R6: =tblPiNAnalysis[[#This Row],[EDU]] -> 128658.03 | S6: =tblPiNAnalysis[[#This Row],[PRO]] -> 202269.84 | T6: =tblPiNAnalysis[[#This Row],[ASH]] -> 381865.5 | U6: =IF(OR(tblPiNHistorical[[#This Row],[SAMV25]]="", tblPiNHistorical[[#This Row],[SAMV25]]=0, tblPiNHistorical[[#This Row],[SAMV26]]="", tblPiNHistorical[[#This Row],[SAMV26]]=0), "", tblPiNHistorical[[#This Row],[SAMV26]]-tblPiNHistorical[[#This Row],[SAMV25]]) -> 110703 | V6: =IF(OR(tblPiNHistorical[[#This Row],[NUT25]]="", tblPiNHistorical[[#This Row],[NUT25]]=0, tblPiNHistorical[[#This Row],[NUT26]]="", tblPiNHistorical[[#This Row],[NUT26]]=0), "", tblPiNHistorical[[#This Row],[NUT26]]-tblPiNHistorical[[#This Row],[NUT25]]) -> 42148.616 | W6: =IF(OR(tblPiNHistorical[[#This Row],[SAL25]]="", tblPiNHistorical[[#This Row],[SAL25]]=0, tblPiNHistorical[[#This Row],[SAL26]]="", tblPiNHistorical[[#This Row],[SAL26]]=0), "", tblPiNHistorical[[#This Row],[SAL26]]-tblPiNHistorical[[#This Row],[SAL25]]) -> 307348.53 | X6: =IF(OR(tblPiNHistorical[[#This Row],[EDU25]]="", tblPiNHistorical[[#This Row],[EDU25]]=0, tblPiNHistorical[[#This Row],[EDU26]]="", tblPiNHistorical[[#This Row],[EDU26]]=0), "", tblPiNHistorical[[#This Row],[EDU26]]-tblPiNHistorical[[#This Row],[EDU25]]) -> 127411 | Y6: =IF(OR(tblPiNHistorical[[#This Row],[PRO25]]="", tblPiNHistorical[[#This Row],[PRO25]]=0, tblPiNHistorical[[#This Row],[PRO26]]="", tblPiNHistorical[[#This Row],[PRO26]]=0), "", tblPiNHistorical[[#This Row],[PRO26]]-tblPiNHistorical[[#This Row],[PRO25]]) -> 200279.21 | Z6: =IF(OR(tblPiNHistorical[[#This Row],[ASH25]]="", tblPiNHistorical[[#This Row],[ASH25]]=0, tblPiNHistorical[[#This Row],[ASH26]]="", tblPiNHistorical[[#This Row],[ASH26]]=0), "", tblPiNHistorical[[#This Row],[ASH26]]-tblPiNHistorical[[#This Row],[ASH25]]) -> 377280.5 | AA6: =IF(AND(tblPiNHistorical[[#This Row],[SAMV25]]=0,tblPiNHistorical[[#This Row],[SAMV26]]>0),"New26 "&tblPiNHistorical[[#This Row],[SAMV26]], IF(AND(tblPiNHistorical[[#This Row],[SAMV25]]>0,tblPiNHistorical[[#This Row],[SAMV26]]=0),"NoPIN26 "&tblPiNHistorical[[#This Row],[SAMV25]], IFERROR(ROUND((tblPiNHistorical[[#This Row],[SAMV26]]-tblPiNHistorical[[#This Row],[SAMV25]])/tblPiNHistorical[[#This Row],[SAMV25]], 1), "") )) -> 60.4 | AB6: =IF(AND(tblPiNHistorical[[#This Row],[NUT25]]=0,tblPiNHistorical[[#This Row],[NUT26]]>0),"New26 "&tblPiNHistorical[[#This Row],[NUT26]], IF(AND(tblPiNHistorical[[#This Row],[NUT25]]>0,tblPiNHistorical[[#This Row],[NUT26]]=0),"NoPIN26 "&tblPiNHistorical[[#This Row],[NUT25]], IFERROR(ROUND((tblPiNHistorical[[#This Row],[NUT26]]-tblPiNHistorical[[#This Row],[NUT25]])/tblPiNHistorical[[#This Row],[NUT25]], 1), "") )) -> 71.3 | AC6: =IF(AND(tblPiNHistorical[[#This Row],[SAL25]]=0,tblPiNHistorical[[#This Row],[SAL26]]>0),"New26 "&tblPiNHistorical[[#This Row],[SAL26]], IF(AND(tblPiNHistorical[[#This Row],[SAL25]]>0,tblPiNHistorical[[#This Row],[SAL26]]=0),"NoPIN26 "&tblPiNHistorical[[#This Row],[SAL25]], IFERROR(ROUND((tblPiNHistorical[[#This Row],[SAL26]]-tblPiNHistorical[[#This Row],[SAL25]])/tblPiNHistorical[[#This Row],[SAL25]], 1), "") )) -> 128.8 | AD6: =IF(AND(tblPiNHistorical[[#This Row],[EDU25]]=0,tblPiNHistorical[[#This Row],[EDU26]]>0),"New26 "&tblPiNHistorical[[#This Row],[EDU26]], IF(AND(tblPiNHistorical[[#This Row],[EDU25]]>0,tblPiNHistorical[[#This Row],[EDU26]]=0),"NoPIN26 "&tblPiNHistorical[[#This Row],[EDU25]], IFERROR(ROUND((tblPiNHistorical[[#This Row],[EDU26]]-tblPiNHistorical[[#This Row],[EDU25]])/tblPiNHistorical[[#This Row],[EDU25]], 1), "") )) -> 102.2 | AE6: =IF(AND(tblPiNHistorical[[#This Row],[PRO25]]=0,tblPiNHistorical[[#This Row],[PRO26]]>0),"New26 "&tblPiNHistorical[[#This Row],[PRO26]], IF(AND(tblPiNHistorical[[#This Row],[PRO25]]>0,tblPiNHistorical[[#This Row],[PRO26]]=0),"NoPIN26 "&tblPiNHistorical[[#This Row],[PRO25]], IFERROR(ROUND((tblPiNHistorical[[#This Row],[PRO26]]-tblPiNHistorical[[#This Row],[PRO25]])/tblPiNHistorical[[#This Row],[PRO25]], 1), "") )) -> 100.6 | AF6: =IF(AND(tblPiNHistorical[[#This Row],[ASH25]]=0,tblPiNHistorical[[#This Row],[ASH26]]>0),"New26 "&tblPiNHistorical[[#This Row],[ASH26]], IF(AND(tblPiNHistorical[[#This Row],[ASH25]]>0,tblPiNHistorical[[#This Row],[ASH26]]=0),"NoPIN26 "&tblPiNHistorical[[#This Row],[ASH25]], IFERROR(ROUND((tblPiNHistorical[[#This Row],[ASH26]]-tblPiNHistorical[[#This Row],[ASH25]])/tblPiNHistorical[[#This Row],[ASH25]], 1), "") )) -> 82.3
A7: =IFERROR(_xlfn.CONCAT(IF(tblPiNHistorical[[#This Row],[Grupo de población]]="", "",tblPiNHistorical[[#This Row],[Grupo de población]] ), IF(tblPiNHistorical[[#This Row],[Foco de necesidades]]<>"",tblPiNHistorical[[#This Row],[Foco de necesidades]],), _xlfn.IFS(tblPiNHistorical[[#This Row],[Admin 2 Código P]]<>"", tblPiNHistorical[[#This Row],[Admin 2 Código P]], tblPiNHistorical[[#This Row],[Admin 1 Código P]]<>"", tblPiNHistorical[[#This Row],[Admin 1 Código P]])),"") -> VenezolanosVE0203 | B7: Amazonas | C7: VE02 | D7: Autónomo Atures | E7: VE0203 | G7: 104228 | H7: Venezolanos | I7: 20846 | J7: 4752 | K7: 27136.845 | L7: 9983.9079 | M7: 10714.9 | N7: 52114 | O7: =tblPiNAnalysis[[#This Row],[SAMV]] -> 92924 | P7: =tblPiNAnalysis[[#This Row],[NUT]] -> 43618.731 | Q7: =tblPiNAnalysis[[#This Row],[SAL]] -> 371835.72 | R7: =tblPiNAnalysis[[#This Row],[EDU]] -> 106430.13 | S7: =tblPiNAnalysis[[#This Row],[PRO]] -> 202318.84 | T7: =tblPiNAnalysis[[#This Row],[ASH]] -> 0 | U7: =IF(OR(tblPiNHistorical[[#This Row],[SAMV25]]="", tblPiNHistorical[[#This Row],[SAMV25]]=0, tblPiNHistorical[[#This Row],[SAMV26]]="", tblPiNHistorical[[#This Row],[SAMV26]]=0), "", tblPiNHistorical[[#This Row],[SAMV26]]-tblPiNHistorical[[#This Row],[SAMV25]]) -> 72078 | V7: =IF(OR(tblPiNHistorical[[#This Row],[NUT25]]="", tblPiNHistorical[[#This Row],[NUT25]]=0, tblPiNHistorical[[#This Row],[NUT26]]="", tblPiNHistorical[[#This Row],[NUT26]]=0), "", tblPiNHistorical[[#This Row],[NUT26]]-tblPiNHistorical[[#This Row],[NUT25]]) -> 38866.731 | W7: =IF(OR(tblPiNHistorical[[#This Row],[SAL25]]="", tblPiNHistorical[[#This Row],[SAL25]]=0, tblPiNHistorical[[#This Row],[SAL26]]="", tblPiNHistorical[[#This Row],[SAL26]]=0), "", tblPiNHistorical[[#This Row],[SAL26]]-tblPiNHistorical[[#This Row],[SAL25]]) -> 344698.88 | X7: =IF(OR(tblPiNHistorical[[#This Row],[EDU25]]="", tblPiNHistorical[[#This Row],[EDU25]]=0, tblPiNHistorical[[#This Row],[EDU26]]="", tblPiNHistorical[[#This Row],[EDU26]]=0), "", tblPiNHistorical[[#This Row],[EDU26]]-tblPiNHistorical[[#This Row],[EDU25]]) -> 96446.224 | Y7: =IF(OR(tblPiNHistorical[[#This Row],[PRO25]]="", tblPiNHistorical[[#This Row],[PRO25]]=0, tblPiNHistorical[[#This Row],[PRO26]]="", tblPiNHistorical[[#This Row],[PRO26]]=0), "", tblPiNHistorical[[#This Row],[PRO26]]-tblPiNHistorical[[#This Row],[PRO25]]) -> 191603.94 | Z7: =IF(OR(tblPiNHistorical[[#This Row],[ASH25]]="", tblPiNHistorical[[#This Row],[ASH25]]=0, tblPiNHistorical[[#This Row],[ASH26]]="", tblPiNHistorical[[#This Row],[ASH26]]=0), "", tblPiNHistorical[[#This Row],[ASH26]]-tblPiNHistorical[[#This Row],[ASH25]]) | AA7: =IF(AND(tblPiNHistorical[[#This Row],[SAMV25]]=0,tblPiNHistorical[[#This Row],[SAMV26]]>0),"New26 "&tblPiNHistorical[[#This Row],[SAMV26]], IF(AND(tblPiNHistorical[[#This Row],[SAMV25]]>0,tblPiNHistorical[[#This Row],[SAMV26]]=0),"NoPIN26 "&tblPiNHistorical[[#This Row],[SAMV25]], IFERROR(ROUND((tblPiNHistorical[[#This Row],[SAMV26]]-tblPiNHistorical[[#This Row],[SAMV25]])/tblPiNHistorical[[#This Row],[SAMV25]], 1), "") )) -> 3.5 | AB7: =IF(AND(tblPiNHistorical[[#This Row],[NUT25]]=0,tblPiNHistorical[[#This Row],[NUT26]]>0),"New26 "&tblPiNHistorical[[#This Row],[NUT26]], IF(AND(tblPiNHistorical[[#This Row],[NUT25]]>0,tblPiNHistorical[[#This Row],[NUT26]]=0),"NoPIN26 "&tblPiNHistorical[[#This Row],[NUT25]], IFERROR(ROUND((tblPiNHistorical[[#This Row],[NUT26]]-tblPiNHistorical[[#This Row],[NUT25]])/tblPiNHistorical[[#This Row],[NUT25]], 1), "") )) -> 8.2 | AC7: =IF(AND(tblPiNHistorical[[#This Row],[SAL25]]=0,tblPiNHistorical[[#This Row],[SAL26]]>0),"New26 "&tblPiNHistorical[[#This Row],[SAL26]], IF(AND(tblPiNHistorical[[#This Row],[SAL25]]>0,tblPiNHistorical[[#This Row],[SAL26]]=0),"NoPIN26 "&tblPiNHistorical[[#This Row],[SAL25]], IFERROR(ROUND((tblPiNHistorical[[#This Row],[SAL26]]-tblPiNHistorical[[#This Row],[SAL25]])/tblPiNHistorical[[#This Row],[SAL25]], 1), "") )) -> 12.7 | AD7: =IF(AND(tblPiNHistorical[[#This Row],[EDU25]]=0,tblPiNHistorical[[#This Row],[EDU26]]>0),"New26 "&tblPiNHistorical[[#This Row],[EDU26]], IF(AND(tblPiNHistorical[[#This Row],[EDU25]]>0,tblPiNHistorical[[#This Row],[EDU26]]=0),"NoPIN26 "&tblPiNHistorical[[#This Row],[EDU25]], IFERROR(ROUND((tblPiNHistorical[[#This Row],[EDU26]]-tblPiNHistorical[[#This Row],[EDU25]])/tblPiNHistorical[[#This Row],[EDU25]], 1), "") )) -> 9.7 | AE7: =IF(AND(tblPiNHistorical[[#This Row],[PRO25]]=0,tblPiNHistorical[[#This Row],[PRO26]]>0),"New26 "&tblPiNHistorical[[#This Row],[PRO26]], IF(AND(tblPiNHistorical[[#This Row],[PRO25]]>0,tblPiNHistorical[[#This Row],[PRO26]]=0),"NoPIN26 "&tblPiNHistorical[[#This Row],[PRO25]], IFERROR(ROUND((tblPiNHistorical[[#This Row],[PRO26]]-tblPiNHistorical[[#This Row],[PRO25]])/tblPiNHistorical[[#This Row],[PRO25]], 1), "") )) -> 17.9 | AF7: =IF(AND(tblPiNHistorical[[#This Row],[ASH25]]=0,tblPiNHistorical[[#This Row],[ASH26]]>0),"New26 "&tblPiNHistorical[[#This Row],[ASH26]], IF(AND(tblPiNHistorical[[#This Row],[ASH25]]>0,tblPiNHistorical[[#This Row],[ASH26]]=0),"NoPIN26 "&tblPiNHistorical[[#This Row],[ASH25]], IFERROR(ROUND((tblPiNHistorical[[#This Row],[ASH26]]-tblPiNHistorical[[#This Row],[ASH25]])/tblPiNHistorical[[#This Row],[ASH25]], 1), "") )) -> NoPIN26 52114
A8: =IFERROR(_xlfn.CONCAT(IF(tblPiNHistorical[[#This Row],[Grupo de población]]="", "",tblPiNHistorical[[#This Row],[Grupo de población]] ), IF(tblPiNHistorical[[#This Row],[Foco de necesidades]]<>"",tblPiNHistorical[[#This Row],[Foco de necesidades]],), _xlfn.IFS(tblPiNHistorical[[#This Row],[Admin 2 Código P]]<>"", tblPiNHistorical[[#This Row],[Admin 2 Código P]], tblPiNHistorical[[#This Row],[Admin 1 Código P]]<>"", tblPiNHistorical[[#This Row],[Admin 1 Código P]])),"") -> VenezolanosVE0204 | B8: Amazonas | C8: VE02 | D8: Autónomo Autana | E8: VE0204 | G8: 8352 | H8: Venezolanos | I8: 1670 | J8: 589 | K8: 2174.7919 | L8: 984.59197 | M8: 4082.8764 | N8: 4176 | O8: =tblPiNAnalysis[[#This Row],[SAMV]] -> 146423 | P8: =tblPiNAnalysis[[#This Row],[NUT]] -> 55309.996 | Q8: =tblPiNAnalysis[[#This Row],[SAL]] -> 263785.86 | R8: =tblPiNAnalysis[[#This Row],[EDU]] -> 84391.478 | S8: =tblPiNAnalysis[[#This Row],[PRO]] -> 173168.1 | T8: =tblPiNAnalysis[[#This Row],[ASH]] -> 325215.45 | U8: =IF(OR(tblPiNHistorical[[#This Row],[SAMV25]]="", tblPiNHistorical[[#This Row],[SAMV25]]=0, tblPiNHistorical[[#This Row],[SAMV26]]="", tblPiNHistorical[[#This Row],[SAMV26]]=0), "", tblPiNHistorical[[#This Row],[SAMV26]]-tblPiNHistorical[[#This Row],[SAMV25]]) -> 144753 | V8: =IF(OR(tblPiNHistorical[[#This Row],[NUT25]]="", tblPiNHistorical[[#This Row],[NUT25]]=0, tblPiNHistorical[[#This Row],[NUT26]]="", tblPiNHistorical[[#This Row],[NUT26]]=0), "", tblPiNHistorical[[#This Row],[NUT26]]-tblPiNHistorical[[#This Row],[NUT25]]) -> 54720.996 | W8: =IF(OR(tblPiNHistorical[[#This Row],[SAL25]]="", tblPiNHistorical[[#This Row],[SAL25]]=0, tblPiNHistorical[[#This Row],[SAL26]]="", tblPiNHistorical[[#This Row],[SAL26]]=0), "", tblPiNHistorical[[#This Row],[SAL26]]-tblPiNHistorical[[#This Row],[SAL25]]) -> 261611.07 | X8: =IF(OR(tblPiNHistorical[[#This Row],[EDU25]]="", tblPiNHistorical[[#This Row],[EDU25]]=0, tblPiNHistorical[[#This Row],[EDU26]]="", tblPiNHistorical[[#This Row],[EDU26]]=0), "", tblPiNHistorical[[#This Row],[EDU26]]-tblPiNHistorical[[#This Row],[EDU25]]) -> 83406.886 | Y8: =IF(OR(tblPiNHistorical[[#This Row],[PRO25]]="", tblPiNHistorical[[#This Row],[PRO25]]=0, tblPiNHistorical[[#This Row],[PRO26]]="", tblPiNHistorical[[#This Row],[PRO26]]=0), "", tblPiNHistorical[[#This Row],[PRO26]]-tblPiNHistorical[[#This Row],[PRO25]]) -> 169085.23 | Z8: =IF(OR(tblPiNHistorical[[#This Row],[ASH25]]="", tblPiNHistorical[[#This Row],[ASH25]]=0, tblPiNHistorical[[#This Row],[ASH26]]="", tblPiNHistorical[[#This Row],[ASH26]]=0), "", tblPiNHistorical[[#This Row],[ASH26]]-tblPiNHistorical[[#This Row],[ASH25]]) -> 321039.45 | AA8: =IF(AND(tblPiNHistorical[[#This Row],[SAMV25]]=0,tblPiNHistorical[[#This Row],[SAMV26]]>0),"New26 "&tblPiNHistorical[[#This Row],[SAMV26]], IF(AND(tblPiNHistorical[[#This Row],[SAMV25]]>0,tblPiNHistorical[[#This Row],[SAMV26]]=0),"NoPIN26 "&tblPiNHistorical[[#This Row],[SAMV25]], IFERROR(ROUND((tblPiNHistorical[[#This Row],[SAMV26]]-tblPiNHistorical[[#This Row],[SAMV25]])/tblPiNHistorical[[#This Row],[SAMV25]], 1), "") )) -> 86.7 | AB8: =IF(AND(tblPiNHistorical[[#This Row],[NUT25]]=0,tblPiNHistorical[[#This Row],[NUT26]]>0),"New26 "&tblPiNHistorical[[#This Row],[NUT26]], IF(AND(tblPiNHistorical[[#This Row],[NUT25]]>0,tblPiNHistorical[[#This Row],[NUT26]]=0),"NoPIN26 "&tblPiNHistorical[[#This Row],[NUT25]], IFERROR(ROUND((tblPiNHistorical[[#This Row],[NUT26]]-tblPiNHistorical[[#This Row],[NUT25]])/tblPiNHistorical[[#This Row],[NUT25]], 1), "") )) -> 92.9 | AC8: =IF(AND(tblPiNHistorical[[#This Row],[SAL25]]=0,tblPiNHistorical[[#This Row],[SAL26]]>0),"New26 "&tblPiNHistorical[[#This Row],[SAL26]], IF(AND(tblPiNHistorical[[#This Row],[SAL25]]>0,tblPiNHistorical[[#This Row],[SAL26]]=0),"NoPIN26 "&tblPiNHistorical[[#This Row],[SAL25]], IFERROR(ROUND((tblPiNHistorical[[#This Row],[SAL26]]-tblPiNHistorical[[#This Row],[SAL25]])/tblPiNHistorical[[#This Row],[SAL25]], 1), "") )) -> 120.3 | AD8: =IF(AND(tblPiNHistorical[[#This Row],[EDU25]]=0,tblPiNHistorical[[#This Row],[EDU26]]>0),"New26 "&tblPiNHistorical[[#This Row],[EDU26]], IF(AND(tblPiNHistorical[[#This Row],[EDU25]]>0,tblPiNHistorical[[#This Row],[EDU26]]=0),"NoPIN26 "&tblPiNHistorical[[#This Row],[EDU25]], IFERROR(ROUND((tblPiNHistorical[[#This Row],[EDU26]]-tblPiNHistorical[[#This Row],[EDU25]])/tblPiNHistorical[[#This Row],[EDU25]], 1), "") )) -> 84.7 | AE8: =IF(AND(tblPiNHistorical[[#This Row],[PRO25]]=0,tblPiNHistorical[[#This Row],[PRO26]]>0),"New26 "&tblPiNHistorical[[#This Row],[PRO26]], IF(AND(tblPiNHistorical[[#This Row],[PRO25]]>0,tblPiNHistorical[[#This Row],[PRO26]]=0),"NoPIN26 "&tblPiNHistorical[[#This Row],[PRO25]], IFERROR(ROUND((tblPiNHistorical[[#This Row],[PRO26]]-tblPiNHistorical[[#This Row],[PRO25]])/tblPiNHistorical[[#This Row],[PRO25]], 1), "") )) -> 41.4 | AF8: =IF(AND(tblPiNHistorical[[#This Row],[ASH25]]=0,tblPiNHistorical[[#This Row],[ASH26]]>0),"New26 "&tblPiNHistorical[[#This Row],[ASH26]], IF(AND(tblPiNHistorical[[#This Row],[ASH25]]>0,tblPiNHistorical[[#This Row],[ASH26]]=0),"NoPIN26 "&tblPiNHistorical[[#This Row],[ASH25]], IFERROR(ROUND((tblPiNHistorical[[#This Row],[ASH26]]-tblPiNHistorical[[#This Row],[ASH25]])/tblPiNHistorical[[#This Row],[ASH25]], 1), "") )) -> 76.9
A9: =IFERROR(_xlfn.CONCAT(IF(tblPiNHistorical[[#This Row],[Grupo de población]]="", "",tblPiNHistorical[[#This Row],[Grupo de población]] ), IF(tblPiNHistorical[[#This Row],[Foco de necesidades]]<>"",tblPiNHistorical[[#This Row],[Foco de necesidades]],), _xlfn.IFS(tblPiNHistorical[[#This Row],[Admin 2 Código P]]<>"", tblPiNHistorical[[#This Row],[Admin 2 Código P]], tblPiNHistorical[[#This Row],[Admin 1 Código P]]<>"", tblPiNHistorical[[#This Row],[Admin 1 Código P]])),"") -> VenezolanosVE0205 | B9: Amazonas | C9: VE02 | D9: Autónomo Maroa | E9: VE0205 | G9: 2029 | H9: Venezolanos | I9: 406 | J9: 126 | K9: 528.09296 | L9: 305.44782 | M9: 991.87694 | N9: 1217 | O9: =tblPiNAnalysis[[#This Row],[SAMV]] -> 95637 | P9: =tblPiNAnalysis[[#This Row],[NUT]] -> 32923.263 | Q9: =tblPiNAnalysis[[#This Row],[SAL]] -> 224074.23 | R9: =tblPiNAnalysis[[#This Row],[EDU]] -> 89542.975 | S9: =tblPiNAnalysis[[#This Row],[PRO]] -> 146863.51 | T9: =tblPiNAnalysis[[#This Row],[ASH]] -> 276255.9 | U9: =IF(OR(tblPiNHistorical[[#This Row],[SAMV25]]="", tblPiNHistorical[[#This Row],[SAMV25]]=0, tblPiNHistorical[[#This Row],[SAMV26]]="", tblPiNHistorical[[#This Row],[SAMV26]]=0), "", tblPiNHistorical[[#This Row],[SAMV26]]-tblPiNHistorical[[#This Row],[SAMV25]]) -> 95231 | V9: =IF(OR(tblPiNHistorical[[#This Row],[NUT25]]="", tblPiNHistorical[[#This Row],[NUT25]]=0, tblPiNHistorical[[#This Row],[NUT26]]="", tblPiNHistorical[[#This Row],[NUT26]]=0), "", tblPiNHistorical[[#This Row],[NUT26]]-tblPiNHistorical[[#This Row],[NUT25]]) -> 32797.263 | W9: =IF(OR(tblPiNHistorical[[#This Row],[SAL25]]="", tblPiNHistorical[[#This Row],[SAL25]]=0, tblPiNHistorical[[#This Row],[SAL26]]="", tblPiNHistorical[[#This Row],[SAL26]]=0), "", tblPiNHistorical[[#This Row],[SAL26]]-tblPiNHistorical[[#This Row],[SAL25]]) -> 223546.14 | X9: =IF(OR(tblPiNHistorical[[#This Row],[EDU25]]="", tblPiNHistorical[[#This Row],[EDU25]]=0, tblPiNHistorical[[#This Row],[EDU26]]="", tblPiNHistorical[[#This Row],[EDU26]]=0), "", tblPiNHistorical[[#This Row],[EDU26]]-tblPiNHistorical[[#This Row],[EDU25]]) -> 89237.527 | Y9: =IF(OR(tblPiNHistorical[[#This Row],[PRO25]]="", tblPiNHistorical[[#This Row],[PRO25]]=0, tblPiNHistorical[[#This Row],[PRO26]]="", tblPiNHistorical[[#This Row],[PRO26]]=0), "", tblPiNHistorical[[#This Row],[PRO26]]-tblPiNHistorical[[#This Row],[PRO25]]) -> 145871.63 | Z9: =IF(OR(tblPiNHistorical[[#This Row],[ASH25]]="", tblPiNHistorical[[#This Row],[ASH25]]=0, tblPiNHistorical[[#This Row],[ASH26]]="", tblPiNHistorical[[#This Row],[ASH26]]=0), "", tblPiNHistorical[[#This Row],[ASH26]]-tblPiNHistorical[[#This Row],[ASH25]]) -> 275038.9 | AA9: =IF(AND(tblPiNHistorical[[#This Row],[SAMV25]]=0,tblPiNHistorical[[#This Row],[SAMV26]]>0),"New26 "&tblPiNHistorical[[#This Row],[SAMV26]], IF(AND(tblPiNHistorical[[#This Row],[SAMV25]]>0,tblPiNHistorical[[#This Row],[SAMV26]]=0),"NoPIN26 "&tblPiNHistorical[[#This Row],[SAMV25]], IFERROR(ROUND((tblPiNHistorical[[#This Row],[SAMV26]]-tblPiNHistorical[[#This Row],[SAMV25]])/tblPiNHistorical[[#This Row],[SAMV25]], 1), "") )) -> 234.6 | AB9: =IF(AND(tblPiNHistorical[[#This Row],[NUT25]]=0,tblPiNHistorical[[#This Row],[NUT26]]>0),"New26 "&tblPiNHistorical[[#This Row],[NUT26]], IF(AND(tblPiNHistorical[[#This Row],[NUT25]]>0,tblPiNHistorical[[#This Row],[NUT26]]=0),"NoPIN26 "&tblPiNHistorical[[#This Row],[NUT25]], IFERROR(ROUND((tblPiNHistorical[[#This Row],[NUT26]]-tblPiNHistorical[[#This Row],[NUT25]])/tblPiNHistorical[[#This Row],[NUT25]], 1), "") )) -> 260.3 | AC9: =IF(AND(tblPiNHistorical[[#This Row],[SAL25]]=0,tblPiNHistorical[[#This Row],[SAL26]]>0),"New26 "&tblPiNHistorical[[#This Row],[SAL26]], IF(AND(tblPiNHistorical[[#This Row],[SAL25]]>0,tblPiNHistorical[[#This Row],[SAL26]]=0),"NoPIN26 "&tblPiNHistorical[[#This Row],[SAL25]], IFERROR(ROUND((tblPiNHistorical[[#This Row],[SAL26]]-tblPiNHistorical[[#This Row],[SAL25]])/tblPiNHistorical[[#This Row],[SAL25]], 1), "") )) -> 423.3 | AD9: =IF(AND(tblPiNHistorical[[#This Row],[EDU25]]=0,tblPiNHistorical[[#This Row],[EDU26]]>0),"New26 "&tblPiNHistorical[[#This Row],[EDU26]], IF(AND(tblPiNHistorical[[#This Row],[EDU25]]>0,tblPiNHistorical[[#This Row],[EDU26]]=0),"NoPIN26 "&tblPiNHistorical[[#This Row],[EDU25]], IFERROR(ROUND((tblPiNHistorical[[#This Row],[EDU26]]-tblPiNHistorical[[#This Row],[EDU25]])/tblPiNHistorical[[#This Row],[EDU25]], 1), "") )) -> 292.2 | AE9: =IF(AND(tblPiNHistorical[[#This Row],[PRO25]]=0,tblPiNHistorical[[#This Row],[PRO26]]>0),"New26 "&tblPiNHistorical[[#This Row],[PRO26]], IF(AND(tblPiNHistorical[[#This Row],[PRO25]]>0,tblPiNHistorical[[#This Row],[PRO26]]=0),"NoPIN26 "&tblPiNHistorical[[#This Row],[PRO25]], IFERROR(ROUND((tblPiNHistorical[[#This Row],[PRO26]]-tblPiNHistorical[[#This Row],[PRO25]])/tblPiNHistorical[[#This Row],[PRO25]], 1), "") )) -> 147.1 | AF9: =IF(AND(tblPiNHistorical[[#This Row],[ASH25]]=0,tblPiNHistorical[[#This Row],[ASH26]]>0),"New26 "&tblPiNHistorical[[#This Row],[ASH26]], IF(AND(tblPiNHistorical[[#This Row],[ASH25]]>0,tblPiNHistorical[[#This Row],[ASH26]]=0),"NoPIN26 "&tblPiNHistorical[[#This Row],[ASH25]], IFERROR(ROUND((tblPiNHistorical[[#This Row],[ASH26]]-tblPiNHistorical[[#This Row],[ASH25]])/tblPiNHistorical[[#This Row],[ASH25]], 1), "") )) -> 226
A10: =IFERROR(_xlfn.CONCAT(IF(tblPiNHistorical[[#This Row],[Grupo de población]]="", "",tblPiNHistorical[[#This Row],[Grupo de población]] ), IF(tblPiNHistorical[[#This Row],[Foco de necesidades]]<>"",tblPiNHistorical[[#This Row],[Foco de necesidades]],), _xlfn.IFS(tblPiNHistorical[[#This Row],[Admin 2 Código P]]<>"", tblPiNHistorical[[#This Row],[Admin 2 Código P]], tblPiNHistorical[[#This Row],[Admin 1 Código P]]<>"", tblPiNHistorical[[#This Row],[Admin 1 Código P]])),"") -> VenezolanosVE0206 | B10: Amazonas | C10: VE02 | D10: Autónomo Manapiare | E10: VE0206 | G10: 7715 | H10: Venezolanos | I10: 1543 | J10: 511 | K10: 2008.3385 | L10: 2095.883 | M10: 6171.5108 | N10: 3858 | O10: =tblPiNAnalysis[[#This Row],[SAMV]] -> 102118 | P10: =tblPiNAnalysis[[#This Row],[NUT]] -> 15306.588 | Q10: =tblPiNAnalysis[[#This Row],[SAL]] -> 157292.37 | R10: =tblPiNAnalysis[[#This Row],[EDU]] -> 47018.272 | S10: =tblPiNAnalysis[[#This Row],[PRO]] -> 102856.01 | T10: =tblPiNAnalysis[[#This Row],[ASH]] -> 258562.8 | U10: =IF(OR(tblPiNHistorical[[#This Row],[SAMV25]]="", tblPiNHistorical[[#This Row],[SAMV25]]=0, tblPiNHistorical[[#This Row],[SAMV26]]="", tblPiNHistorical[[#This Row],[SAMV26]]=0), "", tblPiNHistorical[[#This Row],[SAMV26]]-tblPiNHistorical[[#This Row],[SAMV25]]) -> 100575 | V10: =IF(OR(tblPiNHistorical[[#This Row],[NUT25]]="", tblPiNHistorical[[#This Row],[NUT25]]=0, tblPiNHistorical[[#This Row],[NUT26]]="", tblPiNHistorical[[#This Row],[NUT26]]=0), "", tblPiNHistorical[[#This Row],[NUT26]]-tblPiNHistorical[[#This Row],[NUT25]]) -> 14795.588 | W10: =IF(OR(tblPiNHistorical[[#This Row],[SAL25]]="", tblPiNHistorical[[#This Row],[SAL25]]=0, tblPiNHistorical[[#This Row],[SAL26]]="", tblPiNHistorical[[#This Row],[SAL26]]=0), "", tblPiNHistorical[[#This Row],[SAL26]]-tblPiNHistorical[[#This Row],[SAL25]]) -> 155284.03 | X10: =IF(OR(tblPiNHistorical[[#This Row],[EDU25]]="", tblPiNHistorical[[#This Row],[EDU25]]=0, tblPiNHistorical[[#This Row],[EDU26]]="", tblPiNHistorical[[#This Row],[EDU26]]=0), "", tblPiNHistorical[[#This Row],[EDU26]]-tblPiNHistorical[[#This Row],[EDU25]]) -> 44922.389 | Y10: =IF(OR(tblPiNHistorical[[#This Row],[PRO25]]="", tblPiNHistorical[[#This Row],[PRO25]]=0, tblPiNHistorical[[#This Row],[PRO26]]="", tblPiNHistorical[[#This Row],[PRO26]]=0), "", tblPiNHistorical[[#This Row],[PRO26]]-tblPiNHistorical[[#This Row],[PRO25]]) -> 96684.504 | Z10: =IF(OR(tblPiNHistorical[[#This Row],[ASH25]]="", tblPiNHistorical[[#This Row],[ASH25]]=0, tblPiNHistorical[[#This Row],[ASH26]]="", tblPiNHistorical[[#This Row],[ASH26]]=0), "", tblPiNHistorical[[#This Row],[ASH26]]-tblPiNHistorical[[#This Row],[ASH25]]) -> 254704.8 | AA10: =IF(AND(tblPiNHistorical[[#This Row],[SAMV25]]=0,tblPiNHistorical[[#This Row],[SAMV26]]>0),"New26 "&tblPiNHistorical[[#This Row],[SAMV26]], IF(AND(tblPiNHistorical[[#This Row],[SAMV25]]>0,tblPiNHistorical[[#This Row],[SAMV26]]=0),"NoPIN26 "&tblPiNHistorical[[#This Row],[SAMV25]], IFERROR(ROUND((tblPiNHistorical[[#This Row],[SAMV26]]-tblPiNHistorical[[#This Row],[SAMV25]])/tblPiNHistorical[[#This Row],[SAMV25]], 1), "") )) -> 65.2 | AB10: =IF(AND(tblPiNHistorical[[#This Row],[NUT25]]=0,tblPiNHistorical[[#This Row],[NUT26]]>0),"New26 "&tblPiNHistorical[[#This Row],[NUT26]], IF(AND(tblPiNHistorical[[#This Row],[NUT25]]>0,tblPiNHistorical[[#This Row],[NUT26]]=0),"NoPIN26 "&tblPiNHistorical[[#This Row],[NUT25]], IFERROR(ROUND((tblPiNHistorical[[#This Row],[NUT26]]-tblPiNHistorical[[#This Row],[NUT25]])/tblPiNHistorical[[#This Row],[NUT25]], 1), "") )) -> 29 | AC10: =IF(AND(tblPiNHistorical[[#This Row],[SAL25]]=0,tblPiNHistorical[[#This Row],[SAL26]]>0),"New26 "&tblPiNHistorical[[#This Row],[SAL26]], IF(AND(tblPiNHistorical[[#This Row],[SAL25]]>0,tblPiNHistorical[[#This Row],[SAL26]]=0),"NoPIN26 "&tblPiNHistorical[[#This Row],[SAL25]], IFERROR(ROUND((tblPiNHistorical[[#This Row],[SAL26]]-tblPiNHistorical[[#This Row],[SAL25]])/tblPiNHistorical[[#This Row],[SAL25]], 1), "") )) -> 77.3 | AD10: =IF(AND(tblPiNHistorical[[#This Row],[EDU25]]=0,tblPiNHistorical[[#This Row],[EDU26]]>0),"New26 "&tblPiNHistorical[[#This Row],[EDU26]], IF(AND(tblPiNHistorical[[#This Row],[EDU25]]>0,tblPiNHistorical[[#This Row],[EDU26]]=0),"NoPIN26 "&tblPiNHistorical[[#This Row],[EDU25]], IFERROR(ROUND((tblPiNHistorical[[#This Row],[EDU26]]-tblPiNHistorical[[#This Row],[EDU25]])/tblPiNHistorical[[#This Row],[EDU25]], 1), "") )) -> 21.4 | AE10: =IF(AND(tblPiNHistorical[[#This Row],[PRO25]]=0,tblPiNHistorical[[#This Row],[PRO26]]>0),"New26 "&tblPiNHistorical[[#This Row],[PRO26]], IF(AND(tblPiNHistorical[[#This Row],[PRO25]]>0,tblPiNHistorical[[#This Row],[PRO26]]=0),"NoPIN26 "&tblPiNHistorical[[#This Row],[PRO25]], IFERROR(ROUND((tblPiNHistorical[[#This Row],[PRO26]]-tblPiNHistorical[[#This Row],[PRO25]])/tblPiNHistorical[[#This Row],[PRO25]], 1), "") )) -> 15.7 | AF10: =IF(AND(tblPiNHistorical[[#This Row],[ASH25]]=0,tblPiNHistorical[[#This Row],[ASH26]]>0),"New26 "&tblPiNHistorical[[#This Row],[ASH26]], IF(AND(tblPiNHistorical[[#This Row],[ASH25]]>0,tblPiNHistorical[[#This Row],[ASH26]]=0),"NoPIN26 "&tblPiNHistorical[[#This Row],[ASH25]], IFERROR(ROUND((tblPiNHistorical[[#This Row],[ASH26]]-tblPiNHistorical[[#This Row],[ASH25]])/tblPiNHistorical[[#This Row],[ASH25]], 1), "") )) -> 66
A11: =IFERROR(_xlfn.CONCAT(IF(tblPiNHistorical[[#This Row],[Grupo de población]]="", "",tblPiNHistorical[[#This Row],[Grupo de población]] ), IF(tblPiNHistorical[[#This Row],[Foco de necesidades]]<>"",tblPiNHistorical[[#This Row],[Foco de necesidades]],), _xlfn.IFS(tblPiNHistorical[[#This Row],[Admin 2 Código P]]<>"", tblPiNHistorical[[#This Row],[Admin 2 Código P]], tblPiNHistorical[[#This Row],[Admin 1 Código P]]<>"", tblPiNHistorical[[#This Row],[Admin 1 Código P]])),"") -> VenezolanosVE0207 | B11: Amazonas | C11: VE02 | D11: Autónomo Río Negro | E11: VE0207 | G11: 2300 | H11: Venezolanos | I11: 460 | J11: 152 | K11: 598.43931 | L11: 402.21319 | M11: 1124.3553 | N11: 1380 | O11: =tblPiNAnalysis[[#This Row],[SAMV]] -> 112245 | P11: =tblPiNAnalysis[[#This Row],[NUT]] -> 12970.937 | Q11: =tblPiNAnalysis[[#This Row],[SAL]] -> 127753.65 | R11: =tblPiNAnalysis[[#This Row],[EDU]] -> 44158.5 | S11: =tblPiNAnalysis[[#This Row],[PRO]] -> 83866.728 | T11: =tblPiNAnalysis[[#This Row],[ASH]] -> 210006 | U11: =IF(OR(tblPiNHistorical[[#This Row],[SAMV25]]="", tblPiNHistorical[[#This Row],[SAMV25]]=0, tblPiNHistorical[[#This Row],[SAMV26]]="", tblPiNHistorical[[#This Row],[SAMV26]]=0), "", tblPiNHistorical[[#This Row],[SAMV26]]-tblPiNHistorical[[#This Row],[SAMV25]]) -> 111785 | V11: =IF(OR(tblPiNHistorical[[#This Row],[NUT25]]="", tblPiNHistorical[[#This Row],[NUT25]]=0, tblPiNHistorical[[#This Row],[NUT26]]="", tblPiNHistorical[[#This Row],[NUT26]]=0), "", tblPiNHistorical[[#This Row],[NUT26]]-tblPiNHistorical[[#This Row],[NUT25]]) -> 12818.937 | W11: =IF(OR(tblPiNHistorical[[#This Row],[SAL25]]="", tblPiNHistorical[[#This Row],[SAL25]]=0, tblPiNHistorical[[#This Row],[SAL26]]="", tblPiNHistorical[[#This Row],[SAL26]]=0), "", tblPiNHistorical[[#This Row],[SAL26]]-tblPiNHistorical[[#This Row],[SAL25]]) -> 127155.21 | X11: =IF(OR(tblPiNHistorical[[#This Row],[EDU25]]="", tblPiNHistorical[[#This Row],[EDU25]]=0, tblPiNHistorical[[#This Row],[EDU26]]="", tblPiNHistorical[[#This Row],[EDU26]]=0), "", tblPiNHistorical[[#This Row],[EDU26]]-tblPiNHistorical[[#This Row],[EDU25]]) -> 43756.287 | Y11: =IF(OR(tblPiNHistorical[[#This Row],[PRO25]]="", tblPiNHistorical[[#This Row],[PRO25]]=0, tblPiNHistorical[[#This Row],[PRO26]]="", tblPiNHistorical[[#This Row],[PRO26]]=0), "", tblPiNHistorical[[#This Row],[PRO26]]-tblPiNHistorical[[#This Row],[PRO25]]) -> 82742.372 | Z11: =IF(OR(tblPiNHistorical[[#This Row],[ASH25]]="", tblPiNHistorical[[#This Row],[ASH25]]=0, tblPiNHistorical[[#This Row],[ASH26]]="", tblPiNHistorical[[#This Row],[ASH26]]=0), "", tblPiNHistorical[[#This Row],[ASH26]]-tblPiNHistorical[[#This Row],[ASH25]]) -> 208626 | AA11: =IF(AND(tblPiNHistorical[[#This Row],[SAMV25]]=0,tblPiNHistorical[[#This Row],[SAMV26]]>0),"New26 "&tblPiNHistorical[[#This Row],[SAMV26]], IF(AND(tblPiNHistorical[[#This Row],[SAMV25]]>0,tblPiNHistorical[[#This Row],[SAMV26]]=0),"NoPIN26 "&tblPiNHistorical[[#This Row],[SAMV25]], IFERROR(ROUND((tblPiNHistorical[[#This Row],[SAMV26]]-tblPiNHistorical[[#This Row],[SAMV25]])/tblPiNHistorical[[#This Row],[SAMV25]], 1), "") )) -> 243 | AB11: =IF(AND(tblPiNHistorical[[#This Row],[NUT25]]=0,tblPiNHistorical[[#This Row],[NUT26]]>0),"New26 "&tblPiNHistorical[[#This Row],[NUT26]], IF(AND(tblPiNHistorical[[#This Row],[NUT25]]>0,tblPiNHistorical[[#This Row],[NUT26]]=0),"NoPIN26 "&tblPiNHistorical[[#This Row],[NUT25]], IFERROR(ROUND((tblPiNHistorical[[#This Row],[NUT26]]-tblPiNHistorical[[#This Row],[NUT25]])/tblPiNHistorical[[#This Row],[NUT25]], 1), "") )) -> 84.3 | AC11: =IF(AND(tblPiNHistorical[[#This Row],[SAL25]]=0,tblPiNHistorical[[#This Row],[SAL26]]>0),"New26 "&tblPiNHistorical[[#This Row],[SAL26]], IF(AND(tblPiNHistorical[[#This Row],[SAL25]]>0,tblPiNHistorical[[#This Row],[SAL26]]=0),"NoPIN26 "&tblPiNHistorical[[#This Row],[SAL25]], IFERROR(ROUND((tblPiNHistorical[[#This Row],[SAL26]]-tblPiNHistorical[[#This Row],[SAL25]])/tblPiNHistorical[[#This Row],[SAL25]], 1), "") )) -> 212.5 | AD11: =IF(AND(tblPiNHistorical[[#This Row],[EDU25]]=0,tblPiNHistorical[[#This Row],[EDU26]]>0),"New26 "&tblPiNHistorical[[#This Row],[EDU26]], IF(AND(tblPiNHistorical[[#This Row],[EDU25]]>0,tblPiNHistorical[[#This Row],[EDU26]]=0),"NoPIN26 "&tblPiNHistorical[[#This Row],[EDU25]], IFERROR(ROUND((tblPiNHistorical[[#This Row],[EDU26]]-tblPiNHistorical[[#This Row],[EDU25]])/tblPiNHistorical[[#This Row],[EDU25]], 1), "") )) -> 108.8 | AE11: =IF(AND(tblPiNHistorical[[#This Row],[PRO25]]=0,tblPiNHistorical[[#This Row],[PRO26]]>0),"New26 "&tblPiNHistorical[[#This Row],[PRO26]], IF(AND(tblPiNHistorical[[#This Row],[PRO25]]>0,tblPiNHistorical[[#This Row],[PRO26]]=0),"NoPIN26 "&tblPiNHistorical[[#This Row],[PRO25]], IFERROR(ROUND((tblPiNHistorical[[#This Row],[PRO26]]-tblPiNHistorical[[#This Row],[PRO25]])/tblPiNHistorical[[#This Row],[PRO25]], 1), "") )) -> 73.6 | AF11: =IF(AND(tblPiNHistorical[[#This Row],[ASH25]]=0,tblPiNHistorical[[#This Row],[ASH26]]>0),"New26 "&tblPiNHistorical[[#This Row],[ASH26]], IF(AND(tblPiNHistorical[[#This Row],[ASH25]]>0,tblPiNHistorical[[#This Row],[ASH26]]=0),"NoPIN26 "&tblPiNHistorical[[#This Row],[ASH25]], IFERROR(ROUND((tblPiNHistorical[[#This Row],[ASH26]]-tblPiNHistorical[[#This Row],[ASH25]])/tblPiNHistorical[[#This Row],[ASH25]], 1), "") )) -> 151.2
A12: =IFERROR(_xlfn.CONCAT(IF(tblPiNHistorical[[#This Row],[Grupo de población]]="", "",tblPiNHistorical[[#This Row],[Grupo de población]] ), IF(tblPiNHistorical[[#This Row],[Foco de necesidades]]<>"",tblPiNHistorical[[#This Row],[Foco de necesidades]],), _xlfn.IFS(tblPiNHistorical[[#This Row],[Admin 2 Código P]]<>"", tblPiNHistorical[[#This Row],[Admin 2 Código P]], tblPiNHistorical[[#This Row],[Admin 1 Código P]]<>"", tblPiNHistorical[[#This Row],[Admin 1 Código P]])),"") -> VenezolanosVE0301 | B12: Anzoátegui | C12: VE03 | D12: Anaco | E12: VE0301 | G12: 122634 | H12: Venezolanos | I12: 21611 | J12: 5177 | K12: 31928.322 | L12: 12841.341 | M12: 13695.896 | N12: 24527 | O12: =tblPiNAnalysis[[#This Row],[SAMV]] -> 161344 | P12: =tblPiNAnalysis[[#This Row],[NUT]] -> 21117.765 | Q12: =tblPiNAnalysis[[#This Row],[SAL]] -> 202395.05 | R12: =tblPiNAnalysis[[#This Row],[EDU]] -> 43027.272 | S12: =tblPiNAnalysis[[#This Row],[PRO]] -> 110727.55 | T12: =tblPiNAnalysis[[#This Row],[ASH]] -> 0 | U12: =IF(OR(tblPiNHistorical[[#This Row],[SAMV25]]="", tblPiNHistorical[[#This Row],[SAMV25]]=0, tblPiNHistorical[[#This Row],[SAMV26]]="", tblPiNHistorical[[#This Row],[SAMV26]]=0), "", tblPiNHistorical[[#This Row],[SAMV26]]-tblPiNHistorical[[#This Row],[SAMV25]]) -> 139733 | V12: =IF(OR(tblPiNHistorical[[#This Row],[NUT25]]="", tblPiNHistorical[[#This Row],[NUT25]]=0, tblPiNHistorical[[#This Row],[NUT26]]="", tblPiNHistorical[[#This Row],[NUT26]]=0), "", tblPiNHistorical[[#This Row],[NUT26]]-tblPiNHistorical[[#This Row],[NUT25]]) -> 15940.765 | W12: =IF(OR(tblPiNHistorical[[#This Row],[SAL25]]="", tblPiNHistorical[[#This Row],[SAL25]]=0, tblPiNHistorical[[#This Row],[SAL26]]="", tblPiNHistorical[[#This Row],[SAL26]]=0), "", tblPiNHistorical[[#This Row],[SAL26]]-tblPiNHistorical[[#This Row],[SAL25]]) -> 170466.73 | X12: =IF(OR(tblPiNHistorical[[#This Row],[EDU25]]="", tblPiNHistorical[[#This Row],[EDU25]]=0, tblPiNHistorical[[#This Row],[EDU26]]="", tblPiNHistorical[[#This Row],[EDU26]]=0), "", tblPiNHistorical[[#This Row],[EDU26]]-tblPiNHistorical[[#This Row],[EDU25]]) -> 30185.932 | Y12: =IF(OR(tblPiNHistorical[[#This Row],[PRO25]]="", tblPiNHistorical[[#This Row],[PRO25]]=0, tblPiNHistorical[[#This Row],[PRO26]]="", tblPiNHistorical[[#This Row],[PRO26]]=0), "", tblPiNHistorical[[#This Row],[PRO26]]-tblPiNHistorical[[#This Row],[PRO25]]) -> 97031.654 | Z12: =IF(OR(tblPiNHistorical[[#This Row],[ASH25]]="", tblPiNHistorical[[#This Row],[ASH25]]=0, tblPiNHistorical[[#This Row],[ASH26]]="", tblPiNHistorical[[#This Row],[ASH26]]=0), "", tblPiNHistorical[[#This Row],[ASH26]]-tblPiNHistorical[[#This Row],[ASH25]]) | AA12: =IF(AND(tblPiNHistorical[[#This Row],[SAMV25]]=0,tblPiNHistorical[[#This Row],[SAMV26]]>0),"New26 "&tblPiNHistorical[[#This Row],[SAMV26]], IF(AND(tblPiNHistorical[[#This Row],[SAMV25]]>0,tblPiNHistorical[[#This Row],[SAMV26]]=0),"NoPIN26 "&tblPiNHistorical[[#This Row],[SAMV25]], IFERROR(ROUND((tblPiNHistorical[[#This Row],[SAMV26]]-tblPiNHistorical[[#This Row],[SAMV25]])/tblPiNHistorical[[#This Row],[SAMV25]], 1), "") )) -> 6.5 | AB12: =IF(AND(tblPiNHistorical[[#This Row],[NUT25]]=0,tblPiNHistorical[[#This Row],[NUT26]]>0),"New26 "&tblPiNHistorical[[#This Row],[NUT26]], IF(AND(tblPiNHistorical[[#This Row],[NUT25]]>0,tblPiNHistorical[[#This Row],[NUT26]]=0),"NoPIN26 "&tblPiNHistorical[[#This Row],[NUT25]], IFERROR(ROUND((tblPiNHistorical[[#This Row],[NUT26]]-tblPiNHistorical[[#This Row],[NUT25]])/tblPiNHistorical[[#This Row],[NUT25]], 1), "") )) -> 3.1 | AC12: =IF(AND(tblPiNHistorical[[#This Row],[SAL25]]=0,tblPiNHistorical[[#This Row],[SAL26]]>0),"New26 "&tblPiNHistorical[[#This Row],[SAL26]], IF(AND(tblPiNHistorical[[#This Row],[SAL25]]>0,tblPiNHistorical[[#This Row],[SAL26]]=0),"NoPIN26 "&tblPiNHistorical[[#This Row],[SAL25]], IFERROR(ROUND((tblPiNHistorical[[#This Row],[SAL26]]-tblPiNHistorical[[#This Row],[SAL25]])/tblPiNHistorical[[#This Row],[SAL25]], 1), "") )) -> 5.3 | AD12: =IF(AND(tblPiNHistorical[[#This Row],[EDU25]]=0,tblPiNHistorical[[#This Row],[EDU26]]>0),"New26 "&tblPiNHistorical[[#This Row],[EDU26]], IF(AND(tblPiNHistorical[[#This Row],[EDU25]]>0,tblPiNHistorical[[#This Row],[EDU26]]=0),"NoPIN26 "&tblPiNHistorical[[#This Row],[EDU25]], IFERROR(ROUND((tblPiNHistorical[[#This Row],[EDU26]]-tblPiNHistorical[[#This Row],[EDU25]])/tblPiNHistorical[[#This Row],[EDU25]], 1), "") )) -> 2.4 | AE12: =IF(AND(tblPiNHistorical[[#This Row],[PRO25]]=0,tblPiNHistorical[[#This Row],[PRO26]]>0),"New26 "&tblPiNHistorical[[#This Row],[PRO26]], IF(AND(tblPiNHistorical[[#This Row],[PRO25]]>0,tblPiNHistorical[[#This Row],[PRO26]]=0),"NoPIN26 "&tblPiNHistorical[[#This Row],[PRO25]], IFERROR(ROUND((tblPiNHistorical[[#This Row],[PRO26]]-tblPiNHistorical[[#This Row],[PRO25]])/tblPiNHistorical[[#This Row],[PRO25]], 1), "") )) -> 7.1 | AF12: =IF(AND(tblPiNHistorical[[#This Row],[ASH25]]=0,tblPiNHistorical[[#This Row],[ASH26]]>0),"New26 "&tblPiNHistorical[[#This Row],[ASH26]], IF(AND(tblPiNHistorical[[#This Row],[ASH25]]>0,tblPiNHistorical[[#This Row],[ASH26]]=0),"NoPIN26 "&tblPiNHistorical[[#This Row],[ASH25]], IFERROR(ROUND((tblPiNHistorical[[#This Row],[ASH26]]-tblPiNHistorical[[#This Row],[ASH25]])/tblPiNHistorical[[#This Row],[ASH25]], 1), "") )) -> NoPIN26 24527
