Workbook
Name flag_pin_historical: Thresholds!$D$13
Name flag_pin_perc: Thresholds!$D$12
Name perc_1st_2nd: Thresholds!$D$9
Name perc_1st_3rd: Thresholds!$D$10
Name pin_perc: 'PiN Visuals'!$B$5:$F$16
Name sectors_sev_4: Thresholds!$D$29
Name sectors_sev_5: Thresholds!$D$28
Name zero_pin_thresh: Thresholds!$D$8

Sheet Read Me
A1: JIAF 2 Tool 3: PiN & Severity estimation template
A3: Warnings for all sheets! | B3: Pre-set data checks have been coded into the template and they will be implemented as soon as sector data is inserted into the template. OCHA analysis teams are free to modify the template, including additional checks or removing any checks that are deemed not useful by the analysis team. At a minimum, the following columns will need to be updated by the teams: ID: A unique identifier, automatically generated and required to link certain formulas. Do not change or delete. Geographic and Population related columns: Do not delete columns for admin units and population group; please just hide any column if not needed. Sectoral Data: sectoral header names can be changed; sector columns can be removed or added in between the first and last collumn (but do not remove the first and the last sector columns); make sure the order of the sector names match the order of their percentage column and if new sector columns are added make sure to write the formula for the percentage calculation. More importantly, Do not delete the first and last column of the sectoral data section.
A5: Sheet | B5: Description
A6: Thresholds | B6: Thresholds - Flagging criteria & thresholds: OCHA analysis team to adjust if necessary the thresholds for pre-set data checks as per agreements with partners. - Sub-population group sectors: OCHA analysis team to list all sectors targeting sub-population groups (e.g. kids, women, IDPs) in their context.
A7: Overall PiN | B7: Preliminary PiN: Highest PiN among the Sector PINs is automatically taken as the preliminary PiN.
B8: Flags and Outlier Checks: Please note that the analysis team could decide to adjust the thresholds of these indicators, in the Threshold spreadshee or eliminate flags that they consider not relevant to their contexts
B9: Number of missing or zero PiN: OCHA analysis team to decide the threshold for accepted number of sectors at unit level not to provide a PiN value or have zero PiN.
B10: Highest PiN close to the total affected population: OCHA analysis team to decide the threshold of acceptable proportion of people in need to the affected population at unit level.
B11: Highest Sector targets only a subset of the affected population: OCHA analysis team to decide the sectors that target only a subset of the affected population.
B12: Difference b/w highest and 2nd highest: OCHA analysis team to decide whether certain outliers between highest sector with 2nd or 3rd highest require flagging for review and to enter 'Flagged' in the column.
B13: Difference b/w highest and 3rd highest: OCHA analysis team to decide whether certain outliers between highest sector with 2nd or 3rd highest require flagging for review and to enter 'Flagged' in the column.
B14: % Difference between this HNO's highest or 2nd highest sector PiN to same sector in the last HNO: OCHA analysis team to decide the threshold of change for this HNO's highest or 2nd higehst sector PiN and last HNO's PiN for the same sector.
A15: PiN Historical Trend | B15: This table can be used to compare current sector PiNs to the previous year's PiNs to identify increases or decreases. The current PIN will be automatically loaded from the Overal PIN spreadsheet, provided that the unique ID of the rows match. The Previous year's HNO data needs to be loaded in the Historical Trend spreadsheet. Formulas will automatically calculate the %change from previous to current year and highlights area where PiN is 50% higher or lower than the last HNO's PiN for further investigation. Countries can decide to change this 50% threshold according to their context.
A16: PiN Visulas | B16: Two visuals that can help better understand sectoral PiN affecting percentage of affected population and the percentage of change from one HNO to the last distribution.
A17: Intersectoral Severity | B17: # of sectors falling under severity phases: The number of sectors fallen under each severity phase can help better understand and see the relationship of the sectoral severities to the preliminary intersectoral severity. Preliminary Intersectoral Severity: preliminary intersectoral severity is automatically calculated according to the logical formula. Flags and Outlier Checks: Some sectors having severity phase 5 or 4: OCHA analysis team to decide number of sectors in phase 5 or 4 to be flagged and reviewed to confirm the concentration of high sectoral severities . Variation between preliminary severity and outcome indicators: preliminary intersectoral severity is higher or lower then outcome indicators (by 1 or more).
A18: Reference Table indicators | B18: Fill in reference table indicators data at unit level to automatically calculate the severity of the indicator which will be used to compare the intersectoral severity results with. If any indicators are added, removed or modified, please make sure that the formulas correctly reflect these changes.

Sheet Thresholds
C1: Please do not delete this sheet or tables in this sheet!
C3: Tables in this sheet are being used in formulas in other sheets!
B6: PiN Flagging criteria & thresholds | D6: Please assign the thresholds relevant for your country
A7: Flag Name | B7: Flag Description | C7: Recommended Threshold | D7: Country Threshold | E7: Explanation for proposing another threshold | F7: Purpose
B8: # Sectors with 0 PiN | C8: 2 | D8: 2 | F8: To flag potential data quality issue
A9: % Difference between 1st and 2nd highest PIN | B9: % difference threshold between 1st and 2nd highest PiN greater than 30% | C9: 0.3 | D9: 0.3 | F9: To identify areas to manual review
A10: % Difference between 1st and 3rd highest PIN | B10: % difference threshold between 1st and 3rd highest PiN greater than 50% | C10: 0.5 | D10: 0.5 | F10: To identify areas to manual review
A11: Highest sector PIN targets sub-population group(s) | B11: Whenever a sector dealing with a sub-population group is higher than any other sector - e.g., Education and Nutrition
A12: PiN greater than 90% of total affected population | B12: Flag where the 1st or the 2nd highest PiN is 90% of the affected population | C12: 0.9 | D12: 0.9
A13: Change from last year | B13: Flag where the change from last year of the 1st or 2nd highest PiN is significantly higher than the the average change from last year of all sectors | C13: 1 | D13: 1
A14: Manual Flag | B14: Any area can be flagged manually whenever there is a concern by any JIAF analysts about the PIN
B15: Outliers from the porpotion of highest PiN in the population nationwide
B16: % difference threshold between sectoral PiN change between this year and last year | C16: 2std | D16: 2std | F16: To identify areas to manual review
B18: PiN - Sub-population group sectors
B19: Sector | C19: Proportion of sector target population in overall population
A20: Decision Rule for determining PIN | B20: Education
A21: 1. accept highest PIN with no flags. 2. Accept highest PiN after reconciling any flags. 3. If no concensus on highest PIN, use 2nd highest PIN. 4. If no consensus on 2nd highest PIN elevate decision to HC level
B26: Severity Flagging criteria & thresholds | D26: Please assign the thresholds relevant for your country
B27: Flagging criterion for PIN | C27: Recommended Threshold | D27: Country Threshold | E27: Explanation for proposing another threshold
B28: # of sectors in phase 5 | C28: 1 | D28: 1
B29: # of sectors in phase 4 with preliminary in phase 4 | C29: 5 | D29: 5
B33: Targeting thresholds
B34: Targeting criteria | C34: Recommended Threshold | D34: Country Threshold
B35: Areas in severity 3 | C35: 0.5 | D35: 0.5 | E35: 50% is the maximun threshold for Severity 3
B36: Areas in severity 4 & 5 | C36: 1 | D36: 1

Sheet COD
E1: 14363363 | F1: =SUM(Table2[[Refugees ]]) -> 673913 | G1: =SUM(Table2[IDP]) -> 2651905.8 | H1: =SUM(Table2[Returnees]) -> 1585547.3 | I1: 7736195.1 | J1: =SUM(Table2[Affected population without refugees]) -> 11973648 | L1: =SUM(Table2[No. of Male children under 5]) -> 1146512.6 | N1: =SUM(Table2[No. of Female children under 5]) -> 1068899.3 | P1: =SUM(Table2[No. of Male children aged 5 - 17 years]) -> 2107825.8 | R1: =SUM(Table2[No. of Female children aged 5 - 17 years]) -> 2080564.1 | T1: =SUM(Table2[No. of Male adults aged 18 - 60]) -> 2287143.8 | V1: =SUM(Table2[No. of Female adults aged 18 - 60]) -> 2410890.9 | X1: =SUM(Table2[No. of Male adults aged over 60]) -> 416875.59 | Z1: =SUM(Table2[No. Female adults aged over 60]) -> 454935.99 | AA1: =SUM(Table2[Persons with disability]) -> 2255591.4
A2: State | B2: admin1Pcod | C2: County | D2: admin2Pcod | E2: Total 2026 COD pop estimate (without refugees) | F2: Refugees | G2: IDP | H2: Returnees | I2: Vulnerable Resident | J2: Affected population without refugees | K2: % Male children under 5 | L2: No. of Male children under 5 | M2: % Female children under 5 | N2: No. of Female children under 5 | O2: % Male children aged 5 - 17 years | P2: No. of Male children aged 5 - 17 years | Q2: % Female children aged 5 - 17 years | R2: No. of Female children aged 5 - 17 years | S2: % Male adults aged 18 - 60 | T2: No. of Male adults aged 18 - 60 | U2: % Female adults aged 18 - 60 | V2: No. of Female adults aged 18 - 60 | W2: % Male adults aged over 60 | X2: No. of Male adults aged over 60 | Y2: % Female adults aged over 60 | Z2: No. Female adults aged over 60 | AA2: Persons with disability
A3: Abyei Administrative Area | B3: SS00 | C3: Abyei Administrative Area | D3: SS0001 | E3: 160330.44 | F3: 0 | G3: 122221.69 | H3: 19107.704 | I3: 14516.803 | J3: =SUM(I3,H3,G3) -> 155846.2 | K3: 0.096 | L3: =Table2[[#This Row],[% Male children under 5]]*Table2[[#This Row],[Affected population without refugees]] -> 14961.235 | M3: 0.089 | N3: =Table2[[#This Row],[Affected population without refugees]]*Table2[[#This Row],[% Female children under 5]] -> 13870.311 | O3: 0.177 | P3: =Table2[[#This Row],[Affected population without refugees]]*Table2[[#This Row],[% Male children aged 5 - 17 years]] -> 27584.777 | Q3: 0.173 | R3: =Table2[[#This Row],[Affected population without refugees]]*Table2[[#This Row],[% Female children aged 5 - 17 years]] -> 26961.392 | S3: 0.19 | T3: =Table2[[#This Row],[Affected population without refugees]]*Table2[[#This Row],[% Male adults aged 18 - 60]] -> 29610.777 | U3: 0.202 | V3: =Table2[[#This Row],[Affected population without refugees]]*Table2[[#This Row],[% Female adults aged 18 - 60]] -> 31480.932 | W3: 0.034 | X3: =Table2[[#This Row],[Affected population without refugees]]*Table2[[#This Row],[% Male adults aged over 60]] -> 5298.7707 | Y3: 0.039 | Z3: =Table2[[#This Row],[Affected population without refugees]]*Table2[[#This Row],[% Female adults aged over 60]] -> 6078.0017 | AA3: 24049.567
A4: Central Equatoria | B4: SS01 | C4: Juba | D4: SS0101 | E4: 651079.37 | F4: 47867 | G4: 185655.53 | H4: 58949.896 | I4: 310546.09 | J4: =SUM(I4,H4,G4) -> 555151.52 | K4: 0.074 | L4: =Table2[[#This Row],[% Male children under 5]]*Table2[[#This Row],[Affected population without refugees]] -> 41081.212 | M4: 0.0974 | N4: =Table2[[#This Row],[Affected population without refugees]]*Table2[[#This Row],[% Female children under 5]] -> 54071.758 | O4: 0.154 | P4: =Table2[[#This Row],[Affected population without refugees]]*Table2[[#This Row],[% Male children aged 5 - 17 years]] -> 85493.334 | Q4: 0.159 | R4: =Table2[[#This Row],[Affected population without refugees]]*Table2[[#This Row],[% Female children aged 5 - 17 years]] -> 88269.091 | S4: 0.232 | T4: =Table2[[#This Row],[Affected population without refugees]]*Table2[[#This Row],[% Male adults aged 18 - 60]] -> 128795.15 | U4: 0.241 | V4: =Table2[[#This Row],[Affected population without refugees]]*Table2[[#This Row],[% Female adults aged 18 - 60]] -> 133791.52 | W4: 0.0235 | X4: =Table2[[#This Row],[Affected population without refugees]]*Table2[[#This Row],[% Male adults aged over 60]] -> 13046.061 | Y4: 0.0191 | Z4: =Table2[[#This Row],[Affected population without refugees]]*Table2[[#This Row],[% Female adults aged over 60]] -> 10603.394 | AA4: 104841.96
A5: Central Equatoria | B5: SS01 | C5: Kajo-keji | D5: SS0102 | E5: 247876.07 | F5: 0 | G5: 16311.748 | H5: 15480.714 | I5: 165087.87 | J5: =SUM(I5,H5,G5) -> 196880.34 | K5: 0.0163 | L5: =Table2[[#This Row],[% Male children under 5]]*Table2[[#This Row],[Affected population without refugees]] -> 3209.1495 | M5: 0.0301 | N5: =Table2[[#This Row],[Affected population without refugees]]*Table2[[#This Row],[% Female children under 5]] -> 5926.0981 | O5: 0.0575 | P5: =Table2[[#This Row],[Affected population without refugees]]*Table2[[#This Row],[% Male children aged 5 - 17 years]] -> 11320.619 | Q5: 0.0581 | R5: =Table2[[#This Row],[Affected population without refugees]]*Table2[[#This Row],[% Female children aged 5 - 17 years]] -> 11438.748 | S5: 0.328 | T5: =Table2[[#This Row],[Affected population without refugees]]*Table2[[#This Row],[% Male adults aged 18 - 60]] -> 64576.75 | U5: 0.32 | V5: =Table2[[#This Row],[Affected population without refugees]]*Table2[[#This Row],[% Female adults aged 18 - 60]] -> 63001.708 | W5: 0.127 | X5: =Table2[[#This Row],[Affected population without refugees]]*Table2[[#This Row],[% Male adults aged over 60]] -> 25003.803 | Y5: 0.063 | Z5: =Table2[[#This Row],[Affected population without refugees]]*Table2[[#This Row],[% Female adults aged over 60]] -> 12403.461 | AA5: 37181.41
A6: Central Equatoria | B6: SS01 | C6: Lainya | D6: SS0103 | E6: 121047.48 | F6: 0 | G6: 7434.8764 | H6: 7168.4286 | I6: 81323.353 | J6: =SUM(I6,H6,G6) -> 95926.658 | K6: 0.105 | L6: =Table2[[#This Row],[% Male children under 5]]*Table2[[#This Row],[Affected population without refugees]] -> 10072.299 | M6: 0.101 | N6: =Table2[[#This Row],[Affected population without refugees]]*Table2[[#This Row],[% Female children under 5]] -> 9688.5925 | O6: 0.11 | P6: =Table2[[#This Row],[Affected population without refugees]]*Table2[[#This Row],[% Male children aged 5 - 17 years]] -> 10551.932 | Q6: 0.104 | R6: =Table2[[#This Row],[Affected population without refugees]]*Table2[[#This Row],[% Female children aged 5 - 17 years]] -> 9976.3725 | S6: 0.286 | T6: =Table2[[#This Row],[Affected population without refugees]]*Table2[[#This Row],[% Male adults aged 18 - 60]] -> 27435.024 | U6: 0.234 | V6: =Table2[[#This Row],[Affected population without refugees]]*Table2[[#This Row],[% Female adults aged 18 - 60]] -> 22446.838 | W6: 0.027 | X6: =Table2[[#This Row],[Affected population without refugees]]*Table2[[#This Row],[% Male adults aged over 60]] -> 2590.0198 | Y6: 0.033 | Z6: =Table2[[#This Row],[Affected population without refugees]]*Table2[[#This Row],[% Female adults aged over 60]] -> 3165.5797 | AA6: 18157.123
A7: Central Equatoria | B7: SS01 | C7: Morobo | D7: SS0104 | E7: 123332.34 | F7: 2339 | G7: 10995.852 | H7: 12810 | I7: 76038.236 | J7: =SUM(I7,H7,G7) -> 99844.088 | K7: 0.0815 | L7: =Table2[[#This Row],[% Male children under 5]]*Table2[[#This Row],[Affected population without refugees]] -> 8137.2932 | M7: 0.105 | N7: =Table2[[#This Row],[Affected population without refugees]]*Table2[[#This Row],[% Female children under 5]] -> 10483.629 | O7: 0.178 | P7: =Table2[[#This Row],[Affected population without refugees]]*Table2[[#This Row],[% Male children aged 5 - 17 years]] -> 17772.248 | Q7: 0.163 | R7: =Table2[[#This Row],[Affected population without refugees]]*Table2[[#This Row],[% Female children aged 5 - 17 years]] -> 16274.586 | S7: 0.218 | T7: =Table2[[#This Row],[Affected population without refugees]]*Table2[[#This Row],[% Male adults aged 18 - 60]] -> 21766.011 | U7: 0.203 | V7: =Table2[[#This Row],[Affected population without refugees]]*Table2[[#This Row],[% Female adults aged 18 - 60]] -> 20268.35 | W7: 0.0326 | X7: =Table2[[#This Row],[Affected population without refugees]]*Table2[[#This Row],[% Male adults aged over 60]] -> 3254.9173 | Y7: 0.0189 | Z7: =Table2[[#This Row],[Affected population without refugees]]*Table2[[#This Row],[% Female adults aged over 60]] -> 1887.0533 | AA7: 18850.701
A8: Central Equatoria | B8: SS01 | C8: Terekeka | D8: SS0105 | E8: 274703.53 | F8: 0 | G8: 13333.613 | H8: 1080 | I8: 198861.5 | J8: =SUM(I8,H8,G8) -> 213275.11 | K8: 0.0885 | L8: =Table2[[#This Row],[% Male children under 5]]*Table2[[#This Row],[Affected population without refugees]] -> 18874.847 | M8: 0.0831 | N8: =Table2[[#This Row],[Affected population without refugees]]*Table2[[#This Row],[% Female children under 5]] -> 17723.162 | O8: 0.181 | P8: =Table2[[#This Row],[Affected population without refugees]]*Table2[[#This Row],[% Male children aged 5 - 17 years]] -> 38602.795 | Q8: 0.164 | R8: =Table2[[#This Row],[Affected population without refugees]]*Table2[[#This Row],[% Female children aged 5 - 17 years]] -> 34977.118 | S8: 0.1934 | T8: =Table2[[#This Row],[Affected population without refugees]]*Table2[[#This Row],[% Male adults aged 18 - 60]] -> 41247.407 | U8: 0.231 | V8: =Table2[[#This Row],[Affected population without refugees]]*Table2[[#This Row],[% Female adults aged 18 - 60]] -> 49266.551 | W8: 0.0186 | X8: =Table2[[#This Row],[Affected population without refugees]]*Table2[[#This Row],[% Male adults aged over 60]] -> 3966.9171 | Y8: 0.0404 | Z8: =Table2[[#This Row],[Affected population without refugees]]*Table2[[#This Row],[% Female adults aged over 60]] -> 8616.3145 | AA8: 41205.53
A9: Central Equatoria | B9: SS01 | C9: Yei | D9: SS0106 | E9: 322475.1 | F9: 2908 | G9: 38535.007 | H9: 29744.714 | I9: 194205.27 | J9: =SUM(I9,H9,G9) -> 262484.99 | K9: 0.0938 | L9: =Table2[[#This Row],[% Male children under 5]]*Table2[[#This Row],[Affected population without refugees]] -> 24621.092 | M9: 0.122 | N9: =Table2[[#This Row],[Affected population without refugees]]*Table2[[#This Row],[% Female children under 5]] -> 32023.169 | O9: 0.146 | P9: =Table2[[#This Row],[Affected population without refugees]]*Table2[[#This Row],[% Male children aged 5 - 17 years]] -> 38322.809 | Q9: 0.189 | R9: =Table2[[#This Row],[Affected population without refugees]]*Table2[[#This Row],[% Female children aged 5 - 17 years]] -> 49609.663 | S9: 0.174 | T9: =Table2[[#This Row],[Affected population without refugees]]*Table2[[#This Row],[% Male adults aged 18 - 60]] -> 45672.388 | U9: 0.193 | V9: =Table2[[#This Row],[Affected population without refugees]]*Table2[[#This Row],[% Female adults aged 18 - 60]] -> 50659.603 | W9: 0.0532 | X9: =Table2[[#This Row],[Affected population without refugees]]*Table2[[#This Row],[% Male adults aged over 60]] -> 13964.201 | Y9: 0.029 | Z9: =Table2[[#This Row],[Affected population without refugees]]*Table2[[#This Row],[% Female adults aged over 60]] -> 7612.0647 | AA9: 48807.465
A10: Eastern Equatoria | B10: SS02 | C10: Budi | D10: SS0201 | E10: 112687.87 | F10: 0 | G10: 4566.5836 | H10: 2130 | I10: 80977.343 | J10: =SUM(I10,H10,G10) -> 87673.927 | K10: 0.1036 | L10: =Table2[[#This Row],[% Male children under 5]]*Table2[[#This Row],[Affected population without refugees]] -> 9083.0188 | M10: 0.0978 | N10: =Table2[[#This Row],[Affected population without refugees]]*Table2[[#This Row],[% Female children under 5]] -> 8574.51 | O10: 0.189 | P10: =Table2[[#This Row],[Affected population without refugees]]*Table2[[#This Row],[% Male children aged 5 - 17 years]] -> 16570.372 | Q10: 0.173 | R10: =Table2[[#This Row],[Affected population without refugees]]*Table2[[#This Row],[% Female children aged 5 - 17 years]] -> 15167.589 | S10: 0.16 | T10: =Table2[[#This Row],[Affected population without refugees]]*Table2[[#This Row],[% Male adults aged 18 - 60]] -> 14027.828 | U10: 0.22 | V10: =Table2[[#This Row],[Affected population without refugees]]*Table2[[#This Row],[% Female adults aged 18 - 60]] -> 19288.264 | W10: 0.0181 | X10: =Table2[[#This Row],[Affected population without refugees]]*Table2[[#This Row],[% Male adults aged over 60]] -> 1586.8981 | Y10: 0.0385 | Z10: =Table2[[#This Row],[Affected population without refugees]]*Table2[[#This Row],[% Female adults aged over 60]] -> 3375.4462 | AA10: 16903.181
A11: Eastern Equatoria | B11: SS02 | C11: Ikotos | D11: SS0202 | E11: 113621.63 | F11: 0 | G11: 6185.6712 | H11: 3437.4286 | I11: 79454.881 | J11: =SUM(I11,H11,G11) -> 89077.98 | K11: 0.1161 | L11: =Table2[[#This Row],[% Male children under 5]]*Table2[[#This Row],[Affected population without refugees]] -> 10341.954 | M11: 0.105 | N11: =Table2[[#This Row],[Affected population without refugees]]*Table2[[#This Row],[% Female children under 5]] -> 9353.1879 | O11: 0.158 | P11: =Table2[[#This Row],[Affected population without refugees]]*Table2[[#This Row],[% Male children aged 5 - 17 years]] -> 14074.321 | Q11: 0.156 | R11: =Table2[[#This Row],[Affected population without refugees]]*Table2[[#This Row],[% Female children aged 5 - 17 years]] -> 13896.165 | S11: 0.171 | T11: =Table2[[#This Row],[Affected population without refugees]]*Table2[[#This Row],[% Male adults aged 18 - 60]] -> 15232.335 | U11: 0.218 | V11: =Table2[[#This Row],[Affected population without refugees]]*Table2[[#This Row],[% Female adults aged 18 - 60]] -> 19419 | W11: 0.0278 | X11: =Table2[[#This Row],[Affected population without refugees]]*Table2[[#This Row],[% Male adults aged over 60]] -> 2476.3679 | Y11: 0.0481 | Z11: =Table2[[#This Row],[Affected population without refugees]]*Table2[[#This Row],[% Female adults aged over 60]] -> 4284.6509 | AA11: 17043.245
A12: Eastern Equatoria | B12: SS02 | C12: Kapoeta East | D12: SS0203 | E12: 183613.18 | F12: 0 | G12: 2159.773 | H12: 3548.7143 | I12: 135919.18 | J12: =SUM(I12,H12,G12) -> 141627.67 | K12: 0.132 | L12: =Table2[[#This Row],[% Male children under 5]]*Table2[[#This Row],[Affected population without refugees]] -> 18694.852 | M12: 0.0871 | N12: =Table2[[#This Row],[Affected population without refugees]]*Table2[[#This Row],[% Female children under 5]] -> 12335.77 | O12: 0.1716 | P12: =Table2[[#This Row],[Affected population without refugees]]*Table2[[#This Row],[% Male children aged 5 - 17 years]] -> 24303.308 | Q12: 0.17 | R12: =Table2[[#This Row],[Affected population without refugees]]*Table2[[#This Row],[% Female children aged 5 - 17 years]] -> 24076.704 | S12: 0.193 | T12: =Table2[[#This Row],[Affected population without refugees]]*Table2[[#This Row],[% Male adults aged 18 - 60]] -> 27334.14 | U12: 0.211 | V12: =Table2[[#This Row],[Affected population without refugees]]*Table2[[#This Row],[% Female adults aged 18 - 60]] -> 29883.438 | W12: 0.0192 | X12: =Table2[[#This Row],[Affected population without refugees]]*Table2[[#This Row],[% Male adults aged over 60]] -> 2719.2513 | Y12: 0.0161 | Z12: =Table2[[#This Row],[Affected population without refugees]]*Table2[[#This Row],[% Female adults aged over 60]] -> 2280.2055 | AA12: 27541.976
A13: Eastern Equatoria | B13: SS02 | C13: Kapoeta North | D13: SS0204 | E13: 167036.93 | F13: 0 | G13: 8023.4115 | H13: 3 | I13: 121484.03 | J13: =SUM(I13,H13,G13) -> 129510.45 | K13: 0.109 | L13: =Table2[[#This Row],[% Male children under 5]]*Table2[[#This Row],[Affected population without refugees]] -> 14116.639 | M13: 0.107 | N13: =Table2[[#This Row],[Affected population without refugees]]*Table2[[#This Row],[% Female children under 5]] -> 13857.618 | O13: 0.212 | P13: =Table2[[#This Row],[Affected population without refugees]]*Table2[[#This Row],[% Male children aged 5 - 17 years]] -> 27456.215 | Q13: 0.167 | R13: =Table2[[#This Row],[Affected population without refugees]]*Table2[[#This Row],[% Female children aged 5 - 17 years]] -> 21628.244 | S13: 0.162 | T13: =Table2[[#This Row],[Affected population without refugees]]*Table2[[#This Row],[% Male adults aged 18 - 60]] -> 20980.692 | U13: 0.171 | V13: =Table2[[#This Row],[Affected population without refugees]]*Table2[[#This Row],[% Female adults aged 18 - 60]] -> 22146.286 | W13: 0.0343 | X13: =Table2[[#This Row],[Affected population without refugees]]*Table2[[#This Row],[% Male adults aged over 60]] -> 4442.2083 | Y13: 0.0377 | Z13: =Table2[[#This Row],[Affected population without refugees]]*Table2[[#This Row],[% Female adults aged over 60]] -> 4882.5438 | AA13: 25055.539
A14: Eastern Equatoria | B14: SS02 | C14: Kapoeta South | D14: SS0205 | E14: 117777.33 | F14: 0 | G14: 4829.7887 | H14: 9189.5714 | I14: 79271.089 | J14: =SUM(I14,H14,G14) -> 93290.449 | K14: 0.093 | L14: =Table2[[#This Row],[% Male children under 5]]*Table2[[#This Row],[Affected population without refugees]] -> 8676.0117 | M14: 0.102 | N14: =Table2[[#This Row],[Affected population without refugees]]*Table2[[#This Row],[% Female children under 5]] -> 9515.6258 | O14: 0.2188 | P14: =Table2[[#This Row],[Affected population without refugees]]*Table2[[#This Row],[% Male children aged 5 - 17 years]] -> 20411.95 | Q14: 0.205 | R14: =Table2[[#This Row],[Affected population without refugees]]*Table2[[#This Row],[% Female children aged 5 - 17 years]] -> 19124.542 | S14: 0.183 | T14: =Table2[[#This Row],[Affected population without refugees]]*Table2[[#This Row],[% Male adults aged 18 - 60]] -> 17072.152 | U14: 0.188 | V14: =Table2[[#This Row],[Affected population without refugees]]*Table2[[#This Row],[% Female adults aged 18 - 60]] -> 17538.604 | W14: 0.00626 | X14: =Table2[[#This Row],[Affected population without refugees]]*Table2[[#This Row],[% Male adults aged over 60]] -> 583.99821 | Y14: 0.00394 | Z14: =Table2[[#This Row],[Affected population without refugees]]*Table2[[#This Row],[% Female adults aged over 60]] -> 367.56437 | AA14: 17666.599
... A81: Western Equatoria | B81: SS10 | C81: Yambio | D81: SS1010 | E81: 179215.56 | F81: 17982 | G81: 10973.798 | H81: 7750 | I81: 122615.71 | J81: =SUM(I81,H81,G81) -> 141339.5 | K81: 0.1021 | L81: =Table2[[#This Row],[% Male children under 5]]*Table2[[#This Row],[Affected population without refugees]] -> 14430.763 | M81: 0.102 | N81: =Table2[[#This Row],[Affected population without refugees]]*Table2[[#This Row],[% Female children under 5]] -> 14416.629 | O81: 0.17 | P81: =Table2[[#This Row],[Affected population without refugees]]*Table2[[#This Row],[% Male children aged 5 - 17 years]] -> 24027.716 | Q81: 0.146 | R81: =Table2[[#This Row],[Affected population without refugees]]*Table2[[#This Row],[% Female children aged 5 - 17 years]] -> 20635.568 | S81: 0.223 | T81: =Table2[[#This Row],[Affected population without refugees]]*Table2[[#This Row],[% Male adults aged 18 - 60]] -> 31518.709 | U81: 0.224 | V81: =Table2[[#This Row],[Affected population without refugees]]*Table2[[#This Row],[% Female adults aged 18 - 60]] -> 31660.049 | W81: 0.0132 | X81: =Table2[[#This Row],[Affected population without refugees]]*Table2[[#This Row],[% Male adults aged over 60]] -> 1865.6814 | Y81: 0.0197 | Z81: =Table2[[#This Row],[Affected population without refugees]]*Table2[[#This Row],[% Female adults aged over 60]] -> 2784.3882 | AA81: 29579.634

Sheet Pivots-graphs
A3: Sum of Final PiN | C3: Population Group
A4: Admin 1 | B4: Admin 2 | C4: IDPs | D4: Residents | E4: Returnees | F4: Grand Total | O4: Values
A5: Abyei Administrative Area | B5: Abyei Administrative Area | C5: 85561.699 | D5: 10162.536 | E5: 13376.412 | F5: 109100.65 | M5: Admin 1 | N5: Admin 2 | O5: Sum of Final PiN | P5: Sum of CCCM | Q5: Sum of Education | R5: Sum of Nutrition | S5: Sum of Food Security | T5: Sum of Health | U5: Sum of Overarching Protection | V5: Sum of Shelter | W5: Sum of WASH
A6: Central Equatoria | B6: Juba | C6: 156584.91 | D6: 218524.29 | E6: 53054.907 | F6: 428164.11 | M6: Abyei Administrative Area | N6: Abyei Administrative Area | O6: 109100.65 | P6: 30000 | Q6: 29482.722 | R6: 59367.004 | S6: 96198.267 | T6: 109100.65 | U6: 100145 | V6: 84622.603 | W6: 60606.854
B7: Kajo-Keji | C7: 13291.054 | D7: 134516.05 | E7: 12613.915 | F7: 160421.02 | M7: Central Equatoria | N7: Juba | O7: 428164.11 | P7: 151967.48 | Q7: 61685.661 | R7: 195209.26 | S7: 390647.62 | T7: 307865.72 | U7: 271178 | V7: 325577.03 | W7: 217013.78
B8: Lainya | C8: 5948 | D8: 51309.967 | E8: 5734 | F8: 62991.967 | N8: Kajo-Keji | O8: 160421.02 | P8: 2322.1071 | Q8: 14702.551 | R8: 83321.069 | S8: 136331.84 | T8: 104304.79 | U8: 76651 | V8: 122076.41 | W8: 160421.02
B9: Morobo | C9: 10472.24 | D9: 51659.397 | E9: 10248 | F9: 72379.637 | N9: Lainya | O9: 62991.967 | P9: 1075.2643 | Q9: 12665.964 | R9: 49115.477 | S9: 60523.742 | T9: 43687.294 | U9: 28322 | V9: 51080.889 | W9: 56845.427
B10: Terekeka | C10: 11111.344 | D10: 151270.71 | E10: 1080 | F10: 163462.06 | N10: Morobo | O10: 72379.637 | P10: 11925.25 | Q10: 17670.307 | R10: 40965.726 | S10: 67832.786 | T10: 64830.407 | U10: 45895 | V10: 61515.216 | W10: 56393.42
B11: Yei | C11: 31398.894 | D11: 158241.33 | E11: 24236.434 | F11: 213876.66 | N11: Terekeka | O11: 163462.06 | P11: 162 | Q11: 56582.954 | R11: 80782.353 | S11: 137351.77 | T11: 109073.36 | U11: 79626 | V11: 163462.06 | W11: 77016.013
A12: Eastern Equatoria | B12: Budi | C12: 3424.9377 | D12: 60733.007 | E12: 1597.5 | F12: 65755.445 | N12: Yei | O12: 213876.66 | P12: 11317.957 | Q12: 45988.683 | R12: 110806.64 | S12: 128990.04 | T12: 121176.18 | U12: 91150 | V12: 125794.75 | W12: 213876.66
B13: Ikotos | C13: 4315 | D13: 44732.491 | E13: 2406 | F13: 51453.491 | M13: Eastern Equatoria | N13: Budi | O13: 65755.445 | P13: 319.5 | Q13: 28659.379 | R13: 44753.797 | S13: 56343.935 | T13: 38417.015 | U13: 17931 | V13: 49487.277 | W13: 65755.445
B14: Kapoeta East | C14: 1719.8192 | D14: 108231.94 | E14: 2825.828 | F14: 112777.59 | N14: Ikotos | O14: 51453.491 | P14: 515.61429 | Q14: 11371.839 | R14: 46087.398 | S14: 39767.572 | T14: 50150.223 | U14: 21278 | V14: 21896.276 | W14: 43313.146
B15: Kapoeta North | C15: 8023.4115 | D15: 89929.74 | E15: 2.1280981 | F15: 97955.279 | N15: Kapoeta East | O15: 112777.59 | P15: 532.30714 | Q15: 48380.012 | R15: 71373.069 | S15: 100987.25 | T15: 54936.758 | U15: 48828 | V15: 70224.911 | W15: 112777.59
B16: Kapoeta South | C16: 4785.0684 | D16: 78537.097 | E16: 9104.4828 | F16: 92426.648 | N16: Kapoeta North | O16: 97955.279 | P16: 0.45 | Q16: 49084.459 | R16: 62879.97 | S16: 91870.31 | T16: 46091.977 | U16: 24545 | V16: 97953.151 | W16: 66537.477
B17: Lafon | C17: 14604.061 | D17: 73504.163 | E17: 3812 | F17: 91920.225 | N17: Kapoeta South | O17: 92426.648 | P17: 1378.4357 | Q17: 23168.384 | R17: 42333.877 | S17: 41222.065 | T17: 45530.362 | U17: 22872 | V17: 46616.83 | W17: 92426.648
B18: Magwi | C18: 28480 | D18: 83224.484 | E18: 21427 | F18: 133131.48 | N18: Lafon | O18: 91920.225 | P18: 15095.879 | Q18: 7164.702 | R18: 54543.23 | S18: 91918.76 | T18: 55533.207 | U18: 36047 | V18: 37362.837 | W18: 39194.489
B19: Torit | C19: 2501.5236 | D19: 37597.566 | E19: 7367.6571 | F19: 47466.747 | N19: Magwi | O19: 133131.48 | P19: 4973.8714 | Q19: 15352.849 | R19: 91996.57 | S19: 56531.278 | T19: 121928 | U19: 103926 | V19: 17162.291 | W19: 80721.213
A20: Jonglei | B20: Akobo | C20: 40611.544 | D20: 126136.82 | E20: 6904.2601 | F20: 173652.63 | N20: Torit | O20: 47466.747 | P20: 1381.4357 | Q20: 6621.5547 | R20: 35990.937 | S20: 33232.662 | T20: 46872.221 | U20: 22591 | V20: 35980.1 | W20: 40891.796
B21: Ayod | C21: 18659.003 | D21: 108231.5 | E21: 16563.369 | F21: 143453.88 | M21: Jonglei | N21: Akobo | O21: 173652.63 | P21: 31226.889 | Q21: 39328.004 | R21: 108898.64 | S21: 171324.03 | T21: 106740.6 | U21: 99192 | V21: 149151.74 | W21: 99699.855
B22: Bor South | C22: 71925.882 | D22: 157119.14 | E22: 16703 | F22: 245748.02 | N22: Ayod | O22: 143453.88 | P22: 2910.4205 | Q22: 23158.079 | R22: 68700.653 | S22: 124326.04 | T22: 75453.237 | U22: 74244 | V22: 81600.947 | W22: 143453.88
B23: Canal/Pigi | C23: 69039.733 | D23: 31549.299 | E23: 1161.3333 | F23: 101750.37 | N23: Bor South | O23: 245748.02 | P23: 52770.45 | Q23: 61555.162 | R23: 139673.98 | S23: 72724.441 | T23: 169092.34 | U23: 143743 | V23: 245748.02 | W23: 143735.92
B24: Duk | C24: 77068.443 | D24: 90800.563 | E24: 9262.1429 | F24: 177131.15 | N24: Canal/Pigi | O24: 101750.37 | P24: 3120.9 | Q24: 16021.404 | R24: 42857.697 | S24: 90503.114 | T24: 75882.405 | U24: 65431 | V24: 94521.859 | W24: 99193.338
B25: Fangak | C25: 103011.13 | D25: 49721.19 | E25: 33686.174 | F25: 186418.49 | N25: Duk | O25: 177131.15 | P25: 1389.3214 | Q25: 19685.661 | R25: 80321.479 | S25: 127113.84 | T25: 121214.36 | U25: 93383 | V25: 177131.15 | W25: 86054.144
B26: Nyirol | C26: 47024.571 | D26: 48712.09 | E26: 9851.9936 | F26: 105588.65 | N26: Fangak | O26: 186418.49 | P26: 58479.176 | Q26: 70147.599 | R26: 76836.359 | S26: 181956.02 | T26: 136606.08 | U26: 140912 | V26: 139310.21 | W26: 165073.78
B27: Pibor | C27: 38060.248 | D27: 119138.14 | E27: 3453.1852 | F27: 160651.57 | N27: Nyirol | O27: 105588.65 | P27: 11314.486 | Q27: 45639.608 | R27: 63147.661 | S27: 98400.657 | T27: 92571.491 | U27: 68322 | V27: 104386.14 | W27: 89969.301
B28: Pochalla | C28: 14426.852 | D28: 38340.073 | E28: 2409.551 | F28: 55176.476 | N28: Pibor | O28: 160651.57 | P28: 4620.7 | Q28: 56497.929 | R28: 112680.42 | S28: 157513.96 | T28: 120090.86 | U28: 84292 | V28: 112428 | W28: 160651.57
B29: Twic East | C29: 25870.03 | D29: 73931.578 | E29: 5169 | F29: 104970.61 | N29: Pochalla | O29: 55176.476 | P29: 421.67143 | Q29: 8867.7003 | R29: 29182.806 | S29: 46609.815 | T29: 43669.621 | U29: 29931 | V29: 55176.476 | W29: 2534.1884
B30: Uror | C30: 23976.104 | D30: 113792.55 | E30: 4709.1667 | F30: 142477.82 | N30: Twic East | O30: 104970.61 | P30: 775.35 | Q30: 31137.404 | R30: 51123.364 | S30: 79517.132 | T30: 60529.04 | U30: 37100 | V30: 104970.61 | W30: 72384.684
A31: Lakes | B31: Awerial | C31: 39461.328 | D31: 55437.418 | E31: 2305.2857 | F31: 97204.032 | N31: Uror | O31: 142477.82 | P31: 4597.65 | Q31: 40407.018 | R31: 106332.24 | S31: 135433.26 | T31: 79671.127 | U31: 67845 | V31: 56387.668 | W31: 138481.81
B32: Cueibet | C32: 3578.7598 | D32: 94596.309 | E32: 765.33333 | F32: 98940.402 | M32: Lakes | N32: Awerial | O32: 97204.032 | P32: 28053.557 | Q32: 48138.925 | R32: 50863.726 | S32: 81670.658 | T32: 61454.718 | U32: 22363 | V32: 87854.687 | W32: 94244.432
B33: Rumbek Centre | C33: 2086.7142 | D33: 125533.72 | E33: 2057.9428 | F33: 129678.38 | N33: Cueibet | O33: 98940.402 | P33: 172.2 | Q33: 42156.339 | R33: 63093.642 | S33: 77973.336 | T33: 63079.281 | U33: 26644 | V33: 49353.093 | W33: 98929.772
B34: Rumbek East | C34: 6808.1234 | D34: 112657.34 | E34: 6376.7407 | F34: 125842.2 | N34: Rumbek Centre | O34: 129678.38 | P34: 432.15 | Q34: 46592.552 | R34: 73581.984 | S34: 126196.41 | T34: 88575.611 | U34: 33088 | V34: 127550.42 | W34: 85902.605
B35: Rumbek North | C35: 16898.631 | D35: 27348.681 | E35: 2637.784 | F35: 46885.096 | N35: Rumbek East | O35: 125842.2 | P35: 2954.55 | Q35: 20758.189 | R35: 60698.336 | S35: 111390.71 | T35: 52674.904 | U35: 24062 | V35: 125842.2 | W35: 77874.137
B36: Wulu | C36: 8322.5959 | D36: 34856.965 | E36: 1826.4615 | F36: 45006.023 | N36: Rumbek North | O36: 46885.096 | P36: 557.89286 | Q36: 17794.734 | R36: 24800.234 | S36: 46410.096 | T36: 34934.835 | U36: 11531 | V36: 33999.489 | W36: 12118.225
B37: Yirol East | C37: 21917.524 | D37: 82693.256 | E37: 2284.4552 | F37: 106895.24 | N37: Wulu | O37: 45006.023 | P37: 445.2 | Q37: 11566.878 | R37: 33453.93 | S37: 18938.947 | T37: 37077.204 | U37: 13467 | V37: 18933.013 | W37: 41840.852
B38: Yirol West | C38: 10362.577 | D38: 90469.194 | E38: 4188.974 | F38: 105020.74 | N38: Yirol East | O38: 106895.24 | P38: 457.18065 | Q38: 22790.076 | R38: 55122.786 | S38: 102500.62 | T38: 52667.158 | U38: 35910 | V38: 85166.428 | W38: 91169.42
A39: Northern Bahr el Ghazal | B39: Aweil Centre | C39: 7245.0983 | D39: 48176.199 | E39: 13603.718 | F39: 69025.016 | N39: Yirol West | O39: 105020.74 | P39: 767.97857 | Q39: 30188.868 | R39: 59758.037 | S39: 92759.69 | T39: 58154.767 | U39: 25396 | V39: 105020.74 | W39: 94432.824
B40: Aweil East | C40: 47590.975 | D40: 175141.53 | E40: 84624.372 | F40: 307356.88 | M40: Northern Bahr el Ghazal | N40: Aweil Centre | O40: 69025.016 | P40: 2477.0231 | Q40: 13605.446 | R40: 65719.584 | S40: 47403.89 | T40: 64590.339 | U40: 25977 | V40: 51800.689 | W40: 51293.578
B41: Aweil North | C41: 0 | D41: 79008.885 | E41: 48677.688 | F41: 127686.57 | N41: Aweil East | O41: 307356.88 | P41: 44338.656 | Q41: 129471.71 | R41: 161450.3 | S41: 272021.22 | T41: 149133.97 | U41: 130888 | V41: 307356.88 | W41: 143830.41
B42: Aweil South | C42: 6413.1419 | D42: 80340.475 | E42: 6742.2448 | F42: 93495.862 | N42: Aweil North | O42: 127686.57 | P42: 9339.3239 | Q42: 45012.666 | R42: 113237.31 | S42: 123588.49 | T42: 78709.268 | U42: 59385 | V42: 113432.16 | W42: 43015.803
...

Sheet Summary 2026
A1: Cluster/Sector | B1: PiN 2025 | C1: Target 2025 | D1: PiN 2026 | E1: Target 2026 (1&2) | F1: Target 2026 (1&2) (3)50% | G1: Requirement 2025 | H1: Requirement 2026 (1&2) | I1: Requirement 2026 (1&2) (3)50% | J1: PiN change | K1: Target change | L1: Requirements change | M1: Testing | N1: New Requirement 2026 (Priority 1,2 and 50% of 3)
A2: SNFI | B2: 4243316.9 | C2: 1366881.2 | D2: 6669355.4 | E2: 1327241.7 | F2: 882352.95 | G2: 46473960 | H2: 45126218 | I2: 51383194 | J2: =(Table3[[#This Row],[PiN 2026]]-Table3[[#This Row],[PiN 2025]])/Table3[[#This Row],[PiN 2025]] -> 0.57173162 | K2: =(Table3[[#This Row],[Target 2026 (1&2) (3)50%]]-Table3[[#This Row],[Target 2025]])/Table3[[#This Row],[Target 2025]] -> -0.35447722 | L2: =(Table3[[#This Row],[Requirement 2026 (1&2) (3)50%]]-Table3[[#This Row],[Requirement 2025]])/Table3[[#This Row],[Requirement 2025]] -> 0.10563407 | M2: =(Table3[[#This Row],[Requirement 2026 (1&2) (3)50%]]-Table3[[#This Row],[Requirement 2025]])/Table3[[#This Row],[Requirement 2025]] -> 0.10563407 | N2: 30000000
A3: CCCM | B3: 1351731.7 | C3: 1126884 | D3: 1359005.7 | E3: 693109 | F3: 735986 | G3: 18586560 | H3: 15941507 | I3: 16927678 | J3: =(Table3[[#This Row],[PiN 2026]]-Table3[[#This Row],[PiN 2025]])/Table3[[#This Row],[PiN 2025]] -> 0.0053812146 | K3: =(Table3[[#This Row],[Target 2026 (1&2) (3)50%]]-Table3[[#This Row],[Target 2025]])/Table3[[#This Row],[Target 2025]] -> -0.34688398 | L3: =(Table3[[#This Row],[Requirement 2026 (1&2) (3)50%]]-Table3[[#This Row],[Requirement 2025]])/Table3[[#This Row],[Requirement 2025]] -> -0.089251685 | M3: =(Table3[[#This Row],[Requirement 2026 (1&2) (3)50%]]-Table3[[#This Row],[Requirement 2025]])/Table3[[#This Row],[Requirement 2025]] -> -0.089251685 | N3: 15000000
A4: FSL | B4: 7750164.7 | C4: 3556521 | D4: 7650961.6 | E4: 2290400.2 | F4: 2664031.9 | G4: 4.7506879e+08 | H4: 3.7245279e+08 | I4: 4.1056017e+08 | J4: =(Table3[[#This Row],[PiN 2026]]-Table3[[#This Row],[PiN 2025]])/Table3[[#This Row],[PiN 2025]] -> -0.01280014 | K4: =(Table3[[#This Row],[Target 2026 (1&2) (3)50%]]-Table3[[#This Row],[Target 2025]])/Table3[[#This Row],[Target 2025]] -> -0.25094443 | L4: =(Table3[[#This Row],[Requirement 2026 (1&2) (3)50%]]-Table3[[#This Row],[Requirement 2025]])/Table3[[#This Row],[Requirement 2025]] -> -0.13578795 | M4: =(Table3[[#This Row],[Requirement 2026 (1&2) (3)50%]]-Table3[[#This Row],[Requirement 2025]])/Table3[[#This Row],[Requirement 2025]] -> -0.13578795 | N4: 3.6043359e+08
A5: Health | B5: 5657326.8 | C5: 3089736.4 | D5: 6269692.2 | E5: 2505797.9 | F5: 2884600.2 | G5: 1.1922898e+08 | H5: 98728437 | I5: 1.1365325e+08 | J5: =(Table3[[#This Row],[PiN 2026]]-Table3[[#This Row],[PiN 2025]])/Table3[[#This Row],[PiN 2025]] -> 0.10824289 | K5: =(Table3[[#This Row],[Target 2026 (1&2) (3)50%]]-Table3[[#This Row],[Target 2025]])/Table3[[#This Row],[Target 2025]] -> -0.066392791 | L5: =(Table3[[#This Row],[Requirement 2026 (1&2) (3)50%]]-Table3[[#This Row],[Requirement 2025]])/Table3[[#This Row],[Requirement 2025]] -> -0.046764936 | M5: =(Table3[[#This Row],[Requirement 2026 (1&2) (3)50%]]-Table3[[#This Row],[Requirement 2025]])/Table3[[#This Row],[Requirement 2025]] -> -0.046764936 | N5: 75143835
A6: WASH | B6: 5010139 | C6: 2251568.3 | D6: 6806494.8 | E6: 1904586.2 | F6: 2167688.7 | G6: 86315791 | H6: 78088033 | I6: 88875235 | J6: =(Table3[[#This Row],[PiN 2026]]-Table3[[#This Row],[PiN 2025]])/Table3[[#This Row],[PiN 2025]] -> 0.35854409 | K6: =(Table3[[#This Row],[Target 2026 (1&2) (3)50%]]-Table3[[#This Row],[Target 2025]])/Table3[[#This Row],[Target 2025]] -> -0.037253894 | L6: =(Table3[[#This Row],[Requirement 2026 (1&2) (3)50%]]-Table3[[#This Row],[Requirement 2025]])/Table3[[#This Row],[Requirement 2025]] -> 0.029652092 | M6: =(Table3[[#This Row],[Requirement 2026 (1&2) (3)50%]]-Table3[[#This Row],[Requirement 2025]])/Table3[[#This Row],[Requirement 2025]] -> 0.029652092 | N6: 59828207
A7: Education | B7: 2139278.5 | C7: 673771 | D7: 2435900.3 | E7: 721635.79 | F7: 795532.3 | G7: 40426260 | H7: 43298148 | I7: 47731938 | J7: =(Table3[[#This Row],[PiN 2026]]-Table3[[#This Row],[PiN 2025]])/Table3[[#This Row],[PiN 2025]] -> 0.13865506 | K7: =(Table3[[#This Row],[Target 2026 (1&2) (3)50%]]-Table3[[#This Row],[Target 2025]])/Table3[[#This Row],[Target 2025]] -> 0.18071616 | L7: =(Table3[[#This Row],[Requirement 2026 (1&2) (3)50%]]-Table3[[#This Row],[Requirement 2025]])/Table3[[#This Row],[Requirement 2025]] -> 0.18071616 | M7: =(Table3[[#This Row],[Requirement 2026 (1&2) (3)50%]]-Table3[[#This Row],[Requirement 2025]])/Table3[[#This Row],[Requirement 2025]] -> 0.18071616 | N7: 30230227
A8: Protection | B8: 5342405.9 | C8: 1466779 | D8: 4867750 | E8: 1397168 | F8: 1451620 | G8: 81428024 | H8: 70545481 | I8: 79426435 | J8: =(Table3[[#This Row],[PiN 2026]]-Table3[[#This Row],[PiN 2025]])/Table3[[#This Row],[PiN 2025]] -> -0.088846838 | K8: =(Table3[[#This Row],[Target 2026 (1&2) (3)50%]]-Table3[[#This Row],[Target 2025]])/Table3[[#This Row],[Target 2025]] -> -0.010334912 | L8: =(Table3[[#This Row],[Requirement 2026 (1&2) (3)50%]]-Table3[[#This Row],[Requirement 2025]])/Table3[[#This Row],[Requirement 2025]] -> -0.02458108 | M8: =(Table3[[#This Row],[Requirement 2026 (1&2) (3)50%]]-Table3[[#This Row],[Requirement 2025]])/Table3[[#This Row],[Requirement 2025]] -> -0.02458108 | N8: 71431800
A9: Nutrition | B9: 4334588.3 | C9: 2843605.3 | D9: 5250932.6 | E9: 1369296.8 | F9: 1833612.4 | G9: 1.9844334e+08 | H9: 97150883 | I9: 1.2798766e+08 | J9: =(Table3[[#This Row],[PiN 2026]]-Table3[[#This Row],[PiN 2025]])/Table3[[#This Row],[PiN 2025]] -> 0.21140285 | K9: =(Table3[[#This Row],[Target 2026 (1&2) (3)50%]]-Table3[[#This Row],[Target 2025]])/Table3[[#This Row],[Target 2025]] -> -0.35518041 | L9: =(Table3[[#This Row],[Requirement 2026 (1&2) (3)50%]]-Table3[[#This Row],[Requirement 2025]])/Table3[[#This Row],[Requirement 2025]] -> -0.35504179 | M9: =(Table3[[#This Row],[Requirement 2026 (1&2) (3)50%]]-Table3[[#This Row],[Requirement 2025]])/Table3[[#This Row],[Requirement 2025]] -> -0.35504179 | N9: 1.2004131e+08
A10: Logistics | G10: 99806929 | H10: 78248221 | I10: 78248221 | L10: =(Table3[[#This Row],[Requirement 2026 (1&2) (3)50%]]-Table3[[#This Row],[Requirement 2025]])/Table3[[#This Row],[Requirement 2025]] -> -0.21600412 | M10: =(Table3[[#This Row],[Requirement 2026 (1&2) (3)50%]]-Table3[[#This Row],[Requirement 2025]])/Table3[[#This Row],[Requirement 2025]] -> -0.21600412 | N10: 45000000
A11: CCS (with OTA) | G11: 36000000 | H11: 33230246 | I11: 33230246 | L11: =(Table3[[#This Row],[Requirement 2026 (1&2) (3)50%]]-Table3[[#This Row],[Requirement 2025]])/Table3[[#This Row],[Requirement 2025]] -> -0.076937611 | M11: =(Table3[[#This Row],[Requirement 2026 (1&2) (3)50%]]-Table3[[#This Row],[Requirement 2025]])/Table3[[#This Row],[Requirement 2025]] -> -0.076937611 | N11: 20000000
A12: MPCA | F12: 463704.84 | G12: 25000000 | H12: 33539527 | I12: 33539527 | L12: =(Table3[[#This Row],[Requirement 2026 (1&2) (3)50%]]-Table3[[#This Row],[Requirement 2025]])/Table3[[#This Row],[Requirement 2025]] -> 0.34158108 | M12: =(Table3[[#This Row],[Requirement 2026 (1&2) (3)50%]]-Table3[[#This Row],[Requirement 2025]])/Table3[[#This Row],[Requirement 2025]] -> 0.34158108 | N12: 30000000
A13: Refugee | B13: 680000 | C13: 680000 | D13: 741304 | E13: 592848 | F13: 592848 | G13: 468000000 | H13: 500000000 | I13: 500000000 | J13: =(Table3[[#This Row],[PiN 2026]]-Table3[[#This Row],[PiN 2025]])/Table3[[#This Row],[PiN 2025]] -> 0.090152941 | K13: =(Table3[[#This Row],[Target 2026 (1&2) (3)50%]]-Table3[[#This Row],[Target 2025]])/Table3[[#This Row],[Target 2025]] -> -0.12816471 | L13: =(Table3[[#This Row],[Requirement 2026 (1&2) (3)50%]]-Table3[[#This Row],[Requirement 2025]])/Table3[[#This Row],[Requirement 2025]] -> 0.068376068 | M13: =(Table3[[#This Row],[Requirement 2026 (1&2) (3)50%]]-Table3[[#This Row],[Requirement 2025]])/Table3[[#This Row],[Requirement 2025]] -> 0.068376068 | N13: 185000000
A14: Total without refugees | B14: 8610087.9 | C14: 4696982.1 | D14: 9266561 | E14: 3199208.7 | F14: 3656206.7 | G14: 1.2267786e+09 | H14: =SUM(H2:H12) -> 9.6634949e+08 | I14: =SUM(I2:I12) -> 1.0815636e+09 | J14: =(Table3[[#This Row],[PiN 2026]]-Table3[[#This Row],[PiN 2025]])/Table3[[#This Row],[PiN 2025]] -> 0.076244652 | K14: =(Table3[[#This Row],[Target 2026 (1&2) (3)50%]]-Table3[[#This Row],[Target 2025]])/Table3[[#This Row],[Target 2025]] -> -0.22158386 | L14: =(Table3[[#This Row],[Requirement 2026 (1&2) (3)50%]]-Table3[[#This Row],[Requirement 2025]])/Table3[[#This Row],[Requirement 2025]] -> -0.11837106 | M14: =(Table3[[#This Row],[Requirement 2026 (1&2) (3)50%]]-Table3[[#This Row],[Requirement 2025]])/Table3[[#This Row],[Requirement 2025]] -> -0.11837106 | N14: =SUM(N2:N12) -> 8.5710897e+08
A15: Total with refugees | B15: 9290087.9 | C15: 5376982.1 | D15: =SUM(D13:D14) -> 10007865 | E15: =SUM(E14,E13) -> 3792056.7 | F15: =SUM(F14,F13) -> 4249054.7 | G15: 1.6947786e+09 | H15: =SUM(H2:H13) -> 1.4663495e+09 | I15: =SUM(I2:I13) -> 1.5815636e+09 | J15: =(Table3[[#This Row],[PiN 2026]]-Table3[[#This Row],[PiN 2025]])/Table3[[#This Row],[PiN 2025]] -> 0.077262687 | K15: =(Table3[[#This Row],[Target 2026 (1&2) (3)50%]]-Table3[[#This Row],[Target 2025]])/Table3[[#This Row],[Target 2025]] -> -0.20976961 | L15: =(Table3[[#This Row],[Requirement 2026 (1&2) (3)50%]]-Table3[[#This Row],[Requirement 2025]])/Table3[[#This Row],[Requirement 2025]] -> -0.066802284 | M15: =(Table3[[#This Row],[Requirement 2026 (1&2) (3)50%]]-Table3[[#This Row],[Requirement 2025]])/Table3[[#This Row],[Requirement 2025]] -> -0.066802284 | N15: =SUM(N2:N13) -> 1.042109e+09
A21: Cluster/Sector | B21: PiN 2025 | C21: Target 2025 | D21: PiN 2026 | E21: Target 2026 (1&2) | F21: Target 2026 (1&2) (3)50% | G21: Requirement 2025 | H21: Requirement 2026 (1&2) | I21: Requirement 2026 (1&2) (3)50% | J21: PiN change | K21: Target change | L21: Requirements change | M21: New Requirement 2026 (Priority 1,2 and 50% of 3) | N21: Reduction USD million
A22: SNFI | B22: =B2/1000000 -> 4.2433169 | C22: =C2/1000000 -> 1.3668812 | D22: =D2/1000000 -> 6.6693554 | E22: =E2/1000000 -> 1.3272417 | F22: =F2/1000000 -> 0.88235295 | G22: =G2/1000000 -> 46.47396 | H22: =H2/1000000 -> 45.126218 | I22: =I2/1000000 -> 51.383194 | J22: =(Table310[[#This Row],[PiN 2026]]-Table310[[#This Row],[PiN 2025]])/Table310[[#This Row],[PiN 2025]] -> 0.57173162 | K22: =(Table310[[#This Row],[Target 2026 (1&2) (3)50%]]-Table310[[#This Row],[Target 2025]])/Table310[[#This Row],[Target 2025]] -> -0.35447722 | L22: =(Table310[[#This Row],[Requirement 2026 (1&2) (3)50%]]-Table310[[#This Row],[Requirement 2025]])/Table310[[#This Row],[Requirement 2025]] -> 0.10563407 | M22: 30 | N22: =Table310[[#This Row],[Requirement 2026 (1&2) (3)50%]]-Table310[[#This Row],[New Requirement 2026 (Priority 1,2 and 50% of 3)]] -> 21.383194
A23: CCCM | B23: =B3/1000000 -> 1.3517317 | C23: =C3/1000000 -> 1.126884 | D23: =D3/1000000 -> 1.3590057 | E23: =E3/1000000 -> 0.693109 | F23: =F3/1000000 -> 0.735986 | G23: =G3/1000000 -> 18.58656 | H23: =H3/1000000 -> 15.941507 | I23: =I3/1000000 -> 16.927678 | J23: =(Table310[[#This Row],[PiN 2026]]-Table310[[#This Row],[PiN 2025]])/Table310[[#This Row],[PiN 2025]] -> 0.0053812146 | K23: =(Table310[[#This Row],[Target 2026 (1&2) (3)50%]]-Table310[[#This Row],[Target 2025]])/Table310[[#This Row],[Target 2025]] -> -0.34688398 | L23: =(Table310[[#This Row],[Requirement 2026 (1&2) (3)50%]]-Table310[[#This Row],[Requirement 2025]])/Table310[[#This Row],[Requirement 2025]] -> -0.089251685 | M23: 15 | N23: =Table310[[#This Row],[Requirement 2026 (1&2) (3)50%]]-Table310[[#This Row],[New Requirement 2026 (Priority 1,2 and 50% of 3)]] -> 1.927678
A24: FSL | B24: =B4/1000000 -> 7.7501647 | C24: =C4/1000000 -> 3.556521 | D24: 7.65 | E24: =E4/1000000 -> 2.2904002 | F24: =F4/1000000 -> 2.6640319 | G24: =G4/1000000 -> 475.06879 | H24: =H4/1000000 -> 372.45279 | I24: =I4/1000000 -> 410.56017 | J24: =(Table310[[#This Row],[PiN 2026]]-Table310[[#This Row],[PiN 2025]])/Table310[[#This Row],[PiN 2025]] -> -0.012924209 | K24: =(Table310[[#This Row],[Target 2026 (1&2) (3)50%]]-Table310[[#This Row],[Target 2025]])/Table310[[#This Row],[Target 2025]] -> -0.25094443 | L24: =(Table310[[#This Row],[Requirement 2026 (1&2) (3)50%]]-Table310[[#This Row],[Requirement 2025]])/Table310[[#This Row],[Requirement 2025]] -> -0.13578795 | M24: 360 | N24: =Table310[[#This Row],[Requirement 2026 (1&2) (3)50%]]-Table310[[#This Row],[New Requirement 2026 (Priority 1,2 and 50% of 3)]] -> 50.560173
A25: Health | B25: =B5/1000000 -> 5.6573268 | C25: =C5/1000000 -> 3.0897364 | D25: =D5/1000000 -> 6.2696922 | E25: =E5/1000000 -> 2.5057979 | F25: =F5/1000000 -> 2.8846002 | G25: =G5/1000000 -> 119.22898 | H25: =H5/1000000 -> 98.728437 | I25: =I5/1000000 -> 113.65325 | J25: =(Table310[[#This Row],[PiN 2026]]-Table310[[#This Row],[PiN 2025]])/Table310[[#This Row],[PiN 2025]] -> 0.10824289 | K25: =(Table310[[#This Row],[Target 2026 (1&2) (3)50%]]-Table310[[#This Row],[Target 2025]])/Table310[[#This Row],[Target 2025]] -> -0.066392791 | L25: =(Table310[[#This Row],[Requirement 2026 (1&2) (3)50%]]-Table310[[#This Row],[Requirement 2025]])/Table310[[#This Row],[Requirement 2025]] -> -0.046764936 | M25: 75 | N25: =Table310[[#This Row],[Requirement 2026 (1&2) (3)50%]]-Table310[[#This Row],[New Requirement 2026 (Priority 1,2 and 50% of 3)]] -> 38.653248
A26: WASH | B26: =B6/1000000 -> 5.010139 | C26: =C6/1000000 -> 2.2515683 | D26: =D6/1000000 -> 6.8064948 | E26: =E6/1000000 -> 1.9045862 | F26: =F6/1000000 -> 2.1676887 | G26: =G6/1000000 -> 86.315791 | H26: =H6/1000000 -> 78.088033 | I26: =I6/1000000 -> 88.875235 | J26: =(Table310[[#This Row],[PiN 2026]]-Table310[[#This Row],[PiN 2025]])/Table310[[#This Row],[PiN 2025]] -> 0.35854409 | K26: =(Table310[[#This Row],[Target 2026 (1&2) (3)50%]]-Table310[[#This Row],[Target 2025]])/Table310[[#This Row],[Target 2025]] -> -0.037253894 | L26: =(Table310[[#This Row],[Requirement 2026 (1&2) (3)50%]]-Table310[[#This Row],[Requirement 2025]])/Table310[[#This Row],[Requirement 2025]] -> 0.029652092 | M26: 60 | N26: =Table310[[#This Row],[Requirement 2026 (1&2) (3)50%]]-Table310[[#This Row],[New Requirement 2026 (Priority 1,2 and 50% of 3)]] -> 28.875235
A27: Education | B27: =B7/1000000 -> 2.1392785 | C27: =C7/1000000 -> 0.673771 | D27: =D7/1000000 -> 2.4359003 | E27: =E7/1000000 -> 0.72163579 | F27: =F7/1000000 -> 0.7955323 | G27: =G7/1000000 -> 40.42626 | H27: =H7/1000000 -> 43.298148 | I27: =I7/1000000 -> 47.731938 | J27: =(Table310[[#This Row],[PiN 2026]]-Table310[[#This Row],[PiN 2025]])/Table310[[#This Row],[PiN 2025]] -> 0.13865506 | K27: =(Table310[[#This Row],[Target 2026 (1&2) (3)50%]]-Table310[[#This Row],[Target 2025]])/Table310[[#This Row],[Target 2025]] -> 0.18071616 | L27: =(Table310[[#This Row],[Requirement 2026 (1&2) (3)50%]]-Table310[[#This Row],[Requirement 2025]])/Table310[[#This Row],[Requirement 2025]] -> 0.18071616 | M27: 30 | N27: =Table310[[#This Row],[Requirement 2026 (1&2) (3)50%]]-Table310[[#This Row],[New Requirement 2026 (Priority 1,2 and 50% of 3)]] -> 17.731938
A28: Protection | B28: =B8/1000000 -> 5.3424059 | C28: =C8/1000000 -> 1.466779 | D28: =D8/1000000 -> 4.86775 | E28: =E8/1000000 -> 1.397168 | F28: =F8/1000000 -> 1.45162 | G28: =G8/1000000 -> 81.428024 | H28: =H8/1000000 -> 70.545481 | I28: =I8/1000000 -> 79.426435 | J28: =(Table310[[#This Row],[PiN 2026]]-Table310[[#This Row],[PiN 2025]])/Table310[[#This Row],[PiN 2025]] -> -0.088846838 | K28: =(Table310[[#This Row],[Target 2026 (1&2) (3)50%]]-Table310[[#This Row],[Target 2025]])/Table310[[#This Row],[Target 2025]] -> -0.010334912 | L28: =(Table310[[#This Row],[Requirement 2026 (1&2) (3)50%]]-Table310[[#This Row],[Requirement 2025]])/Table310[[#This Row],[Requirement 2025]] -> -0.02458108 | M28: 71.4 | N28: =Table310[[#This Row],[Requirement 2026 (1&2) (3)50%]]-Table310[[#This Row],[New Requirement 2026 (Priority 1,2 and 50% of 3)]] -> 8.026435
A29: Nutrition | B29: =B9/1000000 -> 4.3345883 | C29: =C9/1000000 -> 2.8436053 | D29: =D9/1000000 -> 5.2509326 | E29: =E9/1000000 -> 1.3692968 | F29: =F9/1000000 -> 1.8336124 | G29: =G9/1000000 -> 198.44334 | H29: =H9/1000000 -> 97.150883 | I29: =I9/1000000 -> 127.98766 | J29: =(Table310[[#This Row],[PiN 2026]]-Table310[[#This Row],[PiN 2025]])/Table310[[#This Row],[PiN 2025]] -> 0.21140285 | K29: =(Table310[[#This Row],[Target 2026 (1&2) (3)50%]]-Table310[[#This Row],[Target 2025]])/Table310[[#This Row],[Target 2025]] -> -0.35518041 | L29: =(Table310[[#This Row],[Requirement 2026 (1&2) (3)50%]]-Table310[[#This Row],[Requirement 2025]])/Table310[[#This Row],[Requirement 2025]] -> -0.35504179 | M29: 120 | N29: =Table310[[#This Row],[Requirement 2026 (1&2) (3)50%]]-Table310[[#This Row],[New Requirement 2026 (Priority 1,2 and 50% of 3)]] -> 7.9876628
A30: Logistics | B30: =B10/1000000 -> 0 | C30: =C10/1000000 -> 0 | D30: =D10/1000000 -> 0 | E30: =E10/1000000 -> 0 | F30: =F10/1000000 -> 0 | G30: =G10/1000000 -> 99.806929 | H30: =H10/1000000 -> 78.248221 | I30: =I10/1000000 -> 78.248221 | L30: =(Table310[[#This Row],[Requirement 2026 (1&2) (3)50%]]-Table310[[#This Row],[Requirement 2025]])/Table310[[#This Row],[Requirement 2025]] -> -0.21600412 | M30: 45 | N30: =Table310[[#This Row],[Requirement 2026 (1&2) (3)50%]]-Table310[[#This Row],[New Requirement 2026 (Priority 1,2 and 50% of 3)]] -> 33.248221
A31: CCS (with OTA) | B31: =B11/1000000 -> 0 | C31: =C11/1000000 -> 0 | D31: =D11/1000000 -> 0 | E31: =E11/1000000 -> 0 | F31: =F11/1000000 -> 0 | G31: =G11/1000000 -> 36 | H31: =H11/1000000 -> 33.230246 | I31: =I11/1000000 -> 33.230246 | L31: =(Table310[[#This Row],[Requirement 2026 (1&2) (3)50%]]-Table310[[#This Row],[Requirement 2025]])/Table310[[#This Row],[Requirement 2025]] -> -0.076937611 | M31: 20 | N31: =Table310[[#This Row],[Requirement 2026 (1&2) (3)50%]]-Table310[[#This Row],[New Requirement 2026 (Priority 1,2 and 50% of 3)]] -> 13.230246
A32: MPCA | B32: =B12/1000000 -> 0 | C32: =C12/1000000 -> 0 | D32: =D12/1000000 -> 0 | E32: =E12/1000000 -> 0 | F32: =F12/1000000 -> 0.46370484 | G32: =G12/1000000 -> 25 | H32: =H12/1000000 -> 33.539527 | I32: =I12/1000000 -> 33.539527 | L32: =(Table310[[#This Row],[Requirement 2026 (1&2) (3)50%]]-Table310[[#This Row],[Requirement 2025]])/Table310[[#This Row],[Requirement 2025]] -> 0.34158108 | M32: 30 | N32: =Table310[[#This Row],[Requirement 2026 (1&2) (3)50%]]-Table310[[#This Row],[New Requirement 2026 (Priority 1,2 and 50% of 3)]] -> 3.539527
A33: Refugee | B33: =B13/1000000 -> 0.68 | C33: =C13/1000000 -> 0.68 | D33: =D13/1000000 -> 0.741304 | E33: =E13/1000000 -> 0.592848 | F33: =F13/1000000 -> 0.592848 | G33: =G13/1000000 -> 468 | H33: =H13/1000000 -> 500 | I33: =I13/1000000 -> 500 | J33: =(Table310[[#This Row],[PiN 2026]]-Table310[[#This Row],[PiN 2025]])/Table310[[#This Row],[PiN 2025]] -> 0.090152941 | K33: =(Table310[[#This Row],[Target 2026 (1&2) (3)50%]]-Table310[[#This Row],[Target 2025]])/Table310[[#This Row],[Target 2025]] -> -0.12816471 | L33: =(Table310[[#This Row],[Requirement 2026 (1&2) (3)50%]]-Table310[[#This Row],[Requirement 2025]])/Table310[[#This Row],[Requirement 2025]] -> 0.068376068 | M33: 185 | N33: =Table310[[#This Row],[Requirement 2026 (1&2) (3)50%]]-Table310[[#This Row],[New Requirement 2026 (Priority 1,2 and 50% of 3)]] -> 315
A34: Total without refugees | B34: =B14/1000000 -> 8.6100879 | C34: =C14/1000000 -> 4.6969821 | D34: =D14/1000000 -> 9.266561 | E34: =E14/1000000 -> 3.1992087 | F34: =F14/1000000 -> 3.6562067 | G34: =G14/1000000 -> 1226.7786 | H34: =H14/1000000 -> 966.34949 | I34: =I14/1000000 -> 1081.5636 | J34: =(Table310[[#This Row],[PiN 2026]]-Table310[[#This Row],[PiN 2025]])/Table310[[#This Row],[PiN 2025]] -> 0.076244652 | K34: =(Table310[[#This Row],[Target 2026 (1&2) (3)50%]]-Table310[[#This Row],[Target 2025]])/Table310[[#This Row],[Target 2025]] -> -0.22158386 | L34: =(Table310[[#This Row],[Requirement 2026 (1&2) (3)50%]]-Table310[[#This Row],[Requirement 2025]])/Table310[[#This Row],[Requirement 2025]] -> -0.11837106 | M34: 856.4 | N34: =Table310[[#This Row],[Requirement 2026 (1&2) (3)50%]]-Table310[[#This Row],[New Requirement 2026 (Priority 1,2 and 50% of 3)]] -> 225.16356
A35: Total with refugees | B35: =B15/1000000 -> 9.2900879 | C35: =C15/1000000 -> 5.3769821 | D35: =D15/1000000 -> 10.007865 | E35: =E15/1000000 -> 3.7920567 | F35: =F15/1000000 -> 4.2490547 | G35: =G15/1000000 -> 1694.7786 | H35: =H15/1000000 -> 1466.3495 | I35: =I15/1000000 -> 1581.5636 | J35: =(Table310[[#This Row],[PiN 2026]]-Table310[[#This Row],[PiN 2025]])/Table310[[#This Row],[PiN 2025]] -> 0.077262687 | K35: =(Table310[[#This Row],[Target 2026 (1&2) (3)50%]]-Table310[[#This Row],[Target 2025]])/Table310[[#This Row],[Target 2025]] -> -0.20976961 | L35: =(Table310[[#This Row],[Requirement 2026 (1&2) (3)50%]]-Table310[[#This Row],[Requirement 2025]])/Table310[[#This Row],[Requirement 2025]] -> -0.066802284 | M35: =SUM(M22:M33) -> 1041.4 | N35: =Table310[[#This Row],[Requirement 2026 (1&2) (3)50%]]-Table310[[#This Row],[New Requirement 2026 (Priority 1,2 and 50% of 3)]] -> 540.16356

Sheet County-SADD-PIN
E1: =SUM(Table6[Refugees]) -> 741303 | F1: =SUM(Table6[Overall PiN]) -> 9266561 | G1: =SUM(Table6[Overall PiN with REFUGEES]) -> 10007864 | I1: =SUM(Table6[No. of Male children under 5]) -> 957747.92 | K1: =SUM(Table6[No. of Female children under 5]) -> 895858.38 | M1: =SUM(Table6[No. of Male children aged 5 - 17 years]) -> 1763969.2 | O1: =SUM(Table6[No. of Female children aged 5 - 17 years]) -> 1742443.1 | Q1: =SUM(Table6[No. of Male adults aged 18 - 60]) -> 1909446.9 | S1: =SUM(Table6[No. of Female adults aged 18 - 60]) -> 2006959.6 | U1: =SUM(Table6[No. of Male adults aged over 60]) -> 347699.24 | W1: =SUM(Table6[No. Female adults aged over 60]) -> 383739.57 | X1: =SUM(Table6[Persons with disability]) -> 1393513.2 | AA1: =SUM(I1,M1,Q1,U1) -> 4978863.3 | AB1: =SUM(K1,O1,S1,W1) -> 5029000.7 | AC1: =SUM(I1,K1,M1,O1) -> 5360018.6 | AD1: =SUM(S1,W1) -> 2390699.2 | AE1: =SUM(Q1,U1) -> 2257146.1 | AF1: =SUM(Q1,S1,U1,W1) -> 4647845.4 | AG1: =SUM(U1,W1) -> 731438.81 | AJ1: =SUM(AJ3:AJ81) -> 2721717.1 | AK1: =SUM(AK3:AK81) -> 2638301.5 | AL1: =SUM(AL3:AL81) -> 1909446.9 | AM1: =SUM(AM3:AM81) -> 2006959.6 | AN1: =SUM(AN3:AN81) -> 347699.24 | AO1: =SUM(AO3:AO81) -> 383739.57 | AP1: =SUM(AP3:AP81) -> 10007864
